Workbook

Sheet OFICIAL
A1: JOGOS | I1: OFICIAL | R1: Vencedor da Partida | S1: Score Vencedor | T1: Score Perdedor | AA1: BERNARDO | AB1: ELIANE | AC1: FELIPE | AD1: FERNANDO | AE1: GABRIEL | AF1: HERIS | AG1: KEVEN | AH1: MARCIO | AI1: RENAN | AJ1: THIAGO | AK1: MARQUES | AL1: SOARES | AM1: YURI
A2: 46184 | B2: 0.66666667 | C2: México | D2: 2 | E2: x | F2: 0 | G2: África do Sul | R2: =IF(D2="","",IF(D2>F2,C2,IF(F2>D2,G2,"EMPATE"))) -> México | S2: =IF(D2="","",IF(D2>F2,D2,IF(F2>D2,F2,D2))) -> 2 | T2: =IF(D2="","",IF(D2<F2,D2,IF(F2<D2,F2,D2))) -> 0 | V2: LEGENDA | AA2: =BERNARDO!O2 -> 0 | AB2: =#REF! -> #REF! | AC2: =#REF! -> #REF! | AD2: =FERNANDO!O2 -> 9 | AE2: =GABRIEL!O2 -> 9 | AF2: =#REF! -> #REF! | AG2: =RICARDO!O2 -> 6 | AH2: =MARCIO!O2 -> 9 | AI2: =RENAN!O2 -> 0 | AJ2: =THIAGO!O2 -> 6 | AK2: =MARQUES!O2 -> 3 | AL2: =SOARES!O2 -> 9 | AM2: =GUSTAVO!O2 -> 9
A3: 46184 | B3: 0.95833333 | C3: Coréia do Sul | D3: 2 | E3: x | F3: 1 | G3: República Tcheca | R3: =IF(D3="","",IF(D3>F3,C3,IF(F3>D3,G3,"EMPATE"))) -> Coréia do Sul | S3: =IF(D3="","",IF(D3>F3,D3,IF(F3>D3,F3,D3))) -> 2 | T3: =IF(D3="","",IF(D3<F3,D3,IF(F3<D3,F3,D3))) -> 1 | AA3: =BERNARDO!O3 -> 0 | AB3: =#REF! -> #REF! | AC3: =#REF! -> #REF! | AD3: =FERNANDO!O3 -> 0 | AE3: =GABRIEL!O3 -> 0 | AF3: =#REF! -> #REF! | AG3: =RICARDO!O3 -> 0 | AH3: =MARCIO!O3 -> 0 | AI3: =RENAN!O3 -> 0 | AJ3: =THIAGO!O3 -> 0 | AK3: =MARQUES!O3 -> 9 | AL3: =SOARES!O3 -> 0 | AM3: =GUSTAVO!O3 -> 3
A4: 46185 | B4: 0.66666667 | C4: Canadá | D4: 1 | E4: x | F4: 1 | G4: Bósnia | R4: =IF(D4="","",IF(D4>F4,C4,IF(F4>D4,G4,"EMPATE"))) -> EMPATE | S4: =IF(D4="","",IF(D4>F4,D4,IF(F4>D4,F4,D4))) -> 1 | T4: =IF(D4="","",IF(D4<F4,D4,IF(F4<D4,F4,D4))) -> 1 | V4: 9 PONTOS | W4: VENCEDOR COM PLACAR CORRETO OU EMPATE COM PLACAR CORRETO | AA4: =BERNARDO!O4 -> 9 | AB4: =#REF! -> #REF! | AC4: =#REF! -> #REF! | AD4: =FERNANDO!O4 -> 0 | AE4: =GABRIEL!O4 -> 0 | AF4: =#REF! -> #REF! | AG4: =RICARDO!O4 -> 0 | AH4: =MARCIO!O4 -> 9 | AI4: =RENAN!O4 -> 0 | AJ4: =THIAGO!O4 -> 0 | AK4: =MARQUES!O4 -> 0 | AL4: =SOARES!O4 -> 0 | AM4: =GUSTAVO!O4 -> 0
A5: 46185 | B5: 0.91666667 | C5: Estados Unidos | D5: 4 | E5: x | F5: 1 | G5: Paraguai | I5: RUMO AO HEXA! | R5: =IF(D5="","",IF(D5>F5,C5,IF(F5>D5,G5,"EMPATE"))) -> Estados Unidos | S5: =IF(D5="","",IF(D5>F5,D5,IF(F5>D5,F5,D5))) -> 4 | T5: =IF(D5="","",IF(D5<F5,D5,IF(F5<D5,F5,D5))) -> 1 | V5: 6 PONTOS | W5: VENCEDOR COM APENAS O NÚMERO DE GOLS DO VENCEDOR CORRETO OU EMPATE COM O NÚMERO DE GOLS ERRADO | AA5: =BERNARDO!O5 -> 4 | AB5: =#REF! -> #REF! | AC5: =#REF! -> #REF! | AD5: =FERNANDO!O5 -> 3 | AE5: =GABRIEL!O5 -> 0 | AF5: =#REF! -> #REF! | AG5: =RICARDO!O5 -> 4 | AH5: =MARCIO!O5 -> 0 | AI5: =RENAN!O5 -> 0 | AJ5: =THIAGO!O5 -> 4 | AK5: =MARQUES!O5 -> 4 | AL5: =SOARES!O5 -> 4 | AM5: =GUSTAVO!O5 -> 4
A6: 46186 | B6: 0.66666667 | C6: Catar | D6: 1 | E6: x | F6: 1 | G6: Suíça | R6: =IF(D6="","",IF(D6>F6,C6,IF(F6>D6,G6,"EMPATE"))) -> EMPATE | S6: =IF(D6="","",IF(D6>F6,D6,IF(F6>D6,F6,D6))) -> 1 | T6: =IF(D6="","",IF(D6<F6,D6,IF(F6<D6,F6,D6))) -> 1 | V6: 4 PONTOS | W6: VENCEDOR COM APENAS O NÚMERO DE GOLS DO PERDEDOR CORRETO | AA6: =BERNARDO!O6 -> 0 | AB6: =#REF! -> #REF! | AC6: =#REF! -> #REF! | AD6: =FERNANDO!O6 -> 0 | AE6: =GABRIEL!O6 -> 0 | AF6: =#REF! -> #REF! | AG6: =RICARDO!O6 -> 0 | AH6: =MARCIO!O6 -> 0 | AI6: =RENAN!O6 -> 0 | AJ6: =THIAGO!O6 -> 0 | AK6: =MARQUES!O6 -> 6 | AL6: =SOARES!O6 -> 0 | AM6: =GUSTAVO!O6 -> 0
A7: 46186 | B7: 0.79166667 | C7: Brasil | D7: 1 | E7: x | F7: 1 | G7: Marrocos | R7: =IF(D7="","",IF(D7>F7,C7,IF(F7>D7,G7,"EMPATE"))) -> EMPATE | S7: =IF(D7="","",IF(D7>F7,D7,IF(F7>D7,F7,D7))) -> 1 | T7: =IF(D7="","",IF(D7<F7,D7,IF(F7<D7,F7,D7))) -> 1 | V7: 3 PONTOS | W7: VENCEDOR COM AMBOS OS NÚMERO DE GOLS ERRADO | AA7: =BERNARDO!O7 -> 0 | AB7: =#REF! -> #REF! | AC7: =#REF! -> #REF! | AD7: =FERNANDO!O7 -> 0 | AE7: =GABRIEL!O7 -> 0 | AF7: =#REF! -> #REF! | AG7: =RICARDO!O7 -> 0 | AH7: =MARCIO!O7 -> 0 | AI7: =RENAN!O7 -> 0 | AJ7: =THIAGO!O7 -> 0 | AK7: =MARQUES!O7 -> 0 | AL7: =SOARES!O7 -> 0 | AM7: =GUSTAVO!O7 -> 0
A8: 46186 | B8: 0.91666667 | C8: Haiti | D8: 0 | E8: x | F8: 1 | G8: Escócia | R8: =IF(D8="","",IF(D8>F8,C8,IF(F8>D8,G8,"EMPATE"))) -> Escócia | S8: =IF(D8="","",IF(D8>F8,D8,IF(F8>D8,F8,D8))) -> 1 | T8: =IF(D8="","",IF(D8<F8,D8,IF(F8<D8,F8,D8))) -> 0 | V8: 0 PONTOS | W8: ERROU O VENCEDOR OU ERROU O JOGO QUE FOI EMPATE | AA8: =BERNARDO!O8 -> 3 | AB8: =#REF! -> #REF! | AC8: =#REF! -> #REF! | AD8: =FERNANDO!O8 -> 0 | AE8: =GABRIEL!O8 -> 0 | AF8: =#REF! -> #REF! | AG8: =RICARDO!O8 -> 3 | AH8: =MARCIO!O8 -> 0 | AI8: =RENAN!O8 -> 0 | AJ8: =THIAGO!O8 -> 4 | AK8: =MARQUES!O8 -> 9 | AL8: =SOARES!O8 -> 4 | AM8: =GUSTAVO!O8 -> 4
A9: 46187 | B9: 0.041666667 | C9: Austrália | D9: 2 | E9: x | F9: 0 | G9: Turquia | I9: Copa Phibra 2026 | R9: =IF(D9="","",IF(D9>F9,C9,IF(F9>D9,G9,"EMPATE"))) -> Austrália | S9: =IF(D9="","",IF(D9>F9,D9,IF(F9>D9,F9,D9))) -> 2 | T9: =IF(D9="","",IF(D9<F9,D9,IF(F9<D9,F9,D9))) -> 0 | AA9: =BERNARDO!O9 -> 0 | AB9: =#REF! -> #REF! | AC9: =#REF! -> #REF! | AD9: =FERNANDO!O9 -> 6 | AE9: =GABRIEL!O9 -> 0 | AF9: =#REF! -> #REF! | AG9: =RICARDO!O9 -> 0 | AH9: =MARCIO!O9 -> 0 | AI9: =RENAN!O9 -> 0 | AJ9: =THIAGO!O9 -> 0 | AK9: =MARQUES!O9 -> 0 | AL9: =SOARES!O9 -> 0 | AM9: =GUSTAVO!O9 -> 0
A10: 46187 | B10: 0.58333333 | C10: Alemanha | D10: 7 | E10: x | F10: 1 | G10: Curaçao | I10: Posição | J10: Phibriano | K10: Pontos | L10: 9 | M10: 6 | N10: 4 | O10: 3 | P10: 0 | R10: =IF(D10="","",IF(D10>F10,C10,IF(F10>D10,G10,"EMPATE"))) -> Alemanha | S10: =IF(D10="","",IF(D10>F10,D10,IF(F10>D10,F10,D10))) -> 7 | T10: =IF(D10="","",IF(D10<F10,D10,IF(F10<D10,F10,D10))) -> 1 | V10: CRITÉRIOS DE DESEMPATE | AA10: =BERNARDO!O10 -> 3 | AB10: =#REF! -> #REF! | AC10: =#REF! -> #REF! | AD10: =FERNANDO!O10 -> 3 | AE10: =GABRIEL!O10 -> 3 | AF10: =#REF! -> #REF! | AG10: =RICARDO!O10 -> 3 | AH10: =MARCIO!O10 -> 3 | AI10: =RENAN!O10 -> 3 | AJ10: =THIAGO!O10 -> 3 | AK10: =MARQUES!O10 -> 3 | AL10: =SOARES!O10 -> 3 | AM10: =GUSTAVO!O10 -> 3
A11: 46187 | B11: 0.70833333 | C11: Holanda | D11: 2 | E11: x | F11: 2 | G11: Japão | H11: =(K11*10000+L11*1000+M11*100+N11*10+O11*1) -> 1114495 | I11: =_xlfn.RANK.EQ(H11,$H$11:$H$20) -> 5 | J11: Bernardo | K11: =SUM(BERNARDO!$O$2:$O$65) -> 111 | L11: =COUNTIF(BERNARDO!$O$2:'BERNARDO'!$O$70,"9") -> 4 | M11: =COUNTIF(BERNARDO!$O$2:'BERNARDO'!$O$70,"6") -> 4 | N11: =COUNTIF(BERNARDO!$O$2:'BERNARDO'!$O$70,"4") -> 9 | O11: =COUNTIF(BERNARDO!$O$2:'BERNARDO'!$O$70,"3") -> 5 | P11: =COUNTIF(BERNARDO!$O$2:'BERNARDO'!$O$70,"0") -> 22 | Q11: =L11*9+M11*6+N11*4+O11*3 -> 111 | R11: =IF(D11="","",IF(D11>F11,C11,IF(F11>D11,G11,"EMPATE"))) -> EMPATE | S11: =IF(D11="","",IF(D11>F11,D11,IF(F11>D11,F11,D11))) -> 2 | T11: =IF(D11="","",IF(D11<F11,D11,IF(F11<D11,F11,D11))) -> 2 | V11: MAIOR NÚMERO DE JOGOS COM 9 PONTOS | AA11: =BERNARDO!O11 -> 0 | AB11: =#REF! -> #REF! | AC11: =#REF! -> #REF! | AD11: =FERNANDO!O11 -> 0 | AE11: =GABRIEL!O11 -> 0 | AF11: =#REF! -> #REF! | AG11: =RICARDO!O11 -> 0 | AH11: =MARCIO!O11 -> 0 | AI11: =RENAN!O11 -> 0 | AJ11: =THIAGO!O11 -> 0 | AK11: =MARQUES!O11 -> 9 | AL11: =SOARES!O11 -> 6 | AM11: =GUSTAVO!O11 -> 0
A12: 46187 | B12: 0.83333333 | C12: Costa do Marfim | D12: 1 | E12: x | F12: 0 | G12: Equador | H12: =(K12*10000+L12*1000+M12*100+N12*10+O12*1) -> 1185379 | I12: =_xlfn.RANK.EQ(H12,$H$11:$H$20) -> 4 | J12: Thiago | K12: =SUM(THIAGO!$O$2:$O$70) -> 118 | L12: =COUNTIF(THIAGO!$O$2:'THIAGO'!$O$70,"9") -> 5 | M12: =COUNTIF(THIAGO!$O$2:'THIAGO'!$O$70,"6") -> 3 | N12: =COUNTIF(THIAGO!$O$2:'THIAGO'!$O$70,"4") -> 7 | O12: =COUNTIF(THIAGO!$O$2:'THIAGO'!$O$70,"3") -> 9 | P12: =COUNTIF(THIAGO!$O$2:'THIAGO'!$O$70,"0") -> 20 | Q12: =L12*9+M12*6+N12*4+O12*3 -> 118 | R12: =IF(D12="","",IF(D12>F12,C12,IF(F12>D12,G12,"EMPATE"))) -> Costa do Marfim | S12: =IF(D12="","",IF(D12>F12,D12,IF(F12>D12,F12,D12))) -> 1 | T12: =IF(D12="","",IF(D12<F12,D12,IF(F12<D12,F12,D12))) -> 0 | V12: MAIOR NÚMERO DE JOGOS COM 6 PONTOS | AA12: =BERNARDO!O12 -> 0 | AB12: =#REF! -> #REF! | AC12: =#REF! -> #REF! | AD12: =FERNANDO!O12 -> 0 | AE12: =GABRIEL!O12 -> 0 | AF12: =#REF! -> #REF! | AG12: =RICARDO!O12 -> 0 | AH12: =MARCIO!O12 -> 3 | AI12: =RENAN!O12 -> 0 | AJ12: =THIAGO!O12 -> 0 | AK12: =MARQUES!O12 -> 0 | AL12: =SOARES!O12 -> 0 | AM12: =GUSTAVO!O12 -> 0
A13: 46187 | B13: 0.95833333 | C13: Suécia | D13: 5 | E13: x | F13: 1 | G13: Tunísia | H13: =(K13*10000+L13*1000+M13*100+N13*10+O13*1) -> 1012391 | I13: =_xlfn.RANK.EQ(H13,$H$11:$H$20) -> 7 | J13: Ricardo | K13: =SUM(RICARDO!$O$2:$O$70) -> 101 | L13: =COUNTIF(RICARDO!$O$2:'RICARDO'!$O$70,"9") -> 2 | M13: =COUNTIF(RICARDO!$O$2:'RICARDO'!$O$70,"6") -> 3 | N13: =COUNTIF(RICARDO!$O$2:'RICARDO'!$O$70,"4") -> 8 | O13: =COUNTIF(RICARDO!$O$2:'RICARDO'!$O$70,"3") -> 11 | P13: =COUNTIF(RICARDO!$O$2:'RICARDO'!$O$70,"0") -> 20 | Q13: =L13*9+M13*6+N13*4+O13*3 -> 101 | R13: =IF(D13="","",IF(D13>F13,C13,IF(F13>D13,G13,"EMPATE"))) -> Suécia | S13: =IF(D13="","",IF(D13>F13,D13,IF(F13>D13,F13,D13))) -> 5 | T13: =IF(D13="","",IF(D13<F13,D13,IF(F13<D13,F13,D13))) -> 1 | V13: MAIOR NÚMERO DE JOGOS COM 4 PONTOS | AA13: =BERNARDO!O13 -> 4 | AB13: =#REF! -> #REF! | AC13: =#REF! -> #REF! | AD13: =FERNANDO!O13 -> 4 | AE13: =GABRIEL!O13 -> 3 | AF13: =#REF! -> #REF! | AG13: =RICARDO!O13 -> 3 | AH13: =MARCIO!O13 -> 4 | AI13: =RENAN!O13 -> 0 | AJ13: =THIAGO!O13 -> 3 | AK13: =MARQUES!O13 -> 0 | AL13: =SOARES!O13 -> 3 | AM13: =GUSTAVO!O13 -> 3
A14: 46188 | B14: 0.54166667 | C14: Espanha | D14: 0 | E14: x | F14: 0 | G14: Cabo Verde | H14: =(K14*10000+L14*1000+M14*100+N14*10+O14*1) -> 963369 | I14: =_xlfn.RANK.EQ(H14,$H$11:$H$20) -> 8 | J14: Fernando | K14: =SUM(FERNANDO!$O$2:$O$70) -> 96 | L14: =COUNTIF(FERNANDO!$O$2:'FERNANDO'!$O$70,"9") -> 3 | M14: =COUNTIF(FERNANDO!$O$2:'FERNANDO'!$O$70,"6") -> 3 | N14: =COUNTIF(FERNANDO!$O$2:'FERNANDO'!$O$70,"4") -> 6 | O14: =COUNTIF(FERNANDO!$O$2:'FERNANDO'!$O$70,"3") -> 9 | P14: =COUNTIF(FERNANDO!$O$2:'FERNANDO'!$O$70,"0") -> 23 | Q14: =L14*9+M14*6+N14*4+O14*3 -> 96 | R14: =IF(D14="","",IF(D14>F14,C14,IF(F14>D14,G14,"EMPATE"))) -> EMPATE | S14: =IF(D14="","",IF(D14>F14,D14,IF(F14>D14,F14,D14))) -> 0 | T14: =IF(D14="","",IF(D14<F14,D14,IF(F14<D14,F14,D14))) -> 0 | V14: MAIOR NÚMERO DE JOGOS COM 3 PONTOS | AA14: =BERNARDO!O14 -> 0 | AB14: =#REF! -> #REF! | AC14: =#REF! -> #REF! | AD14: =FERNANDO!O14 -> 0 | AE14: =GABRIEL!O14 -> 0 | AF14: =#REF! -> #REF! | AG14: =RICARDO!O14 -> 0 | AH14: =MARCIO!O14 -> 0 | AI14: =RENAN!O14 -> 0 | AJ14: =THIAGO!O14 -> 0 | AK14: =MARQUES!O14 -> 0 | AL14: =SOARES!O14 -> 0 | AM14: =GUSTAVO!O14 -> 0
A15: 46188 | B15: 0.66666667 | C15: Bélgica | D15: 1 | E15: x | F15: 1 | G15: Egito | H15: =(K15*10000+L15*1000+M15*100+N15*10+O15*1) -> 1014261 | I15: =_xlfn.RANK.EQ(H15,$H$11:$H$20) -> 6 | J15: Gustavo | K15: =SUM(GUSTAVO!$O$2:$O$70) -> 101 | L15: =COUNTIF(GUSTAVO!$O$2:'GUSTAVO'!$O$70,"9") -> 4 | M15: =COUNTIF(GUSTAVO!$O$2:'GUSTAVO'!$O$70,"6") -> 2 | N15: =COUNTIF(GUSTAVO!$O$2:'GUSTAVO'!$O$70,"4") -> 5 | O15: =COUNTIF(GUSTAVO!$O$2:'GUSTAVO'!$O$70,"3") -> 11 | P15: =COUNTIF(GUSTAVO!$O$2:'GUSTAVO'!$O$70,"0") -> 22 | Q15: =L15*9+M15*6+N15*4+O15*3 -> 101 | R15: =IF(D15="","",IF(D15>F15,C15,IF(F15>D15,G15,"EMPATE"))) -> EMPATE | S15: =IF(D15="","",IF(D15>F15,D15,IF(F15>D15,F15,D15))) -> 1 | T15: =IF(D15="","",IF(D15<F15,D15,IF(F15<D15,F15,D15))) -> 1 | V15: SORTEIO | AA15: =BERNARDO!O15 -> 0 | AB15: =#REF! -> #REF! | AC15: =#REF! -> #REF! | AD15: =FERNANDO!O15 -> 0 | AE15: =GABRIEL!O15 -> 0 | AF15: =#REF! -> #REF! | AG15: =RICARDO!O15 -> 0 | AH15: =MARCIO!O15 -> 0 | AI15: =RENAN!O15 -> 0 | AJ15: =THIAGO!O15 -> 0 | AK15: =MARQUES!O15 -> 0 | AL15: =SOARES!O15 -> 0 | AM15: =GUSTAVO!O15 -> 0
A16: 46188 | B16: 0.79166667 | C16: Arábia Saudita | D16: 1 | E16: x | F16: 1 | G16: Uruguai | H16: =(K16*10000+L16*1000+M16*100+N16*10+O16*1) -> 1206146 | I16: =_xlfn.RANK.EQ(H16,$H$11:$H$20) -> 2 | J16: Marcio | K16: =SUM(MARCIO!$O$2:$O$70) -> 120 | L16: =COUNTIF(MARCIO!$O$2:'MARCIO'!$O$70,"9") -> 6 | M16: =COUNTIF(MARCIO!$O$2:'MARCIO'!$O$70,"6") -> 1 | N16: =COUNTIF(MARCIO!$O$2:'MARCIO'!$O$70,"4") -> 3 | O16: =COUNTIF(MARCIO!$O$2:'MARCIO'!$O$70,"3") -> 16 | P16: =COUNTIF(MARCIO!$O$2:'MARCIO'!$O$70,"0") -> 18 | Q16: =L16*9+M16*6+N16*4+O16*3 -> 120 | R16: =IF(D16="","",IF(D16>F16,C16,IF(F16>D16,G16,"EMPATE"))) -> EMPATE | S16: =IF(D16="","",IF(D16>F16,D16,IF(F16>D16,F16,D16))) -> 1 | T16: =IF(D16="","",IF(D16<F16,D16,IF(F16<D16,F16,D16))) -> 1 | AA16: =BERNARDO!O16 -> 0 | AB16: =#REF! -> #REF! | AC16: =#REF! -> #REF! | AD16: =FERNANDO!O16 -> 0 | AE16: =GABRIEL!O16 -> 0 | AF16: =#REF! -> #REF! | AG16: =RICARDO!O16 -> 0 | AH16: =MARCIO!O16 -> 9 | AI16: =RENAN!O16 -> 0 | AJ16: =THIAGO!O16 -> 0 | AK16: =MARQUES!O16 -> 0 | AL16: =SOARES!O16 -> 0 | AM16: =GUSTAVO!O16 -> 0
A17: 46188 | B17: 0.91666667 | C17: Irã | D17: 2 | E17: x | F17: 2 | G17: Nova Zelândia | H17: =(K17*10000+L17*1000+M17*100+N17*10+O17*1) -> 853080 | I17: =_xlfn.RANK.EQ(H17,$H$11:$H$20) -> 9 | J17: Gabriel | K17: =SUM(GABRIEL!$O$2:$O$70) -> 85 | L17: =COUNTIF(GABRIEL!$O$2:'GABRIEL'!$O$70,"9") -> 3 | M17: =COUNTIF(GABRIEL!$O$2:'GABRIEL'!$O$70,"6") -> 0 | N17: =COUNTIF(GABRIEL!$O$2:'GABRIEL'!$O$70,"4") -> 7 | O17: =COUNTIF(GABRIEL!$O$2:'GABRIEL'!$O$70,"3") -> 10 | P17: =COUNTIF(GABRIEL!$O$2:'GABRIEL'!$O$70,"0") -> 24 | Q17: =L17*9+M17*6+N17*4+O17*3 -> 85 | R17: =IF(D17="","",IF(D17>F17,C17,IF(F17>D17,G17,"EMPATE"))) -> EMPATE | S17: =IF(D17="","",IF(D17>F17,D17,IF(F17>D17,F17,D17))) -> 2 | T17: =IF(D17="","",IF(D17<F17,D17,IF(F17<D17,F17,D17))) -> 2 | AA17: =BERNARDO!O17 -> 6 | AB17: =#REF! -> #REF! | AC17: =#REF! -> #REF! | AD17: =FERNANDO!O17 -> 6 | AE17: =GABRIEL!O17 -> 0 | AF17: =#REF! -> #REF! | AG17: =RICARDO!O17 -> 0 | AH17: =MARCIO!O17 -> 0 | AI17: =RENAN!O17 -> 6 | AJ17: =THIAGO!O17 -> 0 | AK17: =MARQUES!O17 -> 0 | AL17: =SOARES!O17 -> 0 | AM17: =GUSTAVO!O17 -> 0
A18: 46189 | B18: 0.66666667 | C18: França | D18: 3 | E18: x | F18: 1 | G18: Senegal | H18: =(K18*10000+L18*1000+M18*100+N18*10+O18*1) -> 831486 | I18: =_xlfn.RANK.EQ(H18,$H$11:$H$20) -> 10 | J18: Renan | K18: =SUM(RENAN!$O$2:$O$70) -> 83 | L18: =COUNTIF(RENAN!$O$2:'RENAN'!$O$70,"9") -> 1 | M18: =COUNTIF(RENAN!$O$2:'RENAN'!$O$70,"6") -> 4 | N18: =COUNTIF(RENAN!$O$2:'RENAN'!$O$70,"4") -> 8 | O18: =COUNTIF(RENAN!$O$2:'RENAN'!$O$70,"3") -> 6 | P18: =COUNTIF(RENAN!$O$2:'RENAN'!$O$70,"0") -> 25 | Q18: =L18*9+M18*6+N18*4+O18*3 -> 83 | R18: =IF(D18="","",IF(D18>F18,C18,IF(F18>D18,G18,"EMPATE"))) -> França | S18: =IF(D18="","",IF(D18>F18,D18,IF(F18>D18,F18,D18))) -> 3 | T18: =IF(D18="","",IF(D18<F18,D18,IF(F18<D18,F18,D18))) -> 1 | AA18: =BERNARDO!O18 -> 9 | AB18: =#REF! -> #REF! | AC18: =#REF! -> #REF! | AD18: =FERNANDO!O18 -> 3 | AE18: =GABRIEL!O18 -> 4 | AF18: =#REF! -> #REF! | AG18: =RICARDO!O18 -> 9 | AH18: =MARCIO!O18 -> 9 | AI18: =RENAN!O18 -> 4 | AJ18: =THIAGO!O18 -> 9 | AK18: =MARQUES!O18 -> 6 | AL18: =SOARES!O18 -> 4 | AM18: =GUSTAVO!O18 -> 3
A19: 46189 | B19: 0.79166667 | C19: Iraque | D19: 1 | E19: x | F19: 4 | G19: Noruega | H19: =(K19*10000+L19*1000+M19*100+N19*10+O19*1) -> 1196261 | I19: =_xlfn.RANK.EQ(H19,$H$11:$H$20) -> 3 | J19: Soares | K19: =SUM(SOARES!$O$2:$O$70) -> 119 | L19: =COUNTIF(SOARES!$O$2:'SOARES'!$O$70,"9") -> 6 | M19: =COUNTIF(SOARES!$O$2:'SOARES'!$O$70,"6") -> 2 | N19: =COUNTIF(SOARES!$O$2:'SOARES'!$O$70,"4") -> 5 | O19: =COUNTIF(SOARES!$O$2:'SOARES'!$O$70,"3") -> 11 | P19: =COUNTIF(SOARES!$O$2:'SOARES'!$O$70,"0") -> 20 | Q19: =L19*9+M19*6+N19*4+O19*3 -> 119 | R19: =IF(D19="","",IF(D19>F19,C19,IF(F19>D19,G19,"EMPATE"))) -> Noruega | S19: =IF(D19="","",IF(D19>F19,D19,IF(F19>D19,F19,D19))) -> 4 | T19: =IF(D19="","",IF(D19<F19,D19,IF(F19<D19,F19,D19))) -> 1 | AA19: =BERNARDO!O19 -> 0 | AB19: =#REF! -> #REF! | AC19: =#REF! -> #REF! | AD19: =FERNANDO!O19 -> 0 | AE19: =GABRIEL!O19 -> 0 | AF19: =#REF! -> #REF! | AG19: =RICARDO!O19 -> 4 | AH19: =MARCIO!O19 -> 6 | AI19: =RENAN!O19 -> 3 | AJ19: =THIAGO!O19 -> 3 | AK19: =MARQUES!O19 -> 3 | AL19: =SOARES!O19 -> 3 | AM19: =GUSTAVO!O19 -> 4
A20: 46189 | B20: 0.91666667 | C20: Argentina | D20: 3 | E20: x | F20: 0 | G20: Argélia | H20: =(K20*10000+L20*1000+M20*100+N20*10+O20*1) -> 1294573 | I20: =_xlfn.RANK.EQ(H20,$H$11:$H$20) -> 1 | J20: Marques | K20: =SUM(MARQUES!$O$2:$O$70) -> 129 | L20: =COUNTIF(MARQUES!$O$2:'MARQUES'!$O$70,"9") -> 4 | M20: =COUNTIF(MARQUES!$O$2:'MARQUES'!$O$70,"6") -> 5 | N20: =COUNTIF(MARQUES!$O$2:'MARQUES'!$O$70,"4") -> 6 | O20: =COUNTIF(MARQUES!$O$2:'MARQUES'!$O$70,"3") -> 13 | P20: =COUNTIF(MARQUES!$O$2:'MARQUES'!$O$70,"0") -> 16 | Q20: =L20*9+M20*6+N20*4+O20*3 -> 129 | R20: =IF(D20="","",IF(D20>F20,C20,IF(F20>D20,G20,"EMPATE"))) -> Argentina | S20: =IF(D20="","",IF(D20>F20,D20,IF(F20>D20,F20,D20))) -> 3 | T20: =IF(D20="","",IF(D20<F20,D20,IF(F20<D20,F20,D20))) -> 0 | AA20: =BERNARDO!O20 -> 6 | AB20: =#REF! -> #REF! | AC20: =#REF! -> #REF! | AD20: =FERNANDO!O20 -> 6 | AE20: =GABRIEL!O20 -> 9 | AF20: =#REF! -> #REF! | AG20: =RICARDO!O20 -> 9 | AH20: =MARCIO!O20 -> 9 | AI20: =RENAN!O20 -> 3 | AJ20: =THIAGO!O20 -> 9 | AK20: =MARQUES!O20 -> 4 | AL20: =SOARES!O20 -> 9 | AM20: =GUSTAVO!O20 -> 9
A21: 46190 | B21: 0.041666667 | C21: Áustria | D21: 3 | E21: x | F21: 1 | G21: Jordânia | R21: =IF(D21="","",IF(D21>F21,C21,IF(F21>D21,G21,"EMPATE"))) -> Áustria | S21: =IF(D21="","",IF(D21>F21,D21,IF(F21>D21,F21,D21))) -> 3 | T21: =IF(D21="","",IF(D21<F21,D21,IF(F21<D21,F21,D21))) -> 1 | AA21: =BERNARDO!O21 -> 0 | AB21: =#REF! -> #REF! | AC21: =#REF! -> #REF! | AD21: =FERNANDO!O21 -> 0 | AE21: =GABRIEL!O21 -> 3 | AF21: =#REF! -> #REF! | AG21: =RICARDO!O21 -> 3 | AH21: =MARCIO!O21 -> 3 | AI21: =RENAN!O21 -> 3 | AJ21: =THIAGO!O21 -> 3 | AK21: =MARQUES!O21 -> 3 | AL21: =SOARES!O21 -> 3 | AM21: =GUSTAVO!O21 -> 3
A22: 46190 | B22: 0.58333333 | C22: Portugal | D22: 1 | E22: x | F22: 1 | G22: RD Congo | I22: Copa Phibra 2026 | R22: =IF(D22="","",IF(D22>F22,C22,IF(F22>D22,G22,"EMPATE"))) -> EMPATE | S22: =IF(D22="","",IF(D22>F22,D22,IF(F22>D22,F22,D22))) -> 1 | T22: =IF(D22="","",IF(D22<F22,D22,IF(F22<D22,F22,D22))) -> 1 | AA22: =BERNARDO!O22 -> 0 | AB22: =#REF! -> #REF! | AC22: =#REF! -> #REF! | AD22: =FERNANDO!O22 -> 0 | AE22: =GABRIEL!O22 -> 0 | AF22: =#REF! -> #REF! | AG22: =RICARDO!O22 -> 0 | AH22: =MARCIO!O22 -> 0 | AI22: =RENAN!O22 -> 0 | AJ22: =THIAGO!O22 -> 0 | AK22: =MARQUES!O22 -> 0 | AL22: =SOARES!O22 -> 0 | AM22: =GUSTAVO!O22 -> 0
A23: 46190 | B23: 0.70833333 | C23: Inglaterra | D23: 4 | E23: x | F23: 2 | G23: Croácia | I23: Posição | J23: Phibriano | K23: Pontos | L23: 9 | M23: 6 | N23: 4 | O23: 3 | P23: 0 | R23: =IF(D23="","",IF(D23>F23,C23,IF(F23>D23,G23,"EMPATE"))) -> Inglaterra | S23: =IF(D23="","",IF(D23>F23,D23,IF(F23>D23,F23,D23))) -> 4 | T23: =IF(D23="","",IF(D23<F23,D23,IF(F23<D23,F23,D23))) -> 2 | AA23: =BERNARDO!O23 -> 0 | AB23: =#REF! -> #REF! | AC23: =#REF! -> #REF! | AD23: =FERNANDO!O23 -> 0 | AE23: =GABRIEL!O23 -> 3 | AF23: =#REF! -> #REF! | AG23: =RICARDO!O23 -> 3 | AH23: =MARCIO!O23 -> 3 | AI23: =RENAN!O23 -> 4 | AJ23: =THIAGO!O23 -> 3 | AK23: =MARQUES!O23 -> 4 | AL23: =SOARES!O23 -> 0 | AM23: =GUSTAVO!O23 -> 3
A24: 46190 | B24: 0.83333333 | C24: Gana | D24: 1 | E24: x | F24: 0 | G24: Panamá | I24: 1 | J24: Marques | K24: 129 | L24: 4 | M24: 5 | N24: 6 | O24: 13 | P24: 16 | R24: =IF(D24="","",IF(D24>F24,C24,IF(F24>D24,G24,"EMPATE"))) -> Gana | S24: =IF(D24="","",IF(D24>F24,D24,IF(F24>D24,F24,D24))) -> 1 | T24: =IF(D24="","",IF(D24<F24,D24,IF(F24<D24,F24,D24))) -> 0 | AA24: =BERNARDO!O24 -> 3 | AB24: =#REF! -> #REF! | AC24: =#REF! -> #REF! | AD24: =FERNANDO!O24 -> 3 | AE24: =GABRIEL!O24 -> 3 | AF24: =#REF! -> #REF! | AG24: =RICARDO!O24 -> 3 | AH24: =MARCIO!O24 -> 3 | AI24: =RENAN!O24 -> 3 | AJ24: =THIAGO!O24 -> 3 | AK24: =MARQUES!O24 -> 0 | AL24: =SOARES!O24 -> 3 | AM24: =GUSTAVO!O24 -> 3
A25: 46190 | B25: 0.95833333 | C25: Uzbequistão | D25: 1 | E25: x | F25: 3 | G25: Colômbia | I25: 2 | J25: Marcio | K25: 120 | L25: 6 | M25: 1 | N25: 3 | O25: 16 | P25: 18 | R25: =IF(D25="","",IF(D25>F25,C25,IF(F25>D25,G25,"EMPATE"))) -> Colômbia | S25: =IF(D25="","",IF(D25>F25,D25,IF(F25>D25,F25,D25))) -> 3 | T25: =IF(D25="","",IF(D25<F25,D25,IF(F25<D25,F25,D25))) -> 1 | AA25: =BERNARDO!O25 -> 4 | AB25: =#REF! -> #REF! | AC25: =#REF! -> #REF! | AD25: =FERNANDO!O25 -> 4 | AE25: =GABRIEL!O25 -> 0 | AF25: =#REF! -> #REF! | AG25: =RICARDO!O25 -> 3 | AH25: =MARCIO!O25 -> 3 | AI25: =RENAN!O25 -> 6 | AJ25: =THIAGO!O25 -> 3 | AK25: =MARQUES!O25 -> 3 | AL25: =SOARES!O25 -> 3 | AM25: =GUSTAVO!O25 -> 9
A26: 46191 | B26: 0.54166667 | C26: República Tcheca | D26: 1 | E26: x | F26: 1 | G26: África do Sul | I26: 3 | J26: Soares | K26: 119 | L26: 6 | M26: 2 | N26: 5 | O26: 11 | P26: 20 | R26: =IF(D26="","",IF(D26>F26,C26,IF(F26>D26,G26,"EMPATE"))) -> EMPATE | S26: =IF(D26="","",IF(D26>F26,D26,IF(F26>D26,F26,D26))) -> 1 | T26: =IF(D26="","",IF(D26<F26,D26,IF(F26<D26,F26,D26))) -> 1 | AA26: =BERNARDO!O26 -> 9 | AB26: =#REF! -> #REF! | AC26: =#REF! -> #REF! | AD26: =FERNANDO!O26 -> 0 | AE26: =GABRIEL!O26 -> 0 | AF26: =#REF! -> #REF! | AG26: =RICARDO!O26 -> 0 | AH26: =MARCIO!O26 -> 0 | AI26: =RENAN!O26 -> 0 | AJ26: =THIAGO!O26 -> 9 | AK26: =MARQUES!O26 -> 0 | AL26: =SOARES!O26 -> 0 | AM26: =GUSTAVO!O26 -> 0
A27: 46191 | B27: 0.66666667 | C27: Suíça | D27: 4 | E27: x | F27: 1 | G27: Bósnia | I27: 4 | J27: Thiago | K27: 118 | L27: 5 | M27: 3 | N27: 7 | O27: 9 | P27: 20 | R27: =IF(D27="","",IF(D27>F27,C27,IF(F27>D27,G27,"EMPATE"))) -> Suíça | S27: =IF(D27="","",IF(D27>F27,D27,IF(F27>D27,F27,D27))) -> 4 | T27: =IF(D27="","",IF(D27<F27,D27,IF(F27<D27,F27,D27))) -> 1 | AA27: =BERNARDO!O27 -> 0 | AB27: =#REF! -> #REF! | AC27: =#REF! -> #REF! | AD27: =FERNANDO!O27 -> 0 | AE27: =GABRIEL!O27 -> 0 | AF27: =#REF! -> #REF! | AG27: =RICARDO!O27 -> 3 | AH27: =MARCIO!O27 -> 3 | AI27: =RENAN!O27 -> 0 | AJ27: =THIAGO!O27 -> 4 | AK27: =MARQUES!O27 -> 3 | AL27: =SOARES!O27 -> 0 | AM27: =GUSTAVO!O27 -> 0
A28: 46191 | B28: 0.79166667 | C28: Canadá | D28: 6 | E28: x | F28: 0 | G28: Catar | I28: 5 | J28: Bernardo | K28: 111 | L28: 4 | M28: 4 | N28: 9 | O28: 5 | P28: 22 | R28: =IF(D28="","",IF(D28>F28,C28,IF(F28>D28,G28,"EMPATE"))) -> Canadá | S28: =IF(D28="","",IF(D28>F28,D28,IF(F28>D28,F28,D28))) -> 6 | T28: =IF(D28="","",IF(D28<F28,D28,IF(F28<D28,F28,D28))) -> 0 | AA28: =BERNARDO!O28 -> 4 | AB28: =#REF! -> #REF! | AC28: =#REF! -> #REF! | AD28: =FERNANDO!O28 -> 3 | AE28: =GABRIEL!O28 -> 3 | AF28: =#REF! -> #REF! | AG28: =RICARDO!O28 -> 3 | AH28: =MARCIO!O28 -> 3 | AI28: =RENAN!O28 -> 4 | AJ28: =THIAGO!O28 -> 0 | AK28: =MARQUES!O28 -> 3 | AL28: =SOARES!O28 -> 3 | AM28: =GUSTAVO!O28 -> 0
A29: 46191 | B29: 0.91666667 | C29: México | D29: 1 | E29: x | F29: 0 | G29: Coréia do Sul | I29: 6 | J29: Gustavo | K29: 101 | L29: 4 | M29: 2 | N29: 5 | O29: 11 | P29: 22 | R29: =IF(D29="","",IF(D29>F29,C29,IF(F29>D29,G29,"EMPATE"))) -> México | S29: =IF(D29="","",IF(D29>F29,D29,IF(F29>D29,F29,D29))) -> 1 | T29: =IF(D29="","",IF(D29<F29,D29,IF(F29<D29,F29,D29))) -> 0 | AA29: =BERNARDO!O29 -> 3 | AB29: =#REF! -> #REF! | AC29: =#REF! -> #REF! | AD29: =FERNANDO!O29 -> 0 | AE29: =GABRIEL!O29 -> 0 | AF29: =#REF! -> #REF! | AG29: =RICARDO!O29 -> 0 | AH29: =MARCIO!O29 -> 0 | AI29: =RENAN!O29 -> 0 | AJ29: =THIAGO!O29 -> 3 | AK29: =MARQUES!O29 -> 3 | AL29: =SOARES!O29 -> 3 | AM29: =GUSTAVO!O29 -> 0
A30: 46192 | B30: 0.66666667 | C30: Estados Unidos | D30: 2 | E30: x | F30: 0 | G30: Austrália | I30: 7 | J30: Ricardo | K30: 101 | L30: 2 | M30: 3 | N30: 8 | O30: 11 | P30: 20 | R30: =IF(D30="","",IF(D30>F30,C30,IF(F30>D30,G30,"EMPATE"))) -> Estados Unidos | S30: =IF(D30="","",IF(D30>F30,D30,IF(F30>D30,F30,D30))) -> 2 | T30: =IF(D30="","",IF(D30<F30,D30,IF(F30<D30,F30,D30))) -> 0 | AA30: =BERNARDO!O30 -> 4 | AB30: =#REF! -> #REF! | AC30: =#REF! -> #REF! | AD30: =FERNANDO!O30 -> 4 | AE30: =GABRIEL!O30 -> 3 | AF30: =#REF! -> #REF! | AG30: =RICARDO!O30 -> 6 | AH30: =MARCIO!O30 -> 3 | AI30: =RENAN!O30 -> 6 | AJ30: =THIAGO!O30 -> 6 | AK30: =MARQUES!O30 -> 6 | AL30: =SOARES!O30 -> 9 | AM30: =GUSTAVO!O30 -> 0
A31: 46192 | B31: 0.79166667 | C31: Escócia | D31: 0 | E31: x | F31: 1 | G31: Marrocos | I31: 8 | J31: Fernando | K31: 96 | L31: 3 | M31: 3 | N31: 6 | O31: 9 | P31: 23 | R31: =IF(D31="","",IF(D31>F31,C31,IF(F31>D31,G31,"EMPATE"))) -> Marrocos | S31: =IF(D31="","",IF(D31>F31,D31,IF(F31>D31,F31,D31))) -> 1 | T31: =IF(D31="","",IF(D31<F31,D31,IF(F31<D31,F31,D31))) -> 0 | AA31: =BERNARDO!O31 -> 0 | AB31: =#REF! -> #REF! | AC31: =#REF! -> #REF! | AD31: =FERNANDO!O31 -> 3 | AE31: =GABRIEL!O31 -> 3 | AF31: =#REF! -> #REF! | AG31: =RICARDO!O31 -> 3 | AH31: =MARCIO!O31 -> 3 | AI31: =RENAN!O31 -> 4 | AJ31: =THIAGO!O31 -> 0 | AK31: =MARQUES!O31 -> 3 | AL31: =SOARES!O31 -> 9 | AM31: =GUSTAVO!O31 -> 3
A32: 46192 | B32: 0.89583333 | C32: Brasil | D32: 3 | E32: x | F32: 0 | G32: Haiti | I32: 9 | J32: Gabriel | K32: 85 | L32: 3 | M32: 0 | N32: 7 | O32: 10 | P32: 24 | R32: =IF(D32="","",IF(D32>F32,C32,IF(F32>D32,G32,"EMPATE"))) -> Brasil | S32: =IF(D32="","",IF(D32>F32,D32,IF(F32>D32,F32,D32))) -> 3 | T32: =IF(D32="","",IF(D32<F32,D32,IF(F32<D32,F32,D32))) -> 0 | AA32: =BERNARDO!O32 -> 4 | AB32: =#REF! -> #REF! | AC32: =#REF! -> #REF! | AD32: =FERNANDO!O32 -> 9 | AE32: =GABRIEL!O32 -> 4 | AF32: =#REF! -> #REF! | AG32: =RICARDO!O32 -> 4 | AH32: =MARCIO!O32 -> 3 | AI32: =RENAN!O32 -> 9 | AJ32: =THIAGO!O32 -> 4 | AK32: =MARQUES!O32 -> 9 | AL32: =SOARES!O32 -> 9 | AM32: =GUSTAVO!O32 -> 4
A33: 46193 | B33: 0 | C33: Turquia | D33: 0 | E33: x | F33: 1 | G33: Paraguai | I33: 10 | J33: Renan | K33: 83 | L33: 1 | M33: 4 | N33: 8 | O33: 6 | P33: 25 | R33: =IF(D33="","",IF(D33>F33,C33,IF(F33>D33,G33,"EMPATE"))) -> Paraguai | S33: =IF(D33="","",IF(D33>F33,D33,IF(F33>D33,F33,D33))) -> 1 | T33: =IF(D33="","",IF(D33<F33,D33,IF(F33<D33,F33,D33))) -> 0 | AA33: =BERNARDO!O33 -> 0 | AB33: =#REF! -> #REF! | AC33: =#REF! -> #REF! | AD33: =FERNANDO!O33 -> 4 | AE33: =GABRIEL!O33 -> 4 | AF33: =#REF! -> #REF! | AG33: =RICARDO!O33 -> 0 | AH33: =MARCIO!O33 -> 3 | AI33: =RENAN!O33 -> 0 | AJ33: =THIAGO!O33 -> 0 | AK33: =MARQUES!O33 -> 0 | AL33: =SOARES!O33 -> 0 | AM33: =GUSTAVO!O33 -> 0
A34: 46193 | B34: 0.58333333 | C34: Holanda | D34: 5 | E34: x | F34: 1 | G34: Suécia | R34: =IF(D34="","",IF(D34>F34,C34,IF(F34>D34,G34,"EMPATE"))) -> Holanda | S34: =IF(D34="","",IF(D34>F34,D34,IF(F34>D34,F34,D34))) -> 5 | T34: =IF(D34="","",IF(D34<F34,D34,IF(F34<D34,F34,D34))) -> 1 | AA34: =BERNARDO!O34 -> 4 | AB34: =#REF! -> #REF! | AC34: =#REF! -> #REF! | AD34: =FERNANDO!O34 -> 0 | AE34: =GABRIEL!O34 -> 4 | AF34: =#REF! -> #REF! | AG34: =RICARDO!O34 -> 4 | AH34: =MARCIO!O34 -> 0 | AI34: =RENAN!O34 -> 0 | AJ34: =THIAGO!O34 -> 4 | AK34: =MARQUES!O34 -> 4 | AL34: =SOARES!O34 -> 0 | AM34: =GUSTAVO!O34 -> 0
A35: 46193 | B35: 0.70833333 | C35: Alemanha | D35: 2 | E35: x | F35: 1 | G35: Costa do Marfim | J35: 1000 | R35: =IF(D35="","",IF(D35>F35,C35,IF(F35>D35,G35,"EMPATE"))) -> Alemanha | S35: =IF(D35="","",IF(D35>F35,D35,IF(F35>D35,F35,D35))) -> 2 | T35: =IF(D35="","",IF(D35<F35,D35,IF(F35<D35,F35,D35))) -> 1 | AA35: =BERNARDO!O35 -> 4 | AB35: =#REF! -> #REF! | AC35: =#REF! -> #REF! | AD35: =FERNANDO!O35 -> 4 | AE35: =GABRIEL!O35 -> 4 | AF35: =#REF! -> #REF! | AG35: =RICARDO!O35 -> 4 | AH35: =MARCIO!O35 -> 4 | AI35: =RENAN!O35 -> 0 | AJ35: =THIAGO!O35 -> 9 | AK35: =MARQUES!O35 -> 3 | AL35: =SOARES!O35 -> 4 | AM35: =GUSTAVO!O35 -> 3
A36: 46193 | B36: 0.875 | C36: Equador | D36: 0 | E36: x | F36: 0 | G36: Curaçao | J36: 500 | R36: =IF(D36="","",IF(D36>F36,C36,IF(F36>D36,G36,"EMPATE"))) -> EMPATE | S36: =IF(D36="","",IF(D36>F36,D36,IF(F36>D36,F36,D36))) -> 0 | T36: =IF(D36="","",IF(D36<F36,D36,IF(F36<D36,F36,D36))) -> 0 | AA36: =BERNARDO!O36 -> 0 | AB36: =#REF! -> #REF! | AC36: =#REF! -> #REF! | AD36: =FERNANDO!O36 -> 0 | AE36: =GABRIEL!O36 -> 0 | AF36: =#REF! -> #REF! | AG36: =RICARDO!O36 -> 0 | AH36: =MARCIO!O36 -> 0 | AI36: =RENAN!O36 -> 0 | AJ36: =THIAGO!O36 -> 0 | AK36: =MARQUES!O36 -> 0 | AL36: =SOARES!O36 -> 0 | AM36: =GUSTAVO!O36 -> 0
A37: 46194 | B37: 0.041666667 | C37: Tunísia | D37: 0 | E37: x | F37: 4 | G37: Japão | J37: 300 | R37: =IF(D37="","",IF(D37>F37,C37,IF(F37>D37,G37,"EMPATE"))) -> Japão | S37: =IF(D37="","",IF(D37>F37,D37,IF(F37>D37,F37,D37))) -> 4 | T37: =IF(D37="","",IF(D37<F37,D37,IF(F37<D37,F37,D37))) -> 0 | AA37: =BERNARDO!O37 -> 4 | AB37: =#REF! -> #REF! | AC37: =#REF! -> #REF! | AD37: =FERNANDO!O37 -> 4 | AE37: =GABRIEL!O37 -> 3 | AF37: =#REF! -> #REF! | AG37: =RICARDO!O37 -> 4 | AH37: =MARCIO!O37 -> 3 | AI37: =RENAN!O37 -> 4 | AJ37: =THIAGO!O37 -> 3 | AK37: =MARQUES!O37 -> 3 | AL37: =SOARES!O37 -> 3 | AM37: =GUSTAVO!O37 -> 3
A38: 46194 | B38: 0.54166667 | C38: Espanha | D38: 4 | E38: x | F38: 0 | G38: Arábia Saudita | R38: =IF(D38="","",IF(D38>F38,C38,IF(F38>D38,G38,"EMPATE"))) -> Espanha | S38: =IF(D38="","",IF(D38>F38,D38,IF(F38>D38,F38,D38))) -> 4 | T38: =IF(D38="","",IF(D38<F38,D38,IF(F38<D38,F38,D38))) -> 0 | AA38: =BERNARDO!O38 -> 3 | AB38: =#REF! -> #REF! | AC38: =#REF! -> #REF! | AD38: =FERNANDO!O38 -> 3 | AE38: =GABRIEL!O38 -> 4 | AF38: =#REF! -> #REF! | AG38: =RICARDO!O38 -> 4 | AH38: =MARCIO!O38 -> 3 | AI38: =RENAN!O38 -> 4 | AJ38: =THIAGO!O38 -> 4 | AK38: =MARQUES!O38 -> 3 | AL38: =SOARES!O38 -> 4 | AM38: =GUSTAVO!O38 -> 4
A39: 46194 | B39: 0.66666667 | C39: Bélgica | D39: 0 | E39: x | F39: 0 | G39: Irã | R39: =IF(D39="","",IF(D39>F39,C39,IF(F39>D39,G39,"EMPATE"))) -> EMPATE | S39: =IF(D39="","",IF(D39>F39,D39,IF(F39>D39,F39,D39))) -> 0 | T39: =IF(D39="","",IF(D39<F39,D39,IF(F39<D39,F39,D39))) -> 0 | AA39: =BERNARDO!O39 -> 6 | AB39: =#REF! -> #REF! | AC39: =#REF! -> #REF! | AD39: =FERNANDO!O39 -> 0 | AE39: =GABRIEL!O39 -> 0 | AF39: =#REF! -> #REF! | AG39: =RICARDO!O39 -> 0 | AH39: =MARCIO!O39 -> 0 | AI39: =RENAN!O39 -> 0 | AJ39: =THIAGO!O39 -> 0 | AK39: =MARQUES!O39 -> 0 | AL39: =SOARES!O39 -> 0 | AM39: =GUSTAVO!O39 -> 6
A40: 46194 | B40: 0.79166667 | C40: Uruguai | D40: 2 | E40: x | F40: 2 | G40: Cabo Verde | R40: =IF(D40="","",IF(D40>F40,C40,IF(F40>D40,G40,"EMPATE"))) -> EMPATE | S40: =IF(D40="","",IF(D40>F40,D40,IF(F40>D40,F40,D40))) -> 2 | T40: =IF(D40="","",IF(D40<F40,D40,IF(F40<D40,F40,D40))) -> 2 | AA40: =BERNARDO!O40 -> 0 | AB40: =#REF! -> #REF! | AC40: =#REF! -> #REF! | AD40: =FERNANDO!O40 -> 0 | AE40: =GABRIEL!O40 -> 0 | AF40: =#REF! -> #REF! | AG40: =RICARDO!O40 -> 0 | AH40: =MARCIO!O40 -> 0 | AI40: =RENAN!O40 -> 0 | AJ40: =THIAGO!O40 -> 0 | AK40: =MARQUES!O40 -> 0 | AL40: =SOARES!O40 -> 0 | AM40: =GUSTAVO!O40 -> 0
...

Sheet BERNARDO
A1: PALPITES | H1: BERNARDO | K1: Palpite do Vencedor da Partida | L1: Score Vencedor | M1: Score Perdedor | O1: Pontos Ganhos
A2: 46184 | B2: 0.66666667 | C2: México | D2: 2 | E2: x | F2: 2 | G2: África do Sul | K2: =IF(D2="","",IF(D2>F2,C2,IF(F2>D2,G2,"EMPATE"))) -> EMPATE | L2: =IF(D2="","",IF(D2>F2,D2,IF(F2>D2,F2,D2))) -> 2 | M2: =IF(D2="","",IF(D2<F2,D2,IF(F2<D2,F2,D2))) -> 2 | O2: =IF(OFICIAL!D2="","",IF(AND(K2=OFICIAL!R2,L2=OFICIAL!S2,M2=OFICIAL!T2),9,IF(AND(K2=OFICIAL!R2,L2=OFICIAL!S2,M2<>OFICIAL!T2),6,IF(AND(K2=OFICIAL!R2,OFICIAL!S2=OFICIAL!T2,M2<>OFICIAL!T2),6,IF(AND(K2=OFICIAL!R2,L2<>OFICIAL!S2,OFICIAL!T2=M2),4,IF(AND(K2=OFICIAL!R2,OFICIAL!S2<>L2,OFICIAL!T2<>M2),3,0)))))) -> 0
A3: 46184 | B3: 0.95833333 | C3: Coréia do Sul | D3: 1 | E3: x | F3: 1 | G3: República Tcheca | K3: =IF(D3="","",IF(D3>F3,C3,IF(F3>D3,G3,"EMPATE"))) -> EMPATE | L3: =IF(D3="","",IF(D3>F3,D3,IF(F3>D3,F3,D3))) -> 1 | M3: =IF(D3="","",IF(D3<F3,D3,IF(F3<D3,F3,D3))) -> 1 | O3: =IF(OFICIAL!D3="","",IF(AND(K3=OFICIAL!R3,L3=OFICIAL!S3,M3=OFICIAL!T3),9,IF(AND(K3=OFICIAL!R3,L3=OFICIAL!S3,M3<>OFICIAL!T3),6,IF(AND(K3=OFICIAL!R3,OFICIAL!S3=OFICIAL!T3,M3<>OFICIAL!T3),6,IF(AND(K3=OFICIAL!R3,L3<>OFICIAL!S3,OFICIAL!T3=M3),4,IF(AND(K3=OFICIAL!R3,OFICIAL!S3<>L3,OFICIAL!T3<>M3),3,0)))))) -> 0
A4: 46185 | B4: 0.66666667 | C4: Canadá | D4: 1 | E4: x | F4: 1 | G4: Bósnia | K4: =IF(D4="","",IF(D4>F4,C4,IF(F4>D4,G4,"EMPATE"))) -> EMPATE | L4: =IF(D4="","",IF(D4>F4,D4,IF(F4>D4,F4,D4))) -> 1 | M4: =IF(D4="","",IF(D4<F4,D4,IF(F4<D4,F4,D4))) -> 1 | O4: =IF(OFICIAL!D4="","",IF(AND(K4=OFICIAL!R4,L4=OFICIAL!S4,M4=OFICIAL!T4),9,IF(AND(K4=OFICIAL!R4,L4=OFICIAL!S4,M4<>OFICIAL!T4),6,IF(AND(K4=OFICIAL!R4,OFICIAL!S4=OFICIAL!T4,M4<>OFICIAL!T4),6,IF(AND(K4=OFICIAL!R4,L4<>OFICIAL!S4,OFICIAL!T4=M4),4,IF(AND(K4=OFICIAL!R4,OFICIAL!S4<>L4,OFICIAL!T4<>M4),3,0)))))) -> 9
A5: 46185 | B5: 0.91666667 | C5: Estados Unidos | D5: 2 | E5: x | F5: 1 | G5: Paraguai | K5: =IF(D5="","",IF(D5>F5,C5,IF(F5>D5,G5,"EMPATE"))) -> Estados Unidos | L5: =IF(D5="","",IF(D5>F5,D5,IF(F5>D5,F5,D5))) -> 2 | M5: =IF(D5="","",IF(D5<F5,D5,IF(F5<D5,F5,D5))) -> 1 | O5: =IF(OFICIAL!D5="","",IF(AND(K5=OFICIAL!R5,L5=OFICIAL!S5,M5=OFICIAL!T5),9,IF(AND(K5=OFICIAL!R5,L5=OFICIAL!S5,M5<>OFICIAL!T5),6,IF(AND(K5=OFICIAL!R5,OFICIAL!S5=OFICIAL!T5,M5<>OFICIAL!T5),6,IF(AND(K5=OFICIAL!R5,L5<>OFICIAL!S5,OFICIAL!T5=M5),4,IF(AND(K5=OFICIAL!R5,OFICIAL!S5<>L5,OFICIAL!T5<>M5),3,0)))))) -> 4
A6: 46186 | B6: 0.66666667 | C6: Catar | D6: 0 | E6: x | F6: 2 | G6: Suíça | H6: PONTOS | I6: QTD | J6: TOTAL | K6: =IF(D6="","",IF(D6>F6,C6,IF(F6>D6,G6,"EMPATE"))) -> Suíça | L6: =IF(D6="","",IF(D6>F6,D6,IF(F6>D6,F6,D6))) -> 2 | M6: =IF(D6="","",IF(D6<F6,D6,IF(F6<D6,F6,D6))) -> 0 | O6: =IF(OFICIAL!D6="","",IF(AND(K6=OFICIAL!R6,L6=OFICIAL!S6,M6=OFICIAL!T6),9,IF(AND(K6=OFICIAL!R6,L6=OFICIAL!S6,M6<>OFICIAL!T6),6,IF(AND(K6=OFICIAL!R6,OFICIAL!S6=OFICIAL!T6,M6<>OFICIAL!T6),6,IF(AND(K6=OFICIAL!R6,L6<>OFICIAL!S6,OFICIAL!T6=M6),4,IF(AND(K6=OFICIAL!R6,OFICIAL!S6<>L6,OFICIAL!T6<>M6),3,0)))))) -> 0
A7: 46186 | B7: 0.79166667 | C7: Brasil | D7: 2 | E7: x | F7: 1 | G7: Marrocos | H7: 9 | I7: =COUNTIF($O$2:$O$65,9) -> 4 | J7: =H7*I7 -> 36 | K7: =IF(D7="","",IF(D7>F7,C7,IF(F7>D7,G7,"EMPATE"))) -> Brasil | L7: =IF(D7="","",IF(D7>F7,D7,IF(F7>D7,F7,D7))) -> 2 | M7: =IF(D7="","",IF(D7<F7,D7,IF(F7<D7,F7,D7))) -> 1 | O7: =IF(OFICIAL!D7="","",IF(AND(K7=OFICIAL!R7,L7=OFICIAL!S7,M7=OFICIAL!T7),9,IF(AND(K7=OFICIAL!R7,L7=OFICIAL!S7,M7<>OFICIAL!T7),6,IF(AND(K7=OFICIAL!R7,OFICIAL!S7=OFICIAL!T7,M7<>OFICIAL!T7),6,IF(AND(K7=OFICIAL!R7,L7<>OFICIAL!S7,OFICIAL!T7=M7),4,IF(AND(K7=OFICIAL!R7,OFICIAL!S7<>L7,OFICIAL!T7<>M7),3,0)))))) -> 0
A8: 46186 | B8: 0.91666667 | C8: Haiti | D8: 1 | E8: x | F8: 3 | G8: Escócia | H8: 6 | I8: =COUNTIF($O$2:$O$65,6) -> 4 | J8: =H8*I8 -> 24 | K8: =IF(D8="","",IF(D8>F8,C8,IF(F8>D8,G8,"EMPATE"))) -> Escócia | L8: =IF(D8="","",IF(D8>F8,D8,IF(F8>D8,F8,D8))) -> 3 | M8: =IF(D8="","",IF(D8<F8,D8,IF(F8<D8,F8,D8))) -> 1 | O8: =IF(OFICIAL!D8="","",IF(AND(K8=OFICIAL!R8,L8=OFICIAL!S8,M8=OFICIAL!T8),9,IF(AND(K8=OFICIAL!R8,L8=OFICIAL!S8,M8<>OFICIAL!T8),6,IF(AND(K8=OFICIAL!R8,OFICIAL!S8=OFICIAL!T8,M8<>OFICIAL!T8),6,IF(AND(K8=OFICIAL!R8,L8<>OFICIAL!S8,OFICIAL!T8=M8),4,IF(AND(K8=OFICIAL!R8,OFICIAL!S8<>L8,OFICIAL!T8<>M8),3,0)))))) -> 3
A9: 46187 | B9: 0.041666667 | C9: Austrália | D9: 1 | E9: x | F9: 2 | G9: Turquia | H9: 4 | I9: =COUNTIF($O$2:$O$65,4) -> 9 | J9: =H9*I9 -> 36 | K9: =IF(D9="","",IF(D9>F9,C9,IF(F9>D9,G9,"EMPATE"))) -> Turquia | L9: =IF(D9="","",IF(D9>F9,D9,IF(F9>D9,F9,D9))) -> 2 | M9: =IF(D9="","",IF(D9<F9,D9,IF(F9<D9,F9,D9))) -> 1 | O9: =IF(OFICIAL!D9="","",IF(AND(K9=OFICIAL!R9,L9=OFICIAL!S9,M9=OFICIAL!T9),9,IF(AND(K9=OFICIAL!R9,L9=OFICIAL!S9,M9<>OFICIAL!T9),6,IF(AND(K9=OFICIAL!R9,OFICIAL!S9=OFICIAL!T9,M9<>OFICIAL!T9),6,IF(AND(K9=OFICIAL!R9,L9<>OFICIAL!S9,OFICIAL!T9=M9),4,IF(AND(K9=OFICIAL!R9,OFICIAL!S9<>L9,OFICIAL!T9<>M9),3,0)))))) -> 0
A10: 46187 | B10: 0.58333333 | C10: Alemanha | D10: 4 | E10: x | F10: 0 | G10: Curaçao | H10: 3 | I10: =COUNTIF($O$2:$O$65,3) -> 5 | J10: =H10*I10 -> 15 | K10: =IF(D10="","",IF(D10>F10,C10,IF(F10>D10,G10,"EMPATE"))) -> Alemanha | L10: =IF(D10="","",IF(D10>F10,D10,IF(F10>D10,F10,D10))) -> 4 | M10: =IF(D10="","",IF(D10<F10,D10,IF(F10<D10,F10,D10))) -> 0 | O10: =IF(OFICIAL!D10="","",IF(AND(K10=OFICIAL!R10,L10=OFICIAL!S10,M10=OFICIAL!T10),9,IF(AND(K10=OFICIAL!R10,L10=OFICIAL!S10,M10<>OFICIAL!T10),6,IF(AND(K10=OFICIAL!R10,OFICIAL!S10=OFICIAL!T10,M10<>OFICIAL!T10),6,IF(AND(K10=OFICIAL!R10,L10<>OFICIAL!S10,OFICIAL!T10=M10),4,IF(AND(K10=OFICIAL!R10,OFICIAL!S10<>L10,OFICIAL!T10<>M10),3,0)))))) -> 3
A11: 46187 | B11: 0.70833333 | C11: Holanda | D11: 2 | E11: x | F11: 1 | G11: Japão | H11: 0 | I11: =COUNTIF($O$2:$O$65,0) -> 22 | J11: =H11*I11 -> 0 | K11: =IF(D11="","",IF(D11>F11,C11,IF(F11>D11,G11,"EMPATE"))) -> Holanda | L11: =IF(D11="","",IF(D11>F11,D11,IF(F11>D11,F11,D11))) -> 2 | M11: =IF(D11="","",IF(D11<F11,D11,IF(F11<D11,F11,D11))) -> 1 | O11: =IF(OFICIAL!D11="","",IF(AND(K11=OFICIAL!R11,L11=OFICIAL!S11,M11=OFICIAL!T11),9,IF(AND(K11=OFICIAL!R11,L11=OFICIAL!S11,M11<>OFICIAL!T11),6,IF(AND(K11=OFICIAL!R11,OFICIAL!S11=OFICIAL!T11,M11<>OFICIAL!T11),6,IF(AND(K11=OFICIAL!R11,L11<>OFICIAL!S11,OFICIAL!T11=M11),4,IF(AND(K11=OFICIAL!R11,OFICIAL!S11<>L11,OFICIAL!T11<>M11),3,0)))))) -> 0
A12: 46187 | B12: 0.83333333 | C12: Costa do Marfim | D12: 2 | E12: x | F12: 2 | G12: Equador | I12: TOTAL | J12: =SUM(J7:J11) -> 111 | K12: =IF(D12="","",IF(D12>F12,C12,IF(F12>D12,G12,"EMPATE"))) -> EMPATE | L12: =IF(D12="","",IF(D12>F12,D12,IF(F12>D12,F12,D12))) -> 2 | M12: =IF(D12="","",IF(D12<F12,D12,IF(F12<D12,F12,D12))) -> 2 | O12: =IF(OFICIAL!D12="","",IF(AND(K12=OFICIAL!R12,L12=OFICIAL!S12,M12=OFICIAL!T12),9,IF(AND(K12=OFICIAL!R12,L12=OFICIAL!S12,M12<>OFICIAL!T12),6,IF(AND(K12=OFICIAL!R12,OFICIAL!S12=OFICIAL!T12,M12<>OFICIAL!T12),6,IF(AND(K12=OFICIAL!R12,L12<>OFICIAL!S12,OFICIAL!T12=M12),4,IF(AND(K12=OFICIAL!R12,OFICIAL!S12<>L12,OFICIAL!T12<>M12),3,0)))))) -> 0
A13: 46187 | B13: 0.95833333 | C13: Suécia | D13: 2 | E13: x | F13: 1 | G13: Tunísia | K13: =IF(D13="","",IF(D13>F13,C13,IF(F13>D13,G13,"EMPATE"))) -> Suécia | L13: =IF(D13="","",IF(D13>F13,D13,IF(F13>D13,F13,D13))) -> 2 | M13: =IF(D13="","",IF(D13<F13,D13,IF(F13<D13,F13,D13))) -> 1 | O13: =IF(OFICIAL!D13="","",IF(AND(K13=OFICIAL!R13,L13=OFICIAL!S13,M13=OFICIAL!T13),9,IF(AND(K13=OFICIAL!R13,L13=OFICIAL!S13,M13<>OFICIAL!T13),6,IF(AND(K13=OFICIAL!R13,OFICIAL!S13=OFICIAL!T13,M13<>OFICIAL!T13),6,IF(AND(K13=OFICIAL!R13,L13<>OFICIAL!S13,OFICIAL!T13=M13),4,IF(AND(K13=OFICIAL!R13,OFICIAL!S13<>L13,OFICIAL!T13<>M13),3,0)))))) -> 4
A14: 46188 | B14: 0.54166667 | C14: Espanha | D14: 4 | E14: x | F14: 0 | G14: Cabo Verde | K14: =IF(D14="","",IF(D14>F14,C14,IF(F14>D14,G14,"EMPATE"))) -> Espanha | L14: =IF(D14="","",IF(D14>F14,D14,IF(F14>D14,F14,D14))) -> 4 | M14: =IF(D14="","",IF(D14<F14,D14,IF(F14<D14,F14,D14))) -> 0 | O14: =IF(OFICIAL!D14="","",IF(AND(K14=OFICIAL!R14,L14=OFICIAL!S14,M14=OFICIAL!T14),9,IF(AND(K14=OFICIAL!R14,L14=OFICIAL!S14,M14<>OFICIAL!T14),6,IF(AND(K14=OFICIAL!R14,OFICIAL!S14=OFICIAL!T14,M14<>OFICIAL!T14),6,IF(AND(K14=OFICIAL!R14,L14<>OFICIAL!S14,OFICIAL!T14=M14),4,IF(AND(K14=OFICIAL!R14,OFICIAL!S14<>L14,OFICIAL!T14<>M14),3,0)))))) -> 0
A15: 46188 | B15: 0.66666667 | C15: Bélgica | D15: 2 | E15: x | F15: 1 | G15: Egito | K15: =IF(D15="","",IF(D15>F15,C15,IF(F15>D15,G15,"EMPATE"))) -> Bélgica | L15: =IF(D15="","",IF(D15>F15,D15,IF(F15>D15,F15,D15))) -> 2 | M15: =IF(D15="","",IF(D15<F15,D15,IF(F15<D15,F15,D15))) -> 1 | O15: =IF(OFICIAL!D15="","",IF(AND(K15=OFICIAL!R15,L15=OFICIAL!S15,M15=OFICIAL!T15),9,IF(AND(K15=OFICIAL!R15,L15=OFICIAL!S15,M15<>OFICIAL!T15),6,IF(AND(K15=OFICIAL!R15,OFICIAL!S15=OFICIAL!T15,M15<>OFICIAL!T15),6,IF(AND(K15=OFICIAL!R15,L15<>OFICIAL!S15,OFICIAL!T15=M15),4,IF(AND(K15=OFICIAL!R15,OFICIAL!S15<>L15,OFICIAL!T15<>M15),3,0)))))) -> 0
A16: 46188 | B16: 0.79166667 | C16: Arábia Saudita | D16: 1 | E16: x | F16: 2 | G16: Uruguai | K16: =IF(D16="","",IF(D16>F16,C16,IF(F16>D16,G16,"EMPATE"))) -> Uruguai | L16: =IF(D16="","",IF(D16>F16,D16,IF(F16>D16,F16,D16))) -> 2 | M16: =IF(D16="","",IF(D16<F16,D16,IF(F16<D16,F16,D16))) -> 1 | O16: =IF(OFICIAL!D16="","",IF(AND(K16=OFICIAL!R16,L16=OFICIAL!S16,M16=OFICIAL!T16),9,IF(AND(K16=OFICIAL!R16,L16=OFICIAL!S16,M16<>OFICIAL!T16),6,IF(AND(K16=OFICIAL!R16,OFICIAL!S16=OFICIAL!T16,M16<>OFICIAL!T16),6,IF(AND(K16=OFICIAL!R16,L16<>OFICIAL!S16,OFICIAL!T16=M16),4,IF(AND(K16=OFICIAL!R16,OFICIAL!S16<>L16,OFICIAL!T16<>M16),3,0)))))) -> 0
A17: 46188 | B17: 0.91666667 | C17: Irã | D17: 1 | E17: x | F17: 1 | G17: Nova Zelândia | K17: =IF(D17="","",IF(D17>F17,C17,IF(F17>D17,G17,"EMPATE"))) -> EMPATE | L17: =IF(D17="","",IF(D17>F17,D17,IF(F17>D17,F17,D17))) -> 1 | M17: =IF(D17="","",IF(D17<F17,D17,IF(F17<D17,F17,D17))) -> 1 | O17: =IF(OFICIAL!D17="","",IF(AND(K17=OFICIAL!R17,L17=OFICIAL!S17,M17=OFICIAL!T17),9,IF(AND(K17=OFICIAL!R17,L17=OFICIAL!S17,M17<>OFICIAL!T17),6,IF(AND(K17=OFICIAL!R17,OFICIAL!S17=OFICIAL!T17,M17<>OFICIAL!T17),6,IF(AND(K17=OFICIAL!R17,L17<>OFICIAL!S17,OFICIAL!T17=M17),4,IF(AND(K17=OFICIAL!R17,OFICIAL!S17<>L17,OFICIAL!T17<>M17),3,0)))))) -> 6
A18: 46189 | B18: 0.66666667 | C18: França | D18: 3 | E18: x | F18: 1 | G18: Senegal | K18: =IF(D18="","",IF(D18>F18,C18,IF(F18>D18,G18,"EMPATE"))) -> França | L18: =IF(D18="","",IF(D18>F18,D18,IF(F18>D18,F18,D18))) -> 3 | M18: =IF(D18="","",IF(D18<F18,D18,IF(F18<D18,F18,D18))) -> 1 | O18: =IF(OFICIAL!D18="","",IF(AND(K18=OFICIAL!R18,L18=OFICIAL!S18,M18=OFICIAL!T18),9,IF(AND(K18=OFICIAL!R18,L18=OFICIAL!S18,M18<>OFICIAL!T18),6,IF(AND(K18=OFICIAL!R18,OFICIAL!S18=OFICIAL!T18,M18<>OFICIAL!T18),6,IF(AND(K18=OFICIAL!R18,L18<>OFICIAL!S18,OFICIAL!T18=M18),4,IF(AND(K18=OFICIAL!R18,OFICIAL!S18<>L18,OFICIAL!T18<>M18),3,0)))))) -> 9
A19: 46189 | B19: 0.79166667 | C19: Iraque | D19: 1 | E19: x | F19: 1 | G19: Noruega | K19: =IF(D19="","",IF(D19>F19,C19,IF(F19>D19,G19,"EMPATE"))) -> EMPATE | L19: =IF(D19="","",IF(D19>F19,D19,IF(F19>D19,F19,D19))) -> 1 | M19: =IF(D19="","",IF(D19<F19,D19,IF(F19<D19,F19,D19))) -> 1 | O19: =IF(OFICIAL!D19="","",IF(AND(K19=OFICIAL!R19,L19=OFICIAL!S19,M19=OFICIAL!T19),9,IF(AND(K19=OFICIAL!R19,L19=OFICIAL!S19,M19<>OFICIAL!T19),6,IF(AND(K19=OFICIAL!R19,OFICIAL!S19=OFICIAL!T19,M19<>OFICIAL!T19),6,IF(AND(K19=OFICIAL!R19,L19<>OFICIAL!S19,OFICIAL!T19=M19),4,IF(AND(K19=OFICIAL!R19,OFICIAL!S19<>L19,OFICIAL!T19<>M19),3,0)))))) -> 0
A20: 46189 | B20: 0.91666667 | C20: Argentina | D20: 3 | E20: x | F20: 1 | G20: Argélia | K20: =IF(D20="","",IF(D20>F20,C20,IF(F20>D20,G20,"EMPATE"))) -> Argentina | L20: =IF(D20="","",IF(D20>F20,D20,IF(F20>D20,F20,D20))) -> 3 | M20: =IF(D20="","",IF(D20<F20,D20,IF(F20<D20,F20,D20))) -> 1 | O20: =IF(OFICIAL!D20="","",IF(AND(K20=OFICIAL!R20,L20=OFICIAL!S20,M20=OFICIAL!T20),9,IF(AND(K20=OFICIAL!R20,L20=OFICIAL!S20,M20<>OFICIAL!T20),6,IF(AND(K20=OFICIAL!R20,OFICIAL!S20=OFICIAL!T20,M20<>OFICIAL!T20),6,IF(AND(K20=OFICIAL!R20,L20<>OFICIAL!S20,OFICIAL!T20=M20),4,IF(AND(K20=OFICIAL!R20,OFICIAL!S20<>L20,OFICIAL!T20<>M20),3,0)))))) -> 6
A21: 46190 | B21: 0.041666667 | C21: Áustria | D21: 1 | E21: x | F21: 1 | G21: Jordânia | K21: =IF(D21="","",IF(D21>F21,C21,IF(F21>D21,G21,"EMPATE"))) -> EMPATE | L21: =IF(D21="","",IF(D21>F21,D21,IF(F21>D21,F21,D21))) -> 1 | M21: =IF(D21="","",IF(D21<F21,D21,IF(F21<D21,F21,D21))) -> 1 | O21: =IF(OFICIAL!D21="","",IF(AND(K21=OFICIAL!R21,L21=OFICIAL!S21,M21=OFICIAL!T21),9,IF(AND(K21=OFICIAL!R21,L21=OFICIAL!S21,M21<>OFICIAL!T21),6,IF(AND(K21=OFICIAL!R21,OFICIAL!S21=OFICIAL!T21,M21<>OFICIAL!T21),6,IF(AND(K21=OFICIAL!R21,L21<>OFICIAL!S21,OFICIAL!T21=M21),4,IF(AND(K21=OFICIAL!R21,OFICIAL!S21<>L21,OFICIAL!T21<>M21),3,0)))))) -> 0
A22: 46190 | B22: 0.58333333 | C22: Portugal | D22: 5 | E22: x | F22: 1 | G22: RD Congo | K22: =IF(D22="","",IF(D22>F22,C22,IF(F22>D22,G22,"EMPATE"))) -> Portugal | L22: =IF(D22="","",IF(D22>F22,D22,IF(F22>D22,F22,D22))) -> 5 | M22: =IF(D22="","",IF(D22<F22,D22,IF(F22<D22,F22,D22))) -> 1 | O22: =IF(OFICIAL!D22="","",IF(AND(K22=OFICIAL!R22,L22=OFICIAL!S22,M22=OFICIAL!T22),9,IF(AND(K22=OFICIAL!R22,L22=OFICIAL!S22,M22<>OFICIAL!T22),6,IF(AND(K22=OFICIAL!R22,OFICIAL!S22=OFICIAL!T22,M22<>OFICIAL!T22),6,IF(AND(K22=OFICIAL!R22,L22<>OFICIAL!S22,OFICIAL!T22=M22),4,IF(AND(K22=OFICIAL!R22,OFICIAL!S22<>L22,OFICIAL!T22<>M22),3,0)))))) -> 0
A23: 46190 | B23: 0.70833333 | C23: Inglaterra | D23: 2 | E23: x | F23: 2 | G23: Croácia | K23: =IF(D23="","",IF(D23>F23,C23,IF(F23>D23,G23,"EMPATE"))) -> EMPATE | L23: =IF(D23="","",IF(D23>F23,D23,IF(F23>D23,F23,D23))) -> 2 | M23: =IF(D23="","",IF(D23<F23,D23,IF(F23<D23,F23,D23))) -> 2 | O23: =IF(OFICIAL!D23="","",IF(AND(K23=OFICIAL!R23,L23=OFICIAL!S23,M23=OFICIAL!T23),9,IF(AND(K23=OFICIAL!R23,L23=OFICIAL!S23,M23<>OFICIAL!T23),6,IF(AND(K23=OFICIAL!R23,OFICIAL!S23=OFICIAL!T23,M23<>OFICIAL!T23),6,IF(AND(K23=OFICIAL!R23,L23<>OFICIAL!S23,OFICIAL!T23=M23),4,IF(AND(K23=OFICIAL!R23,OFICIAL!S23<>L23,OFICIAL!T23<>M23),3,0)))))) -> 0
A24: 46190 | B24: 0.83333333 | C24: Gana | D24: 2 | E24: x | F24: 1 | G24: Panamá | K24: =IF(D24="","",IF(D24>F24,C24,IF(F24>D24,G24,"EMPATE"))) -> Gana | L24: =IF(D24="","",IF(D24>F24,D24,IF(F24>D24,F24,D24))) -> 2 | M24: =IF(D24="","",IF(D24<F24,D24,IF(F24<D24,F24,D24))) -> 1 | O24: =IF(OFICIAL!D24="","",IF(AND(K24=OFICIAL!R24,L24=OFICIAL!S24,M24=OFICIAL!T24),9,IF(AND(K24=OFICIAL!R24,L24=OFICIAL!S24,M24<>OFICIAL!T24),6,IF(AND(K24=OFICIAL!R24,OFICIAL!S24=OFICIAL!T24,M24<>OFICIAL!T24),6,IF(AND(K24=OFICIAL!R24,L24<>OFICIAL!S24,OFICIAL!T24=M24),4,IF(AND(K24=OFICIAL!R24,OFICIAL!S24<>L24,OFICIAL!T24<>M24),3,0)))))) -> 3
... A73: 46200 | B73: 0.95833333 | C73: Argélia | D73: 1 | E73: x | F73: 2 | G73: Áustria | K73: =IF(D73="","",IF(D73>F73,C73,IF(F73>D73,G73,"EMPATE"))) -> Áustria | L73: =IF(D73="","",IF(D73>F73,D73,IF(F73>D73,F73,D73))) -> 2 | M73: =IF(D73="","",IF(D73<F73,D73,IF(F73<D73,F73,D73))) -> 1 | O73: =IF(OFICIAL!D73="","",IF(AND(K73=OFICIAL!R73,L73=OFICIAL!S73,M73=OFICIAL!T73),9,IF(AND(K73=OFICIAL!R73,L73=OFICIAL!S73,M73<>OFICIAL!T73),6,IF(AND(K73=OFICIAL!R73,OFICIAL!S73=OFICIAL!T73,M73<>OFICIAL!T73),6,IF(AND(K73=OFICIAL!R73,L73<>OFICIAL!S73,OFICIAL!T73=M73),4,IF(AND(K73=OFICIAL!R73,OFICIAL!S73<>L73,OFICIAL!T73<>M73),3,0))))))
A74: 46201 | B74: 0.66666667 | C74: 2º A | E74: x | G74: 2º B | K74: =IF(D74="","",IF(D74>F74,C74,IF(F74>D74,G74,"EMPATE"))) | L74: =IF(D74="","",IF(D74>F74,D74,IF(F74>D74,F74,D74))) | M74: =IF(D74="","",IF(D74<F74,D74,IF(F74<D74,F74,D74))) | O74: =IF(OFICIAL!D74="","",IF(AND(K74=OFICIAL!R74,L74=OFICIAL!S74,M74=OFICIAL!T74),9,IF(AND(K74=OFICIAL!R74,L74=OFICIAL!S74,M74<>OFICIAL!T74),6,IF(AND(K74=OFICIAL!R74,OFICIAL!S74=OFICIAL!T74,M74<>OFICIAL!T74),6,IF(AND(K74=OFICIAL!R74,L74<>OFICIAL!S74,OFICIAL!T74=M74),4,IF(AND(K74=OFICIAL!R74,OFICIAL!S74<>L74,OFICIAL!T74<>M74),3,0))))))
A75: 46202 | B75: 0.58333333 | C75: 1º C | E75: x | G75: 2º F | K75: =IF(D75="","",IF(D75>F75,C75,IF(F75>D75,G75,"EMPATE"))) | L75: =IF(D75="","",IF(D75>F75,D75,IF(F75>D75,F75,D75))) | M75: =IF(D75="","",IF(D75<F75,D75,IF(F75<D75,F75,D75))) | O75: =IF(OFICIAL!D75="","",IF(AND(K75=OFICIAL!R75,L75=OFICIAL!S75,M75=OFICIAL!T75),9,IF(AND(K75=OFICIAL!R75,L75=OFICIAL!S75,M75<>OFICIAL!T75),6,IF(AND(K75=OFICIAL!R75,OFICIAL!S75=OFICIAL!T75,M75<>OFICIAL!T75),6,IF(AND(K75=OFICIAL!R75,L75<>OFICIAL!S75,OFICIAL!T75=M75),4,IF(AND(K75=OFICIAL!R75,OFICIAL!S75<>L75,OFICIAL!T75<>M75),3,0))))))
A76: 46202 | B76: 0.72916667 | C76: 1º E | E76: x | G76: 3º ABCDF | K76: =IF(D76="","",IF(D76>F76,C76,IF(F76>D76,G76,"EMPATE"))) | L76: =IF(D76="","",IF(D76>F76,D76,IF(F76>D76,F76,D76))) | M76: =IF(D76="","",IF(D76<F76,D76,IF(F76<D76,F76,D76))) | O76: =IF(OFICIAL!D76="","",IF(AND(K76=OFICIAL!R76,L76=OFICIAL!S76,M76=OFICIAL!T76),9,IF(AND(K76=OFICIAL!R76,L76=OFICIAL!S76,M76<>OFICIAL!T76),6,IF(AND(K76=OFICIAL!R76,OFICIAL!S76=OFICIAL!T76,M76<>OFICIAL!T76),6,IF(AND(K76=OFICIAL!R76,L76<>OFICIAL!S76,OFICIAL!T76=M76),4,IF(AND(K76=OFICIAL!R76,OFICIAL!S76<>L76,OFICIAL!T76<>M76),3,0))))))
A77: 46202 | B77: 0.91666667 | C77: 1º F | E77: x | G77: 2º C | K77: =IF(D77="","",IF(D77>F77,C77,IF(F77>D77,G77,"EMPATE"))) | L77: =IF(D77="","",IF(D77>F77,D77,IF(F77>D77,F77,D77))) | M77: =IF(D77="","",IF(D77<F77,D77,IF(F77<D77,F77,D77))) | O77: =IF(OFICIAL!D77="","",IF(AND(K77=OFICIAL!R77,L77=OFICIAL!S77,M77=OFICIAL!T77),9,IF(AND(K77=OFICIAL!R77,L77=OFICIAL!S77,M77<>OFICIAL!T77),6,IF(AND(K77=OFICIAL!R77,OFICIAL!S77=OFICIAL!T77,M77<>OFICIAL!T77),6,IF(AND(K77=OFICIAL!R77,L77<>OFICIAL!S77,OFICIAL!T77=M77),4,IF(AND(K77=OFICIAL!R77,OFICIAL!S77<>L77,OFICIAL!T77<>M77),3,0))))))
A78: 46203 | B78: 0.58333333 | C78: 2º E | E78: x | G78: 2º I | K78: =IF(D78="","",IF(D78>F78,C78,IF(F78>D78,G78,"EMPATE"))) | L78: =IF(D78="","",IF(D78>F78,D78,IF(F78>D78,F78,D78))) | M78: =IF(D78="","",IF(D78<F78,D78,IF(F78<D78,F78,D78))) | O78: =IF(OFICIAL!D78="","",IF(AND(K78=OFICIAL!R78,L78=OFICIAL!S78,M78=OFICIAL!T78),9,IF(AND(K78=OFICIAL!R78,L78=OFICIAL!S78,M78<>OFICIAL!T78),6,IF(AND(K78=OFICIAL!R78,OFICIAL!S78=OFICIAL!T78,M78<>OFICIAL!T78),6,IF(AND(K78=OFICIAL!R78,L78<>OFICIAL!S78,OFICIAL!T78=M78),4,IF(AND(K78=OFICIAL!R78,OFICIAL!S78<>L78,OFICIAL!T78<>M78),3,0))))))
A79: 46203 | B79: 0.75 | C79: 1º I | E79: x | G79: 3º CDFGH | K79: =IF(D79="","",IF(D79>F79,C79,IF(F79>D79,G79,"EMPATE"))) | L79: =IF(D79="","",IF(D79>F79,D79,IF(F79>D79,F79,D79))) | M79: =IF(D79="","",IF(D79<F79,D79,IF(F79<D79,F79,D79))) | O79: =IF(OFICIAL!D79="","",IF(AND(K79=OFICIAL!R79,L79=OFICIAL!S79,M79=OFICIAL!T79),9,IF(AND(K79=OFICIAL!R79,L79=OFICIAL!S79,M79<>OFICIAL!T79),6,IF(AND(K79=OFICIAL!R79,OFICIAL!S79=OFICIAL!T79,M79<>OFICIAL!T79),6,IF(AND(K79=OFICIAL!R79,L79<>OFICIAL!S79,OFICIAL!T79=M79),4,IF(AND(K79=OFICIAL!R79,OFICIAL!S79<>L79,OFICIAL!T79<>M79),3,0))))))
A80: 46203 | B80: 0.91666667 | C80: 1º A | E80: x | G80: 3º CEFHI | K80: =IF(D80="","",IF(D80>F80,C80,IF(F80>D80,G80,"EMPATE"))) | L80: =IF(D80="","",IF(D80>F80,D80,IF(F80>D80,F80,D80))) | M80: =IF(D80="","",IF(D80<F80,D80,IF(F80<D80,F80,D80))) | O80: =IF(OFICIAL!D80="","",IF(AND(K80=OFICIAL!R80,L80=OFICIAL!S80,M80=OFICIAL!T80),9,IF(AND(K80=OFICIAL!R80,L80=OFICIAL!S80,M80<>OFICIAL!T80),6,IF(AND(K80=OFICIAL!R80,OFICIAL!S80=OFICIAL!T80,M80<>OFICIAL!T80),6,IF(AND(K80=OFICIAL!R80,L80<>OFICIAL!S80,OFICIAL!T80=M80),4,IF(AND(K80=OFICIAL!R80,OFICIAL!S80<>L80,OFICIAL!T80<>M80),3,0))))))
A81: 46204 | B81: 0.54166667 | C81: 1º L | E81: x | G81: 3º EHIJK | K81: =IF(D81="","",IF(D81>F81,C81,IF(F81>D81,G81,"EMPATE"))) | L81: =IF(D81="","",IF(D81>F81,D81,IF(F81>D81,F81,D81))) | M81: =IF(D81="","",IF(D81<F81,D81,IF(F81<D81,F81,D81))) | O81: =IF(OFICIAL!D81="","",IF(AND(K81=OFICIAL!R81,L81=OFICIAL!S81,M81=OFICIAL!T81),9,IF(AND(K81=OFICIAL!R81,L81=OFICIAL!S81,M81<>OFICIAL!T81),6,IF(AND(K81=OFICIAL!R81,OFICIAL!S81=OFICIAL!T81,M81<>OFICIAL!T81),6,IF(AND(K81=OFICIAL!R81,L81<>OFICIAL!S81,OFICIAL!T81=M81),4,IF(AND(K81=OFICIAL!R81,OFICIAL!S81<>L81,OFICIAL!T81<>M81),3,0))))))
A82: 46204 | B82: 0.70833333 | C82: 1º G | E82: x | G82: 3º AEHIJ | K82: =IF(D82="","",IF(D82>F82,C82,IF(F82>D82,G82,"EMPATE"))) | L82: =IF(D82="","",IF(D82>F82,D82,IF(F82>D82,F82,D82))) | M82: =IF(D82="","",IF(D82<F82,D82,IF(F82<D82,F82,D82))) | O82: =IF(OFICIAL!D82="","",IF(AND(K82=OFICIAL!R82,L82=OFICIAL!S82,M82=OFICIAL!T82),9,IF(AND(K82=OFICIAL!R82,L82=OFICIAL!S82,M82<>OFICIAL!T82),6,IF(AND(K82=OFICIAL!R82,OFICIAL!S82=OFICIAL!T82,M82<>OFICIAL!T82),6,IF(AND(K82=OFICIAL!R82,L82<>OFICIAL!S82,OFICIAL!T82=M82),4,IF(AND(K82=OFICIAL!R82,OFICIAL!S82<>L82,OFICIAL!T82<>M82),3,0))))))
A83: 46204 | B83: 0.875 | C83: 1º D | E83: x | G83: 3º BEFIJ | K83: =IF(D83="","",IF(D83>F83,C83,IF(F83>D83,G83,"EMPATE"))) | L83: =IF(D83="","",IF(D83>F83,D83,IF(F83>D83,F83,D83))) | M83: =IF(D83="","",IF(D83<F83,D83,IF(F83<D83,F83,D83))) | O83: =IF(OFICIAL!D83="","",IF(AND(K83=OFICIAL!R83,L83=OFICIAL!S83,M83=OFICIAL!T83),9,IF(AND(K83=OFICIAL!R83,L83=OFICIAL!S83,M83<>OFICIAL!T83),6,IF(AND(K83=OFICIAL!R83,OFICIAL!S83=OFICIAL!T83,M83<>OFICIAL!T83),6,IF(AND(K83=OFICIAL!R83,L83<>OFICIAL!S83,OFICIAL!T83=M83),4,IF(AND(K83=OFICIAL!R83,OFICIAL!S83<>L83,OFICIAL!T83<>M83),3,0))))))
A84: 46205 | B84: 0.66666667 | C84: 1º H | E84: x | G84: 2º J | K84: =IF(D84="","",IF(D84>F84,C84,IF(F84>D84,G84,"EMPATE"))) | L84: =IF(D84="","",IF(D84>F84,D84,IF(F84>D84,F84,D84))) | M84: =IF(D84="","",IF(D84<F84,D84,IF(F84<D84,F84,D84))) | O84: =IF(OFICIAL!D84="","",IF(AND(K84=OFICIAL!R84,L84=OFICIAL!S84,M84=OFICIAL!T84),9,IF(AND(K84=OFICIAL!R84,L84=OFICIAL!S84,M84<>OFICIAL!T84),6,IF(AND(K84=OFICIAL!R84,OFICIAL!S84=OFICIAL!T84,M84<>OFICIAL!T84),6,IF(AND(K84=OFICIAL!R84,L84<>OFICIAL!S84,OFICIAL!T84=M84),4,IF(AND(K84=OFICIAL!R84,OFICIAL!S84<>L84,OFICIAL!T84<>M84),3,0))))))
A85: 46205 | B85: 0.83333333 | C85: 2º K | E85: x | G85: 2º L | K85: =IF(D85="","",IF(D85>F85,C85,IF(F85>D85,G85,"EMPATE"))) | L85: =IF(D85="","",IF(D85>F85,D85,IF(F85>D85,F85,D85))) | M85: =IF(D85="","",IF(D85<F85,D85,IF(F85<D85,F85,D85))) | O85: =IF(OFICIAL!D85="","",IF(AND(K85=OFICIAL!R85,L85=OFICIAL!S85,M85=OFICIAL!T85),9,IF(AND(K85=OFICIAL!R85,L85=OFICIAL!S85,M85<>OFICIAL!T85),6,IF(AND(K85=OFICIAL!R85,OFICIAL!S85=OFICIAL!T85,M85<>OFICIAL!T85),6,IF(AND(K85=OFICIAL!R85,L85<>OFICIAL!S85,OFICIAL!T85=M85),4,IF(AND(K85=OFICIAL!R85,OFICIAL!S85<>L85,OFICIAL!T85<>M85),3,0))))))
... A105: 46222 | B105: 0.66666667 | C105: Venc. Semifinal 1 | E105: x | G105: Venc. Semifinal 2 | K105: =IF(D105="","",IF(D105>F105,C105,IF(F105>D105,G105,"EMPATE"))) | L105: =IF(D105="","",IF(D105>F105,D105,IF(F105>D105,F105,D105))) | M105: =IF(D105="","",IF(D105<F105,D105,IF(F105<D105,F105,D105))) | O105: =IF(OFICIAL!D105="","",IF(AND(K105=OFICIAL!R105,L105=OFICIAL!S105,M105=OFICIAL!T105),9,IF(AND(K105=OFICIAL!R105,L105=OFICIAL!S105,M105<>OFICIAL!T105),6,IF(AND(K105=OFICIAL!R105,OFICIAL!S105=OFICIAL!T105,M105<>OFICIAL!T105),6,IF(AND(K105=OFICIAL!R105,L105<>OFICIAL!S105,OFICIAL!T105=M105),4,IF(AND(K105=OFICIAL!R105,OFICIAL!S105<>L105,OFICIAL!T105<>M105),3,0))))))

Sheet FERNANDO
A1: PALPITES | H1: FERNANDO | K1: Palpite do Vencedor da Partida | L1: Score Vencedor | M1: Score Perdedor | O1: Pontos Ganhos
A2: 46184 | B2: 0.66666667 | C2: México | D2: 2 | E2: x | F2: 0 | G2: África do Sul | K2: =IF(D2="","",IF(D2>F2,C2,IF(F2>D2,G2,"EMPATE"))) -> México | L2: =IF(D2="","",IF(D2>F2,D2,IF(F2>D2,F2,D2))) -> 2 | M2: =IF(D2="","",IF(D2<F2,D2,IF(F2<D2,F2,D2))) -> 0 | O2: =IF(OFICIAL!D2="","",IF(AND(K2=OFICIAL!R2,L2=OFICIAL!S2,M2=OFICIAL!T2),9,IF(AND(K2=OFICIAL!R2,L2=OFICIAL!S2,M2<>OFICIAL!T2),6,IF(AND(K2=OFICIAL!R2,OFICIAL!S2=OFICIAL!T2,M2<>OFICIAL!T2),6,IF(AND(K2=OFICIAL!R2,L2<>OFICIAL!S2,OFICIAL!T2=M2),4,IF(AND(K2=OFICIAL!R2,OFICIAL!S2<>L2,OFICIAL!T2<>M2),3,0)))))) -> 9
A3: 46184 | B3: 0.95833333 | C3: Coréia do Sul | D3: 1 | E3: x | F3: 1 | G3: República Tcheca | K3: =IF(D3="","",IF(D3>F3,C3,IF(F3>D3,G3,"EMPATE"))) -> EMPATE | L3: =IF(D3="","",IF(D3>F3,D3,IF(F3>D3,F3,D3))) -> 1 | M3: =IF(D3="","",IF(D3<F3,D3,IF(F3<D3,F3,D3))) -> 1 | O3: =IF(OFICIAL!D3="","",IF(AND(K3=OFICIAL!R3,L3=OFICIAL!S3,M3=OFICIAL!T3),9,IF(AND(K3=OFICIAL!R3,L3=OFICIAL!S3,M3<>OFICIAL!T3),6,IF(AND(K3=OFICIAL!R3,OFICIAL!S3=OFICIAL!T3,M3<>OFICIAL!T3),6,IF(AND(K3=OFICIAL!R3,L3<>OFICIAL!S3,OFICIAL!T3=M3),4,IF(AND(K3=OFICIAL!R3,OFICIAL!S3<>L3,OFICIAL!T3<>M3),3,0)))))) -> 0
A4: 46185 | B4: 0.66666667 | C4: Canadá | D4: 0 | E4: x | F4: 2 | G4: Bósnia | K4: =IF(D4="","",IF(D4>F4,C4,IF(F4>D4,G4,"EMPATE"))) -> Bósnia | L4: =IF(D4="","",IF(D4>F4,D4,IF(F4>D4,F4,D4))) -> 2 | M4: =IF(D4="","",IF(D4<F4,D4,IF(F4<D4,F4,D4))) -> 0 | O4: =IF(OFICIAL!D4="","",IF(AND(K4=OFICIAL!R4,L4=OFICIAL!S4,M4=OFICIAL!T4),9,IF(AND(K4=OFICIAL!R4,L4=OFICIAL!S4,M4<>OFICIAL!T4),6,IF(AND(K4=OFICIAL!R4,OFICIAL!S4=OFICIAL!T4,M4<>OFICIAL!T4),6,IF(AND(K4=OFICIAL!R4,L4<>OFICIAL!S4,OFICIAL!T4=M4),4,IF(AND(K4=OFICIAL!R4,OFICIAL!S4<>L4,OFICIAL!T4<>M4),3,0)))))) -> 0
A5: 46185 | B5: 0.91666667 | C5: Estados Unidos | D5: 2 | E5: x | F5: 0 | G5: Paraguai | K5: =IF(D5="","",IF(D5>F5,C5,IF(F5>D5,G5,"EMPATE"))) -> Estados Unidos | L5: =IF(D5="","",IF(D5>F5,D5,IF(F5>D5,F5,D5))) -> 2 | M5: =IF(D5="","",IF(D5<F5,D5,IF(F5<D5,F5,D5))) -> 0 | O5: =IF(OFICIAL!D5="","",IF(AND(K5=OFICIAL!R5,L5=OFICIAL!S5,M5=OFICIAL!T5),9,IF(AND(K5=OFICIAL!R5,L5=OFICIAL!S5,M5<>OFICIAL!T5),6,IF(AND(K5=OFICIAL!R5,OFICIAL!S5=OFICIAL!T5,M5<>OFICIAL!T5),6,IF(AND(K5=OFICIAL!R5,L5<>OFICIAL!S5,OFICIAL!T5=M5),4,IF(AND(K5=OFICIAL!R5,OFICIAL!S5<>L5,OFICIAL!T5<>M5),3,0)))))) -> 3
A6: 46186 | B6: 0.66666667 | C6: Catar | D6: 2 | E6: x | F6: 0 | G6: Suíça | H6: PONTOS | I6: QTD | J6: TOTAL | K6: =IF(D6="","",IF(D6>F6,C6,IF(F6>D6,G6,"EMPATE"))) -> Catar | L6: =IF(D6="","",IF(D6>F6,D6,IF(F6>D6,F6,D6))) -> 2 | M6: =IF(D6="","",IF(D6<F6,D6,IF(F6<D6,F6,D6))) -> 0 | O6: =IF(OFICIAL!D6="","",IF(AND(K6=OFICIAL!R6,L6=OFICIAL!S6,M6=OFICIAL!T6),9,IF(AND(K6=OFICIAL!R6,L6=OFICIAL!S6,M6<>OFICIAL!T6),6,IF(AND(K6=OFICIAL!R6,OFICIAL!S6=OFICIAL!T6,M6<>OFICIAL!T6),6,IF(AND(K6=OFICIAL!R6,L6<>OFICIAL!S6,OFICIAL!T6=M6),4,IF(AND(K6=OFICIAL!R6,OFICIAL!S6<>L6,OFICIAL!T6<>M6),3,0)))))) -> 0
A7: 46186 | B7: 0.79166667 | C7: Brasil | D7: 2 | E7: x | F7: 0 | G7: Marrocos | H7: 9 | I7: =COUNTIF($O$2:$O$65,9) -> 3 | J7: =H7*I7 -> 27 | K7: =IF(D7="","",IF(D7>F7,C7,IF(F7>D7,G7,"EMPATE"))) -> Brasil | L7: =IF(D7="","",IF(D7>F7,D7,IF(F7>D7,F7,D7))) -> 2 | M7: =IF(D7="","",IF(D7<F7,D7,IF(F7<D7,F7,D7))) -> 0 | O7: =IF(OFICIAL!D7="","",IF(AND(K7=OFICIAL!R7,L7=OFICIAL!S7,M7=OFICIAL!T7),9,IF(AND(K7=OFICIAL!R7,L7=OFICIAL!S7,M7<>OFICIAL!T7),6,IF(AND(K7=OFICIAL!R7,OFICIAL!S7=OFICIAL!T7,M7<>OFICIAL!T7),6,IF(AND(K7=OFICIAL!R7,L7<>OFICIAL!S7,OFICIAL!T7=M7),4,IF(AND(K7=OFICIAL!R7,OFICIAL!S7<>L7,OFICIAL!T7<>M7),3,0)))))) -> 0
A8: 46186 | B8: 0.91666667 | C8: Haiti | D8: 1 | E8: x | F8: 1 | G8: Escócia | H8: 6 | I8: =COUNTIF($O$2:$O$65,6) -> 3 | J8: =H8*I8 -> 18 | K8: =IF(D8="","",IF(D8>F8,C8,IF(F8>D8,G8,"EMPATE"))) -> EMPATE | L8: =IF(D8="","",IF(D8>F8,D8,IF(F8>D8,F8,D8))) -> 1 | M8: =IF(D8="","",IF(D8<F8,D8,IF(F8<D8,F8,D8))) -> 1 | O8: =IF(OFICIAL!D8="","",IF(AND(K8=OFICIAL!R8,L8=OFICIAL!S8,M8=OFICIAL!T8),9,IF(AND(K8=OFICIAL!R8,L8=OFICIAL!S8,M8<>OFICIAL!T8),6,IF(AND(K8=OFICIAL!R8,OFICIAL!S8=OFICIAL!T8,M8<>OFICIAL!T8),6,IF(AND(K8=OFICIAL!R8,L8<>OFICIAL!S8,OFICIAL!T8=M8),4,IF(AND(K8=OFICIAL!R8,OFICIAL!S8<>L8,OFICIAL!T8<>M8),3,0)))))) -> 0
A9: 46187 | B9: 0.041666667 | C9: Austrália | D9: 2 | E9: x | F9: 1 | G9: Turquia | H9: 4 | I9: =COUNTIF($O$2:$O$65,4) -> 6 | J9: =H9*I9 -> 24 | K9: =IF(D9="","",IF(D9>F9,C9,IF(F9>D9,G9,"EMPATE"))) -> Austrália | L9: =IF(D9="","",IF(D9>F9,D9,IF(F9>D9,F9,D9))) -> 2 | M9: =IF(D9="","",IF(D9<F9,D9,IF(F9<D9,F9,D9))) -> 1 | O9: =IF(OFICIAL!D9="","",IF(AND(K9=OFICIAL!R9,L9=OFICIAL!S9,M9=OFICIAL!T9),9,IF(AND(K9=OFICIAL!R9,L9=OFICIAL!S9,M9<>OFICIAL!T9),6,IF(AND(K9=OFICIAL!R9,OFICIAL!S9=OFICIAL!T9,M9<>OFICIAL!T9),6,IF(AND(K9=OFICIAL!R9,L9<>OFICIAL!S9,OFICIAL!T9=M9),4,IF(AND(K9=OFICIAL!R9,OFICIAL!S9<>L9,OFICIAL!T9<>M9),3,0)))))) -> 6
A10: 46187 | B10: 0.58333333 | C10: Alemanha | D10: 4 | E10: x | F10: 0 | G10: Curaçao | H10: 3 | I10: =COUNTIF($O$2:$O$65,3) -> 9 | J10: =H10*I10 -> 27 | K10: =IF(D10="","",IF(D10>F10,C10,IF(F10>D10,G10,"EMPATE"))) -> Alemanha | L10: =IF(D10="","",IF(D10>F10,D10,IF(F10>D10,F10,D10))) -> 4 | M10: =IF(D10="","",IF(D10<F10,D10,IF(F10<D10,F10,D10))) -> 0 | O10: =IF(OFICIAL!D10="","",IF(AND(K10=OFICIAL!R10,L10=OFICIAL!S10,M10=OFICIAL!T10),9,IF(AND(K10=OFICIAL!R10,L10=OFICIAL!S10,M10<>OFICIAL!T10),6,IF(AND(K10=OFICIAL!R10,OFICIAL!S10=OFICIAL!T10,M10<>OFICIAL!T10),6,IF(AND(K10=OFICIAL!R10,L10<>OFICIAL!S10,OFICIAL!T10=M10),4,IF(AND(K10=OFICIAL!R10,OFICIAL!S10<>L10,OFICIAL!T10<>M10),3,0)))))) -> 3
A11: 46187 | B11: 0.70833333 | C11: Holanda | D11: 2 | E11: x | F11: 3 | G11: Japão | H11: 0 | I11: =COUNTIF($O$2:$O$65,0) -> 23 | J11: =H11*I11 -> 0 | K11: =IF(D11="","",IF(D11>F11,C11,IF(F11>D11,G11,"EMPATE"))) -> Japão | L11: =IF(D11="","",IF(D11>F11,D11,IF(F11>D11,F11,D11))) -> 3 | M11: =IF(D11="","",IF(D11<F11,D11,IF(F11<D11,F11,D11))) -> 2 | O11: =IF(OFICIAL!D11="","",IF(AND(K11=OFICIAL!R11,L11=OFICIAL!S11,M11=OFICIAL!T11),9,IF(AND(K11=OFICIAL!R11,L11=OFICIAL!S11,M11<>OFICIAL!T11),6,IF(AND(K11=OFICIAL!R11,OFICIAL!S11=OFICIAL!T11,M11<>OFICIAL!T11),6,IF(AND(K11=OFICIAL!R11,L11<>OFICIAL!S11,OFICIAL!T11=M11),4,IF(AND(K11=OFICIAL!R11,OFICIAL!S11<>L11,OFICIAL!T11<>M11),3,0)))))) -> 0
