Workbook

Sheet OFICIAL
A1: JOGOS | I1: OFICIAL | R1: Vencedor da Partida | S1: Score Vencedor | T1: Score Perdedor
A2: 46184 | B2: 0.66666667 | C2: México | D2: 2 | E2: x | F2: 0 | G2: África do Sul | R2: =IF(D2="","",IF(D2>F2,C2,IF(F2>D2,G2,"EMPATE"))) -> México | S2: =IF(D2="","",IF(D2>F2,D2,IF(F2>D2,F2,D2))) -> 2 | T2: =IF(D2="","",IF(D2<F2,D2,IF(F2<D2,F2,D2))) -> 0 | V2: LEGENDA
A3: 46184 | B3: 0.95833333 | C3: Coréia do Sul | D3: 2 | E3: x | F3: 1 | G3: República Tcheca | R3: =IF(D3="","",IF(D3>F3,C3,IF(F3>D3,G3,"EMPATE"))) -> Coréia do Sul | S3: =IF(D3="","",IF(D3>F3,D3,IF(F3>D3,F3,D3))) -> 2 | T3: =IF(D3="","",IF(D3<F3,D3,IF(F3<D3,F3,D3))) -> 1
A4: 46185 | B4: 0.66666667 | C4: Canadá | D4: 1 | E4: x | F4: 1 | G4: Bósnia | R4: =IF(D4="","",IF(D4>F4,C4,IF(F4>D4,G4,"EMPATE"))) -> EMPATE | S4: =IF(D4="","",IF(D4>F4,D4,IF(F4>D4,F4,D4))) -> 1 | T4: =IF(D4="","",IF(D4<F4,D4,IF(F4<D4,F4,D4))) -> 1 | V4: 9 PONTOS | W4: VENCEDOR COM PLACAR CORRETO OU EMPATE COM PLACAR CORRETO
A5: 46185 | B5: 0.91666667 | C5: Estados Unidos | D5: 4 | E5: x | F5: 1 | G5: Paraguai | I5: RUMO AO HEXA! | R5: =IF(D5="","",IF(D5>F5,C5,IF(F5>D5,G5,"EMPATE"))) -> Estados Unidos | S5: =IF(D5="","",IF(D5>F5,D5,IF(F5>D5,F5,D5))) -> 4 | T5: =IF(D5="","",IF(D5<F5,D5,IF(F5<D5,F5,D5))) -> 1 | V5: 6 PONTOS | W5: VENCEDOR COM APENAS O NÚMERO DE GOLS DO VENCEDOR CORRETO OU EMPATE COM O NÚMERO DE GOLS ERRADO
A6: 46186 | B6: 0.66666667 | C6: Catar | D6: 1 | E6: x | F6: 1 | G6: Suíça | R6: =IF(D6="","",IF(D6>F6,C6,IF(F6>D6,G6,"EMPATE"))) -> EMPATE | S6: =IF(D6="","",IF(D6>F6,D6,IF(F6>D6,F6,D6))) -> 1 | T6: =IF(D6="","",IF(D6<F6,D6,IF(F6<D6,F6,D6))) -> 1 | V6: 4 PONTOS | W6: VENCEDOR COM APENAS O NÚMERO DE GOLS DO PERDEDOR CORRETO
A7: 46186 | B7: 0.79166667 | C7: Brasil | D7: 1 | E7: x | F7: 1 | G7: Marrocos | R7: =IF(D7="","",IF(D7>F7,C7,IF(F7>D7,G7,"EMPATE"))) -> EMPATE | S7: =IF(D7="","",IF(D7>F7,D7,IF(F7>D7,F7,D7))) -> 1 | T7: =IF(D7="","",IF(D7<F7,D7,IF(F7<D7,F7,D7))) -> 1 | V7: 3 PONTOS | W7: VENCEDOR COM AMBOS OS NÚMERO DE GOLS ERRADO
A8: 46186 | B8: 0.91666667 | C8: Haiti | D8: 0 | E8: x | F8: 1 | G8: Escócia | R8: =IF(D8="","",IF(D8>F8,C8,IF(F8>D8,G8,"EMPATE"))) -> Escócia | S8: =IF(D8="","",IF(D8>F8,D8,IF(F8>D8,F8,D8))) -> 1 | T8: =IF(D8="","",IF(D8<F8,D8,IF(F8<D8,F8,D8))) -> 0 | V8: 0 PONTOS | W8: ERROU O VENCEDOR OU ERROU O JOGO QUE FOI EMPATE
A9: 46187 | B9: 0.041666667 | C9: Austrália | D9: 2 | E9: x | F9: 0 | G9: Turquia | I9: Copa Phibra 2026 | R9: =IF(D9="","",IF(D9>F9,C9,IF(F9>D9,G9,"EMPATE"))) -> Austrália | S9: =IF(D9="","",IF(D9>F9,D9,IF(F9>D9,F9,D9))) -> 2 | T9: =IF(D9="","",IF(D9<F9,D9,IF(F9<D9,F9,D9))) -> 0
A10: 46187 | B10: 0.58333333 | C10: Alemanha | D10: 7 | E10: x | F10: 1 | G10: Curaçao | I10: Posição | J10: Phibriano | K10: Pontos | L10: 9 | M10: 6 | N10: 4 | O10: 3 | P10: 0 | R10: =IF(D10="","",IF(D10>F10,C10,IF(F10>D10,G10,"EMPATE"))) -> Alemanha | S10: =IF(D10="","",IF(D10>F10,D10,IF(F10>D10,F10,D10))) -> 7 | T10: =IF(D10="","",IF(D10<F10,D10,IF(F10<D10,F10,D10))) -> 1 | V10: CRITÉRIOS DE DESEMPATE
A11: 46187 | B11: 0.70833333 | C11: Holanda | D11: 2 | E11: x | F11: 2 | G11: Japão | H11: =(K11*1000000+L11*10000+M11*1000+N11*100+O11*10) -> 208063690 | I11: =_xlfn.RANK.EQ(H11,$H$11:$H$20) -> 3 | J11: Bernardo | K11: =SUM(BERNARDO!$O$2:$O$105) -> 208 | L11: =COUNTIF(BERNARDO!$O$2:'BERNARDO'!$O$105,"9") -> 5 | M11: =COUNTIF(BERNARDO!$O$2:'BERNARDO'!$O$105,"6") -> 12 | N11: =COUNTIF(BERNARDO!$O$2:'BERNARDO'!$O$105,"4") -> 16 | O11: =COUNTIF(BERNARDO!$O$2:'BERNARDO'!$O$105,"3") -> 9 | P11: =COUNTIF(BERNARDO!$O$2:'BERNARDO'!$O$105,"0") -> 30 | Q11: =L11*9+M11*6+N11*4+O11*3 -> 208 | R11: =IF(D11="","",IF(D11>F11,C11,IF(F11>D11,G11,"EMPATE"))) -> EMPATE | S11: =IF(D11="","",IF(D11>F11,D11,IF(F11>D11,F11,D11))) -> 2 | T11: =IF(D11="","",IF(D11<F11,D11,IF(F11<D11,F11,D11))) -> 2 | V11: MAIOR NÚMERO DE JOGOS COM 9 PONTOS
A12: 46187 | B12: 0.83333333 | C12: Costa do Marfim | D12: 1 | E12: x | F12: 0 | G12: Equador | H12: =(K12*1000000+L12*10000+M12*1000+N12*100+O12*10) -> 203061280 | I12: =_xlfn.RANK.EQ(H12,$H$11:$H$20) -> 4 | J12: Thiago | K12: =SUM(THIAGO!$O$2:$O$105) -> 203 | L12: =COUNTIF(THIAGO!$O$2:'THIAGO'!$O$105,"9") -> 5 | M12: =COUNTIF(THIAGO!$O$2:'THIAGO'!$O$105,"6") -> 10 | N12: =COUNTIF(THIAGO!$O$2:'THIAGO'!$O$105,"4") -> 11 | O12: =COUNTIF(THIAGO!$O$2:'THIAGO'!$O$105,"3") -> 18 | P12: =COUNTIF(THIAGO!$O$2:'THIAGO'!$O$105,"0") -> 28 | Q12: =L12*9+M12*6+N12*4+O12*3 -> 203 | R12: =IF(D12="","",IF(D12>F12,C12,IF(F12>D12,G12,"EMPATE"))) -> Costa do Marfim | S12: =IF(D12="","",IF(D12>F12,D12,IF(F12>D12,F12,D12))) -> 1 | T12: =IF(D12="","",IF(D12<F12,D12,IF(F12<D12,F12,D12))) -> 0 | V12: MAIOR NÚMERO DE JOGOS COM 6 PONTOS
A13: 46187 | B13: 0.95833333 | C13: Suécia | D13: 5 | E13: x | F13: 1 | G13: Tunísia | H13: =(K13*1000000+L13*10000+M13*1000+N13*100+O13*10) -> 192057670 | I13: =_xlfn.RANK.EQ(H13,$H$11:$H$20) -> 5 | J13: Ricardo | K13: =SUM(RICARDO!$O$2:$O$105) -> 192 | L13: =COUNTIF(RICARDO!$O$2:'RICARDO'!$O$105,"9") -> 5 | M13: =COUNTIF(RICARDO!$O$2:'RICARDO'!$O$105,"6") -> 6 | N13: =COUNTIF(RICARDO!$O$2:'RICARDO'!$O$105,"4") -> 15 | O13: =COUNTIF(RICARDO!$O$2:'RICARDO'!$O$105,"3") -> 17 | P13: =COUNTIF(RICARDO!$O$2:'RICARDO'!$O$105,"0") -> 29 | Q13: =L13*9+M13*6+N13*4+O13*3 -> 192 | R13: =IF(D13="","",IF(D13>F13,C13,IF(F13>D13,G13,"EMPATE"))) -> Suécia | S13: =IF(D13="","",IF(D13>F13,D13,IF(F13>D13,F13,D13))) -> 5 | T13: =IF(D13="","",IF(D13<F13,D13,IF(F13<D13,F13,D13))) -> 1 | V13: MAIOR NÚMERO DE JOGOS COM 4 PONTOS
A14: 46188 | B14: 0.54166667 | C14: Espanha | D14: 0 | E14: x | F14: 0 | G14: Cabo Verde | H14: =(K14*1000000+L14*10000+M14*1000+N14*100+O14*10) -> 166058850 | I14: =_xlfn.RANK.EQ(H14,$H$11:$H$20) -> 9 | J14: Fernando | K14: =SUM(FERNANDO!$O$2:$O$105) -> 166 | L14: =COUNTIF(FERNANDO!$O$2:'FERNANDO'!$O$105,"9") -> 5 | M14: =COUNTIF(FERNANDO!$O$2:'FERNANDO'!$O$105,"6") -> 8 | N14: =COUNTIF(FERNANDO!$O$2:'FERNANDO'!$O$105,"4") -> 7 | O14: =COUNTIF(FERNANDO!$O$2:'FERNANDO'!$O$105,"3") -> 15 | P14: =COUNTIF(FERNANDO!$O$2:'FERNANDO'!$O$105,"0") -> 37 | Q14: =L14*9+M14*6+N14*4+O14*3 -> 166 | R14: =IF(D14="","",IF(D14>F14,C14,IF(F14>D14,G14,"EMPATE"))) -> EMPATE | S14: =IF(D14="","",IF(D14>F14,D14,IF(F14>D14,F14,D14))) -> 0 | T14: =IF(D14="","",IF(D14<F14,D14,IF(F14<D14,F14,D14))) -> 0 | V14: MAIOR NÚMERO DE JOGOS COM 3 PONTOS
A15: 46188 | B15: 0.66666667 | C15: Bélgica | D15: 1 | E15: x | F15: 1 | G15: Egito | H15: =(K15*1000000+L15*10000+M15*1000+N15*100+O15*10) -> 174074350 | I15: =_xlfn.RANK.EQ(H15,$H$11:$H$20) -> 8 | J15: Gustavo | K15: =SUM(GUSTAVO!$O$2:$O$105) -> 174 | L15: =COUNTIF(GUSTAVO!$O$2:'GUSTAVO'!$O$105,"9") -> 7 | M15: =COUNTIF(GUSTAVO!$O$2:'GUSTAVO'!$O$105,"6") -> 3 | N15: =COUNTIF(GUSTAVO!$O$2:'GUSTAVO'!$O$105,"4") -> 12 | O15: =COUNTIF(GUSTAVO!$O$2:'GUSTAVO'!$O$105,"3") -> 15 | P15: =COUNTIF(GUSTAVO!$O$2:'GUSTAVO'!$O$105,"0") -> 35 | Q15: =L15*9+M15*6+N15*4+O15*3 -> 174 | R15: =IF(D15="","",IF(D15>F15,C15,IF(F15>D15,G15,"EMPATE"))) -> EMPATE | S15: =IF(D15="","",IF(D15>F15,D15,IF(F15>D15,F15,D15))) -> 1 | T15: =IF(D15="","",IF(D15<F15,D15,IF(F15<D15,F15,D15))) -> 1 | V15: SORTEIO
A16: 46188 | B16: 0.79166667 | C16: Arábia Saudita | D16: 1 | E16: x | F16: 1 | G16: Uruguai | H16: =(K16*1000000+L16*10000+M16*1000+N16*100+O16*10) -> 191074060 | I16: =_xlfn.RANK.EQ(H16,$H$11:$H$20) -> 6 | J16: Marcio | K16: =SUM(MARCIO!$O$2:$O$105) -> 191 | L16: =COUNTIF(MARCIO!$O$2:'MARCIO'!$O$105,"9") -> 7 | M16: =COUNTIF(MARCIO!$O$2:'MARCIO'!$O$105,"6") -> 3 | N16: =COUNTIF(MARCIO!$O$2:'MARCIO'!$O$105,"4") -> 8 | O16: =COUNTIF(MARCIO!$O$2:'MARCIO'!$O$105,"3") -> 26 | P16: =COUNTIF(MARCIO!$O$2:'MARCIO'!$O$105,"0") -> 28 | Q16: =L16*9+M16*6+N16*4+O16*3 -> 191 | R16: =IF(D16="","",IF(D16>F16,C16,IF(F16>D16,G16,"EMPATE"))) -> EMPATE | S16: =IF(D16="","",IF(D16>F16,D16,IF(F16>D16,F16,D16))) -> 1 | T16: =IF(D16="","",IF(D16<F16,D16,IF(F16<D16,F16,D16))) -> 1
A17: 46188 | B17: 0.91666667 | C17: Irã | D17: 2 | E17: x | F17: 2 | G17: Nova Zelândia | H17: =(K17*1000000+L17*10000+M17*1000+N17*100+O17*10) -> 177064650 | I17: =_xlfn.RANK.EQ(H17,$H$11:$H$20) -> 7 | J17: Gabriel | K17: =SUM(GABRIEL!$O$2:$O$105) -> 177 | L17: =COUNTIF(GABRIEL!$O$2:'GABRIEL'!$O$105,"9") -> 6 | M17: =COUNTIF(GABRIEL!$O$2:'GABRIEL'!$O$105,"6") -> 3 | N17: =COUNTIF(GABRIEL!$O$2:'GABRIEL'!$O$105,"4") -> 15 | O17: =COUNTIF(GABRIEL!$O$2:'GABRIEL'!$O$105,"3") -> 15 | P17: =COUNTIF(GABRIEL!$O$2:'GABRIEL'!$O$105,"0") -> 33 | Q17: =L17*9+M17*6+N17*4+O17*3 -> 177 | R17: =IF(D17="","",IF(D17>F17,C17,IF(F17>D17,G17,"EMPATE"))) -> EMPATE | S17: =IF(D17="","",IF(D17>F17,D17,IF(F17>D17,F17,D17))) -> 2 | T17: =IF(D17="","",IF(D17<F17,D17,IF(F17<D17,F17,D17))) -> 2
A18: 46189 | B18: 0.66666667 | C18: França | D18: 3 | E18: x | F18: 1 | G18: Senegal | H18: =(K18*1000000+L18*10000+M18*1000+N18*100+O18*10) -> 162020630 | I18: =_xlfn.RANK.EQ(H18,$H$11:$H$20) -> 10 | J18: Renan | K18: =SUM(RENAN!$O$2:$O$105) -> 162 | L18: =COUNTIF(RENAN!$O$2:'RENAN'!$O$105,"9") -> 1 | M18: =COUNTIF(RENAN!$O$2:'RENAN'!$O$105,"6") -> 9 | N18: =COUNTIF(RENAN!$O$2:'RENAN'!$O$105,"4") -> 15 | O18: =COUNTIF(RENAN!$O$2:'RENAN'!$O$105,"3") -> 13 | P18: =COUNTIF(RENAN!$O$2:'RENAN'!$O$105,"0") -> 34 | Q18: =L18*9+M18*6+N18*4+O18*3 -> 162 | R18: =IF(D18="","",IF(D18>F18,C18,IF(F18>D18,G18,"EMPATE"))) -> França | S18: =IF(D18="","",IF(D18>F18,D18,IF(F18>D18,F18,D18))) -> 3 | T18: =IF(D18="","",IF(D18<F18,D18,IF(F18<D18,F18,D18))) -> 1
A19: 46189 | B19: 0.79166667 | C19: Iraque | D19: 1 | E19: x | F19: 4 | G19: Noruega | H19: =(K19*1000000+L19*10000+M19*1000+N19*100+O19*10) -> 215097280 | I19: =_xlfn.RANK.EQ(H19,$H$11:$H$20) -> 2 | J19: Soares | K19: =SUM(SOARES!$O$2:$O$105) -> 215 | L19: =COUNTIF(SOARES!$O$2:'SOARES'!$O$105,"9") -> 9 | M19: =COUNTIF(SOARES!$O$2:'SOARES'!$O$105,"6") -> 6 | N19: =COUNTIF(SOARES!$O$2:'SOARES'!$O$105,"4") -> 11 | O19: =COUNTIF(SOARES!$O$2:'SOARES'!$O$105,"3") -> 18 | P19: =COUNTIF(SOARES!$O$2:'SOARES'!$O$105,"0") -> 28 | Q19: =L19*9+M19*6+N19*4+O19*3 -> 215 | R19: =IF(D19="","",IF(D19>F19,C19,IF(F19>D19,G19,"EMPATE"))) -> Noruega | S19: =IF(D19="","",IF(D19>F19,D19,IF(F19>D19,F19,D19))) -> 4 | T19: =IF(D19="","",IF(D19<F19,D19,IF(F19<D19,F19,D19))) -> 1
A20: 46189 | B20: 0.91666667 | C20: Argentina | D20: 3 | E20: x | F20: 0 | G20: Argélia | H20: =(K20*1000000+L20*10000+M20*1000+N20*100+O20*10) -> 236100290 | I20: =_xlfn.RANK.EQ(H20,$H$11:$H$20) -> 1 | J20: Marques | K20: =SUM(MARQUES!$O$2:$O$105) -> 236 | L20: =COUNTIF(MARQUES!$O$2:'MARQUES'!$O$105,"9") -> 9 | M20: =COUNTIF(MARQUES!$O$2:'MARQUES'!$O$105,"6") -> 9 | N20: =COUNTIF(MARQUES!$O$2:'MARQUES'!$O$105,"4") -> 11 | O20: =COUNTIF(MARQUES!$O$2:'MARQUES'!$O$105,"3") -> 19 | P20: =COUNTIF(MARQUES!$O$2:'MARQUES'!$O$105,"0") -> 24 | Q20: =L20*9+M20*6+N20*4+O20*3 -> 236 | R20: =IF(D20="","",IF(D20>F20,C20,IF(F20>D20,G20,"EMPATE"))) -> Argentina | S20: =IF(D20="","",IF(D20>F20,D20,IF(F20>D20,F20,D20))) -> 3 | T20: =IF(D20="","",IF(D20<F20,D20,IF(F20<D20,F20,D20))) -> 0
A21: 46190 | B21: 0.041666667 | C21: Áustria | D21: 3 | E21: x | F21: 1 | G21: Jordânia | R21: =IF(D21="","",IF(D21>F21,C21,IF(F21>D21,G21,"EMPATE"))) -> Áustria | S21: =IF(D21="","",IF(D21>F21,D21,IF(F21>D21,F21,D21))) -> 3 | T21: =IF(D21="","",IF(D21<F21,D21,IF(F21<D21,F21,D21))) -> 1
A22: 46190 | B22: 0.58333333 | C22: Portugal | D22: 1 | E22: x | F22: 1 | G22: RD Congo | I22: Copa Phibra 2026 | R22: =IF(D22="","",IF(D22>F22,C22,IF(F22>D22,G22,"EMPATE"))) -> EMPATE | S22: =IF(D22="","",IF(D22>F22,D22,IF(F22>D22,F22,D22))) -> 1 | T22: =IF(D22="","",IF(D22<F22,D22,IF(F22<D22,F22,D22))) -> 1
A23: 46190 | B23: 0.70833333 | C23: Inglaterra | D23: 4 | E23: x | F23: 2 | G23: Croácia | I23: Posição | J23: Phibriano | K23: Pontos | L23: 9 | M23: 6 | N23: 4 | O23: 3 | P23: 0 | R23: =IF(D23="","",IF(D23>F23,C23,IF(F23>D23,G23,"EMPATE"))) -> Inglaterra | S23: =IF(D23="","",IF(D23>F23,D23,IF(F23>D23,F23,D23))) -> 4 | T23: =IF(D23="","",IF(D23<F23,D23,IF(F23<D23,F23,D23))) -> 2
A24: 46190 | B24: 0.83333333 | C24: Gana | D24: 1 | E24: x | F24: 0 | G24: Panamá | I24: 1 | J24: Marques | K24: 236 | L24: 9 | M24: 9 | N24: 11 | O24: 19 | P24: 24 | Q24: =K24-K25 -> 21 | R24: =IF(D24="","",IF(D24>F24,C24,IF(F24>D24,G24,"EMPATE"))) -> Gana | S24: =IF(D24="","",IF(D24>F24,D24,IF(F24>D24,F24,D24))) -> 1 | T24: =IF(D24="","",IF(D24<F24,D24,IF(F24<D24,F24,D24))) -> 0
A25: 46190 | B25: 0.95833333 | C25: Uzbequistão | D25: 1 | E25: x | F25: 3 | G25: Colômbia | I25: 2 | J25: Soares | K25: 215 | L25: 9 | M25: 6 | N25: 11 | O25: 18 | P25: 28 | Q25: =K25-K26 -> 7 | R25: =IF(D25="","",IF(D25>F25,C25,IF(F25>D25,G25,"EMPATE"))) -> Colômbia | S25: =IF(D25="","",IF(D25>F25,D25,IF(F25>D25,F25,D25))) -> 3 | T25: =IF(D25="","",IF(D25<F25,D25,IF(F25<D25,F25,D25))) -> 1
A26: 46191 | B26: 0.54166667 | C26: República Tcheca | D26: 1 | E26: x | F26: 1 | G26: África do Sul | I26: 3 | J26: Bernardo | K26: 208 | L26: 5 | M26: 12 | N26: 16 | O26: 9 | P26: 30 | Q26: =K26-K27 -> 5 | R26: =IF(D26="","",IF(D26>F26,C26,IF(F26>D26,G26,"EMPATE"))) -> EMPATE | S26: =IF(D26="","",IF(D26>F26,D26,IF(F26>D26,F26,D26))) -> 1 | T26: =IF(D26="","",IF(D26<F26,D26,IF(F26<D26,F26,D26))) -> 1
A27: 46191 | B27: 0.66666667 | C27: Suíça | D27: 4 | E27: x | F27: 1 | G27: Bósnia | I27: 4 | J27: Thiago | K27: 203 | L27: 5 | M27: 10 | N27: 11 | O27: 18 | P27: 28 | Q27: =K27-K28 -> 11 | R27: =IF(D27="","",IF(D27>F27,C27,IF(F27>D27,G27,"EMPATE"))) -> Suíça | S27: =IF(D27="","",IF(D27>F27,D27,IF(F27>D27,F27,D27))) -> 4 | T27: =IF(D27="","",IF(D27<F27,D27,IF(F27<D27,F27,D27))) -> 1
A28: 46191 | B28: 0.79166667 | C28: Canadá | D28: 6 | E28: x | F28: 0 | G28: Catar | I28: 5 | J28: Ricardo | K28: 192 | L28: 5 | M28: 6 | N28: 15 | O28: 17 | P28: 29 | Q28: =K28-K29 -> 1 | R28: =IF(D28="","",IF(D28>F28,C28,IF(F28>D28,G28,"EMPATE"))) -> Canadá | S28: =IF(D28="","",IF(D28>F28,D28,IF(F28>D28,F28,D28))) -> 6 | T28: =IF(D28="","",IF(D28<F28,D28,IF(F28<D28,F28,D28))) -> 0
A29: 46191 | B29: 0.91666667 | C29: México | D29: 1 | E29: x | F29: 0 | G29: Coréia do Sul | I29: 6 | J29: Marcio | K29: 191 | L29: 7 | M29: 3 | N29: 8 | O29: 26 | P29: 28 | Q29: =K29-K30 -> 14 | R29: =IF(D29="","",IF(D29>F29,C29,IF(F29>D29,G29,"EMPATE"))) -> México | S29: =IF(D29="","",IF(D29>F29,D29,IF(F29>D29,F29,D29))) -> 1 | T29: =IF(D29="","",IF(D29<F29,D29,IF(F29<D29,F29,D29))) -> 0
A30: 46192 | B30: 0.66666667 | C30: Estados Unidos | D30: 2 | E30: x | F30: 0 | G30: Austrália | I30: 7 | J30: Gabriel | K30: 177 | L30: 6 | M30: 3 | N30: 15 | O30: 15 | P30: 33 | Q30: =K30-K31 -> 3 | R30: =IF(D30="","",IF(D30>F30,C30,IF(F30>D30,G30,"EMPATE"))) -> Estados Unidos | S30: =IF(D30="","",IF(D30>F30,D30,IF(F30>D30,F30,D30))) -> 2 | T30: =IF(D30="","",IF(D30<F30,D30,IF(F30<D30,F30,D30))) -> 0
A31: 46192 | B31: 0.79166667 | C31: Escócia | D31: 0 | E31: x | F31: 1 | G31: Marrocos | I31: 8 | J31: Gustavo | K31: 174 | L31: 7 | M31: 3 | N31: 12 | O31: 15 | P31: 35 | Q31: =K31-K32 -> 8 | R31: =IF(D31="","",IF(D31>F31,C31,IF(F31>D31,G31,"EMPATE"))) -> Marrocos | S31: =IF(D31="","",IF(D31>F31,D31,IF(F31>D31,F31,D31))) -> 1 | T31: =IF(D31="","",IF(D31<F31,D31,IF(F31<D31,F31,D31))) -> 0
A32: 46192 | B32: 0.89583333 | C32: Brasil | D32: 3 | E32: x | F32: 0 | G32: Haiti | I32: 9 | J32: Fernando | K32: 166 | L32: 5 | M32: 8 | N32: 7 | O32: 15 | P32: 37 | Q32: =K32-K33 -> 4 | R32: =IF(D32="","",IF(D32>F32,C32,IF(F32>D32,G32,"EMPATE"))) -> Brasil | S32: =IF(D32="","",IF(D32>F32,D32,IF(F32>D32,F32,D32))) -> 3 | T32: =IF(D32="","",IF(D32<F32,D32,IF(F32<D32,F32,D32))) -> 0
A33: 46193 | B33: 0 | C33: Turquia | D33: 0 | E33: x | F33: 1 | G33: Paraguai | I33: 10 | J33: Renan | K33: 162 | L33: 1 | M33: 9 | N33: 15 | O33: 13 | P33: 34 | R33: =IF(D33="","",IF(D33>F33,C33,IF(F33>D33,G33,"EMPATE"))) -> Paraguai | S33: =IF(D33="","",IF(D33>F33,D33,IF(F33>D33,F33,D33))) -> 1 | T33: =IF(D33="","",IF(D33<F33,D33,IF(F33<D33,F33,D33))) -> 0
A34: 46193 | B34: 0.58333333 | C34: Holanda | D34: 5 | E34: x | F34: 1 | G34: Suécia | R34: =IF(D34="","",IF(D34>F34,C34,IF(F34>D34,G34,"EMPATE"))) -> Holanda | S34: =IF(D34="","",IF(D34>F34,D34,IF(F34>D34,F34,D34))) -> 5 | T34: =IF(D34="","",IF(D34<F34,D34,IF(F34<D34,F34,D34))) -> 1
A35: 46193 | B35: 0.70833333 | C35: Alemanha | D35: 2 | E35: x | F35: 1 | G35: Costa do Marfim | J35: 1000 | R35: =IF(D35="","",IF(D35>F35,C35,IF(F35>D35,G35,"EMPATE"))) -> Alemanha | S35: =IF(D35="","",IF(D35>F35,D35,IF(F35>D35,F35,D35))) -> 2 | T35: =IF(D35="","",IF(D35<F35,D35,IF(F35<D35,F35,D35))) -> 1
A36: 46193 | B36: 0.875 | C36: Equador | D36: 0 | E36: x | F36: 0 | G36: Curaçao | J36: 500 | R36: =IF(D36="","",IF(D36>F36,C36,IF(F36>D36,G36,"EMPATE"))) -> EMPATE | S36: =IF(D36="","",IF(D36>F36,D36,IF(F36>D36,F36,D36))) -> 0 | T36: =IF(D36="","",IF(D36<F36,D36,IF(F36<D36,F36,D36))) -> 0
A37: 46194 | B37: 0.041666667 | C37: Tunísia | D37: 0 | E37: x | F37: 4 | G37: Japão | J37: 300 | R37: =IF(D37="","",IF(D37>F37,C37,IF(F37>D37,G37,"EMPATE"))) -> Japão | S37: =IF(D37="","",IF(D37>F37,D37,IF(F37>D37,F37,D37))) -> 4 | T37: =IF(D37="","",IF(D37<F37,D37,IF(F37<D37,F37,D37))) -> 0
A38: 46194 | B38: 0.54166667 | C38: Espanha | D38: 4 | E38: x | F38: 0 | G38: Arábia Saudita | R38: =IF(D38="","",IF(D38>F38,C38,IF(F38>D38,G38,"EMPATE"))) -> Espanha | S38: =IF(D38="","",IF(D38>F38,D38,IF(F38>D38,F38,D38))) -> 4 | T38: =IF(D38="","",IF(D38<F38,D38,IF(F38<D38,F38,D38))) -> 0
A39: 46194 | B39: 0.66666667 | C39: Bélgica | D39: 0 | E39: x | F39: 0 | G39: Irã | R39: =IF(D39="","",IF(D39>F39,C39,IF(F39>D39,G39,"EMPATE"))) -> EMPATE | S39: =IF(D39="","",IF(D39>F39,D39,IF(F39>D39,F39,D39))) -> 0 | T39: =IF(D39="","",IF(D39<F39,D39,IF(F39<D39,F39,D39))) -> 0
A40: 46194 | B40: 0.79166667 | C40: Uruguai | D40: 2 | E40: x | F40: 2 | G40: Cabo Verde | R40: =IF(D40="","",IF(D40>F40,C40,IF(F40>D40,G40,"EMPATE"))) -> EMPATE | S40: =IF(D40="","",IF(D40>F40,D40,IF(F40>D40,F40,D40))) -> 2 | T40: =IF(D40="","",IF(D40<F40,D40,IF(F40<D40,F40,D40))) -> 2
...

Sheet BERNARDO
A1: PALPITES | H1: BERNARDO | K1: Palpite do Vencedor da Partida | L1: Score Vencedor | M1: Score Perdedor | O1: Pontos Ganhos
A2: 46184 | B2: 0.66666667 | C2: México | D2: 2 | E2: x | F2: 2 | G2: África do Sul | K2: =IF(D2="","",IF(D2>F2,C2,IF(F2>D2,G2,"EMPATE"))) -> EMPATE | L2: =IF(D2="","",IF(D2>F2,D2,IF(F2>D2,F2,D2))) -> 2 | M2: =IF(D2="","",IF(D2<F2,D2,IF(F2<D2,F2,D2))) -> 2 | O2: =IF(OFICIAL!D2="","",IF(AND(K2=OFICIAL!R2,L2=OFICIAL!S2,M2=OFICIAL!T2),9,IF(AND(K2=OFICIAL!R2,L2=OFICIAL!S2,M2<>OFICIAL!T2),6,IF(AND(K2=OFICIAL!R2,OFICIAL!S2=OFICIAL!T2,M2<>OFICIAL!T2),6,IF(AND(K2=OFICIAL!R2,L2<>OFICIAL!S2,OFICIAL!T2=M2),4,IF(AND(K2=OFICIAL!R2,OFICIAL!S2<>L2,OFICIAL!T2<>M2),3,0)))))) -> 0
A3: 46184 | B3: 0.95833333 | C3: Coréia do Sul | D3: 1 | E3: x | F3: 1 | G3: República Tcheca | K3: =IF(D3="","",IF(D3>F3,C3,IF(F3>D3,G3,"EMPATE"))) -> EMPATE | L3: =IF(D3="","",IF(D3>F3,D3,IF(F3>D3,F3,D3))) -> 1 | M3: =IF(D3="","",IF(D3<F3,D3,IF(F3<D3,F3,D3))) -> 1 | O3: =IF(OFICIAL!D3="","",IF(AND(K3=OFICIAL!R3,L3=OFICIAL!S3,M3=OFICIAL!T3),9,IF(AND(K3=OFICIAL!R3,L3=OFICIAL!S3,M3<>OFICIAL!T3),6,IF(AND(K3=OFICIAL!R3,OFICIAL!S3=OFICIAL!T3,M3<>OFICIAL!T3),6,IF(AND(K3=OFICIAL!R3,L3<>OFICIAL!S3,OFICIAL!T3=M3),4,IF(AND(K3=OFICIAL!R3,OFICIAL!S3<>L3,OFICIAL!T3<>M3),3,0)))))) -> 0
A4: 46185 | B4: 0.66666667 | C4: Canadá | D4: 1 | E4: x | F4: 1 | G4: Bósnia | K4: =IF(D4="","",IF(D4>F4,C4,IF(F4>D4,G4,"EMPATE"))) -> EMPATE | L4: =IF(D4="","",IF(D4>F4,D4,IF(F4>D4,F4,D4))) -> 1 | M4: =IF(D4="","",IF(D4<F4,D4,IF(F4<D4,F4,D4))) -> 1 | O4: =IF(OFICIAL!D4="","",IF(AND(K4=OFICIAL!R4,L4=OFICIAL!S4,M4=OFICIAL!T4),9,IF(AND(K4=OFICIAL!R4,L4=OFICIAL!S4,M4<>OFICIAL!T4),6,IF(AND(K4=OFICIAL!R4,OFICIAL!S4=OFICIAL!T4,M4<>OFICIAL!T4),6,IF(AND(K4=OFICIAL!R4,L4<>OFICIAL!S4,OFICIAL!T4=M4),4,IF(AND(K4=OFICIAL!R4,OFICIAL!S4<>L4,OFICIAL!T4<>M4),3,0)))))) -> 9
A5: 46185 | B5: 0.91666667 | C5: Estados Unidos | D5: 2 | E5: x | F5: 1 | G5: Paraguai | K5: =IF(D5="","",IF(D5>F5,C5,IF(F5>D5,G5,"EMPATE"))) -> Estados Unidos | L5: =IF(D5="","",IF(D5>F5,D5,IF(F5>D5,F5,D5))) -> 2 | M5: =IF(D5="","",IF(D5<F5,D5,IF(F5<D5,F5,D5))) -> 1 | O5: =IF(OFICIAL!D5="","",IF(AND(K5=OFICIAL!R5,L5=OFICIAL!S5,M5=OFICIAL!T5),9,IF(AND(K5=OFICIAL!R5,L5=OFICIAL!S5,M5<>OFICIAL!T5),6,IF(AND(K5=OFICIAL!R5,OFICIAL!S5=OFICIAL!T5,M5<>OFICIAL!T5),6,IF(AND(K5=OFICIAL!R5,L5<>OFICIAL!S5,OFICIAL!T5=M5),4,IF(AND(K5=OFICIAL!R5,OFICIAL!S5<>L5,OFICIAL!T5<>M5),3,0)))))) -> 4
A6: 46186 | B6: 0.66666667 | C6: Catar | D6: 0 | E6: x | F6: 2 | G6: Suíça | H6: PONTOS | I6: QTD | J6: TOTAL | K6: =IF(D6="","",IF(D6>F6,C6,IF(F6>D6,G6,"EMPATE"))) -> Suíça | L6: =IF(D6="","",IF(D6>F6,D6,IF(F6>D6,F6,D6))) -> 2 | M6: =IF(D6="","",IF(D6<F6,D6,IF(F6<D6,F6,D6))) -> 0 | O6: =IF(OFICIAL!D6="","",IF(AND(K6=OFICIAL!R6,L6=OFICIAL!S6,M6=OFICIAL!T6),9,IF(AND(K6=OFICIAL!R6,L6=OFICIAL!S6,M6<>OFICIAL!T6),6,IF(AND(K6=OFICIAL!R6,OFICIAL!S6=OFICIAL!T6,M6<>OFICIAL!T6),6,IF(AND(K6=OFICIAL!R6,L6<>OFICIAL!S6,OFICIAL!T6=M6),4,IF(AND(K6=OFICIAL!R6,OFICIAL!S6<>L6,OFICIAL!T6<>M6),3,0)))))) -> 0
A7: 46186 | B7: 0.79166667 | C7: Brasil | D7: 2 | E7: x | F7: 1 | G7: Marrocos | H7: 9 | I7: =COUNTIF($O$2:$O$105,9) -> 5 | J7: =H7*I7 -> 45 | K7: =IF(D7="","",IF(D7>F7,C7,IF(F7>D7,G7,"EMPATE"))) -> Brasil | L7: =IF(D7="","",IF(D7>F7,D7,IF(F7>D7,F7,D7))) -> 2 | M7: =IF(D7="","",IF(D7<F7,D7,IF(F7<D7,F7,D7))) -> 1 | O7: =IF(OFICIAL!D7="","",IF(AND(K7=OFICIAL!R7,L7=OFICIAL!S7,M7=OFICIAL!T7),9,IF(AND(K7=OFICIAL!R7,L7=OFICIAL!S7,M7<>OFICIAL!T7),6,IF(AND(K7=OFICIAL!R7,OFICIAL!S7=OFICIAL!T7,M7<>OFICIAL!T7),6,IF(AND(K7=OFICIAL!R7,L7<>OFICIAL!S7,OFICIAL!T7=M7),4,IF(AND(K7=OFICIAL!R7,OFICIAL!S7<>L7,OFICIAL!T7<>M7),3,0)))))) -> 0
A8: 46186 | B8: 0.91666667 | C8: Haiti | D8: 1 | E8: x | F8: 3 | G8: Escócia | H8: 6 | I8: =COUNTIF($O$2:$O$105,6) -> 12 | J8: =H8*I8 -> 72 | K8: =IF(D8="","",IF(D8>F8,C8,IF(F8>D8,G8,"EMPATE"))) -> Escócia | L8: =IF(D8="","",IF(D8>F8,D8,IF(F8>D8,F8,D8))) -> 3 | M8: =IF(D8="","",IF(D8<F8,D8,IF(F8<D8,F8,D8))) -> 1 | O8: =IF(OFICIAL!D8="","",IF(AND(K8=OFICIAL!R8,L8=OFICIAL!S8,M8=OFICIAL!T8),9,IF(AND(K8=OFICIAL!R8,L8=OFICIAL!S8,M8<>OFICIAL!T8),6,IF(AND(K8=OFICIAL!R8,OFICIAL!S8=OFICIAL!T8,M8<>OFICIAL!T8),6,IF(AND(K8=OFICIAL!R8,L8<>OFICIAL!S8,OFICIAL!T8=M8),4,IF(AND(K8=OFICIAL!R8,OFICIAL!S8<>L8,OFICIAL!T8<>M8),3,0)))))) -> 3
A9: 46187 | B9: 0.041666667 | C9: Austrália | D9: 1 | E9: x | F9: 2 | G9: Turquia | H9: 4 | I9: =COUNTIF($O$2:$O$105,4) -> 16 | J9: =H9*I9 -> 64 | K9: =IF(D9="","",IF(D9>F9,C9,IF(F9>D9,G9,"EMPATE"))) -> Turquia | L9: =IF(D9="","",IF(D9>F9,D9,IF(F9>D9,F9,D9))) -> 2 | M9: =IF(D9="","",IF(D9<F9,D9,IF(F9<D9,F9,D9))) -> 1 | O9: =IF(OFICIAL!D9="","",IF(AND(K9=OFICIAL!R9,L9=OFICIAL!S9,M9=OFICIAL!T9),9,IF(AND(K9=OFICIAL!R9,L9=OFICIAL!S9,M9<>OFICIAL!T9),6,IF(AND(K9=OFICIAL!R9,OFICIAL!S9=OFICIAL!T9,M9<>OFICIAL!T9),6,IF(AND(K9=OFICIAL!R9,L9<>OFICIAL!S9,OFICIAL!T9=M9),4,IF(AND(K9=OFICIAL!R9,OFICIAL!S9<>L9,OFICIAL!T9<>M9),3,0)))))) -> 0
A10: 46187 | B10: 0.58333333 | C10: Alemanha | D10: 4 | E10: x | F10: 0 | G10: Curaçao | H10: 3 | I10: =COUNTIF($O$2:$O$105,3) -> 9 | J10: =H10*I10 -> 27 | K10: =IF(D10="","",IF(D10>F10,C10,IF(F10>D10,G10,"EMPATE"))) -> Alemanha | L10: =IF(D10="","",IF(D10>F10,D10,IF(F10>D10,F10,D10))) -> 4 | M10: =IF(D10="","",IF(D10<F10,D10,IF(F10<D10,F10,D10))) -> 0 | O10: =IF(OFICIAL!D10="","",IF(AND(K10=OFICIAL!R10,L10=OFICIAL!S10,M10=OFICIAL!T10),9,IF(AND(K10=OFICIAL!R10,L10=OFICIAL!S10,M10<>OFICIAL!T10),6,IF(AND(K10=OFICIAL!R10,OFICIAL!S10=OFICIAL!T10,M10<>OFICIAL!T10),6,IF(AND(K10=OFICIAL!R10,L10<>OFICIAL!S10,OFICIAL!T10=M10),4,IF(AND(K10=OFICIAL!R10,OFICIAL!S10<>L10,OFICIAL!T10<>M10),3,0)))))) -> 3
A11: 46187 | B11: 0.70833333 | C11: Holanda | D11: 2 | E11: x | F11: 1 | G11: Japão | H11: 0 | I11: =COUNTIF($O$2:$O$105,0) -> 30 | J11: =H11*I11 -> 0 | K11: =IF(D11="","",IF(D11>F11,C11,IF(F11>D11,G11,"EMPATE"))) -> Holanda | L11: =IF(D11="","",IF(D11>F11,D11,IF(F11>D11,F11,D11))) -> 2 | M11: =IF(D11="","",IF(D11<F11,D11,IF(F11<D11,F11,D11))) -> 1 | O11: =IF(OFICIAL!D11="","",IF(AND(K11=OFICIAL!R11,L11=OFICIAL!S11,M11=OFICIAL!T11),9,IF(AND(K11=OFICIAL!R11,L11=OFICIAL!S11,M11<>OFICIAL!T11),6,IF(AND(K11=OFICIAL!R11,OFICIAL!S11=OFICIAL!T11,M11<>OFICIAL!T11),6,IF(AND(K11=OFICIAL!R11,L11<>OFICIAL!S11,OFICIAL!T11=M11),4,IF(AND(K11=OFICIAL!R11,OFICIAL!S11<>L11,OFICIAL!T11<>M11),3,0)))))) -> 0
A12: 46187 | B12: 0.83333333 | C12: Costa do Marfim | D12: 2 | E12: x | F12: 2 | G12: Equador | I12: TOTAL | J12: =SUM(J7:J11) -> 208 | K12: =IF(D12="","",IF(D12>F12,C12,IF(F12>D12,G12,"EMPATE"))) -> EMPATE | L12: =IF(D12="","",IF(D12>F12,D12,IF(F12>D12,F12,D12))) -> 2 | M12: =IF(D12="","",IF(D12<F12,D12,IF(F12<D12,F12,D12))) -> 2 | O12: =IF(OFICIAL!D12="","",IF(AND(K12=OFICIAL!R12,L12=OFICIAL!S12,M12=OFICIAL!T12),9,IF(AND(K12=OFICIAL!R12,L12=OFICIAL!S12,M12<>OFICIAL!T12),6,IF(AND(K12=OFICIAL!R12,OFICIAL!S12=OFICIAL!T12,M12<>OFICIAL!T12),6,IF(AND(K12=OFICIAL!R12,L12<>OFICIAL!S12,OFICIAL!T12=M12),4,IF(AND(K12=OFICIAL!R12,OFICIAL!S12<>L12,OFICIAL!T12<>M12),3,0)))))) -> 0
A13: 46187 | B13: 0.95833333 | C13: Suécia | D13: 2 | E13: x | F13: 1 | G13: Tunísia | K13: =IF(D13="","",IF(D13>F13,C13,IF(F13>D13,G13,"EMPATE"))) -> Suécia | L13: =IF(D13="","",IF(D13>F13,D13,IF(F13>D13,F13,D13))) -> 2 | M13: =IF(D13="","",IF(D13<F13,D13,IF(F13<D13,F13,D13))) -> 1 | O13: =IF(OFICIAL!D13="","",IF(AND(K13=OFICIAL!R13,L13=OFICIAL!S13,M13=OFICIAL!T13),9,IF(AND(K13=OFICIAL!R13,L13=OFICIAL!S13,M13<>OFICIAL!T13),6,IF(AND(K13=OFICIAL!R13,OFICIAL!S13=OFICIAL!T13,M13<>OFICIAL!T13),6,IF(AND(K13=OFICIAL!R13,L13<>OFICIAL!S13,OFICIAL!T13=M13),4,IF(AND(K13=OFICIAL!R13,OFICIAL!S13<>L13,OFICIAL!T13<>M13),3,0)))))) -> 4
A14: 46188 | B14: 0.54166667 | C14: Espanha | D14: 4 | E14: x | F14: 0 | G14: Cabo Verde | K14: =IF(D14="","",IF(D14>F14,C14,IF(F14>D14,G14,"EMPATE"))) -> Espanha | L14: =IF(D14="","",IF(D14>F14,D14,IF(F14>D14,F14,D14))) -> 4 | M14: =IF(D14="","",IF(D14<F14,D14,IF(F14<D14,F14,D14))) -> 0 | O14: =IF(OFICIAL!D14="","",IF(AND(K14=OFICIAL!R14,L14=OFICIAL!S14,M14=OFICIAL!T14),9,IF(AND(K14=OFICIAL!R14,L14=OFICIAL!S14,M14<>OFICIAL!T14),6,IF(AND(K14=OFICIAL!R14,OFICIAL!S14=OFICIAL!T14,M14<>OFICIAL!T14),6,IF(AND(K14=OFICIAL!R14,L14<>OFICIAL!S14,OFICIAL!T14=M14),4,IF(AND(K14=OFICIAL!R14,OFICIAL!S14<>L14,OFICIAL!T14<>M14),3,0)))))) -> 0
A15: 46188 | B15: 0.66666667 | C15: Bélgica | D15: 2 | E15: x | F15: 1 | G15: Egito | K15: =IF(D15="","",IF(D15>F15,C15,IF(F15>D15,G15,"EMPATE"))) -> Bélgica | L15: =IF(D15="","",IF(D15>F15,D15,IF(F15>D15,F15,D15))) -> 2 | M15: =IF(D15="","",IF(D15<F15,D15,IF(F15<D15,F15,D15))) -> 1 | O15: =IF(OFICIAL!D15="","",IF(AND(K15=OFICIAL!R15,L15=OFICIAL!S15,M15=OFICIAL!T15),9,IF(AND(K15=OFICIAL!R15,L15=OFICIAL!S15,M15<>OFICIAL!T15),6,IF(AND(K15=OFICIAL!R15,OFICIAL!S15=OFICIAL!T15,M15<>OFICIAL!T15),6,IF(AND(K15=OFICIAL!R15,L15<>OFICIAL!S15,OFICIAL!T15=M15),4,IF(AND(K15=OFICIAL!R15,OFICIAL!S15<>L15,OFICIAL!T15<>M15),3,0)))))) -> 0
A16: 46188 | B16: 0.79166667 | C16: Arábia Saudita | D16: 1 | E16: x | F16: 2 | G16: Uruguai | K16: =IF(D16="","",IF(D16>F16,C16,IF(F16>D16,G16,"EMPATE"))) -> Uruguai | L16: =IF(D16="","",IF(D16>F16,D16,IF(F16>D16,F16,D16))) -> 2 | M16: =IF(D16="","",IF(D16<F16,D16,IF(F16<D16,F16,D16))) -> 1 | O16: =IF(OFICIAL!D16="","",IF(AND(K16=OFICIAL!R16,L16=OFICIAL!S16,M16=OFICIAL!T16),9,IF(AND(K16=OFICIAL!R16,L16=OFICIAL!S16,M16<>OFICIAL!T16),6,IF(AND(K16=OFICIAL!R16,OFICIAL!S16=OFICIAL!T16,M16<>OFICIAL!T16),6,IF(AND(K16=OFICIAL!R16,L16<>OFICIAL!S16,OFICIAL!T16=M16),4,IF(AND(K16=OFICIAL!R16,OFICIAL!S16<>L16,OFICIAL!T16<>M16),3,0)))))) -> 0
A17: 46188 | B17: 0.91666667 | C17: Irã | D17: 1 | E17: x | F17: 1 | G17: Nova Zelândia | K17: =IF(D17="","",IF(D17>F17,C17,IF(F17>D17,G17,"EMPATE"))) -> EMPATE | L17: =IF(D17="","",IF(D17>F17,D17,IF(F17>D17,F17,D17))) -> 1 | M17: =IF(D17="","",IF(D17<F17,D17,IF(F17<D17,F17,D17))) -> 1 | O17: =IF(OFICIAL!D17="","",IF(AND(K17=OFICIAL!R17,L17=OFICIAL!S17,M17=OFICIAL!T17),9,IF(AND(K17=OFICIAL!R17,L17=OFICIAL!S17,M17<>OFICIAL!T17),6,IF(AND(K17=OFICIAL!R17,OFICIAL!S17=OFICIAL!T17,M17<>OFICIAL!T17),6,IF(AND(K17=OFICIAL!R17,L17<>OFICIAL!S17,OFICIAL!T17=M17),4,IF(AND(K17=OFICIAL!R17,OFICIAL!S17<>L17,OFICIAL!T17<>M17),3,0)))))) -> 6
A18: 46189 | B18: 0.66666667 | C18: França | D18: 3 | E18: x | F18: 1 | G18: Senegal | K18: =IF(D18="","",IF(D18>F18,C18,IF(F18>D18,G18,"EMPATE"))) -> França | L18: =IF(D18="","",IF(D18>F18,D18,IF(F18>D18,F18,D18))) -> 3 | M18: =IF(D18="","",IF(D18<F18,D18,IF(F18<D18,F18,D18))) -> 1 | O18: =IF(OFICIAL!D18="","",IF(AND(K18=OFICIAL!R18,L18=OFICIAL!S18,M18=OFICIAL!T18),9,IF(AND(K18=OFICIAL!R18,L18=OFICIAL!S18,M18<>OFICIAL!T18),6,IF(AND(K18=OFICIAL!R18,OFICIAL!S18=OFICIAL!T18,M18<>OFICIAL!T18),6,IF(AND(K18=OFICIAL!R18,L18<>OFICIAL!S18,OFICIAL!T18=M18),4,IF(AND(K18=OFICIAL!R18,OFICIAL!S18<>L18,OFICIAL!T18<>M18),3,0)))))) -> 9
A19: 46189 | B19: 0.79166667 | C19: Iraque | D19: 1 | E19: x | F19: 1 | G19: Noruega | K19: =IF(D19="","",IF(D19>F19,C19,IF(F19>D19,G19,"EMPATE"))) -> EMPATE | L19: =IF(D19="","",IF(D19>F19,D19,IF(F19>D19,F19,D19))) -> 1 | M19: =IF(D19="","",IF(D19<F19,D19,IF(F19<D19,F19,D19))) -> 1 | O19: =IF(OFICIAL!D19="","",IF(AND(K19=OFICIAL!R19,L19=OFICIAL!S19,M19=OFICIAL!T19),9,IF(AND(K19=OFICIAL!R19,L19=OFICIAL!S19,M19<>OFICIAL!T19),6,IF(AND(K19=OFICIAL!R19,OFICIAL!S19=OFICIAL!T19,M19<>OFICIAL!T19),6,IF(AND(K19=OFICIAL!R19,L19<>OFICIAL!S19,OFICIAL!T19=M19),4,IF(AND(K19=OFICIAL!R19,OFICIAL!S19<>L19,OFICIAL!T19<>M19),3,0)))))) -> 0
A20: 46189 | B20: 0.91666667 | C20: Argentina | D20: 3 | E20: x | F20: 1 | G20: Argélia | K20: =IF(D20="","",IF(D20>F20,C20,IF(F20>D20,G20,"EMPATE"))) -> Argentina | L20: =IF(D20="","",IF(D20>F20,D20,IF(F20>D20,F20,D20))) -> 3 | M20: =IF(D20="","",IF(D20<F20,D20,IF(F20<D20,F20,D20))) -> 1 | O20: =IF(OFICIAL!D20="","",IF(AND(K20=OFICIAL!R20,L20=OFICIAL!S20,M20=OFICIAL!T20),9,IF(AND(K20=OFICIAL!R20,L20=OFICIAL!S20,M20<>OFICIAL!T20),6,IF(AND(K20=OFICIAL!R20,OFICIAL!S20=OFICIAL!T20,M20<>OFICIAL!T20),6,IF(AND(K20=OFICIAL!R20,L20<>OFICIAL!S20,OFICIAL!T20=M20),4,IF(AND(K20=OFICIAL!R20,OFICIAL!S20<>L20,OFICIAL!T20<>M20),3,0)))))) -> 6
A21: 46190 | B21: 0.041666667 | C21: Áustria | D21: 1 | E21: x | F21: 1 | G21: Jordânia | K21: =IF(D21="","",IF(D21>F21,C21,IF(F21>D21,G21,"EMPATE"))) -> EMPATE | L21: =IF(D21="","",IF(D21>F21,D21,IF(F21>D21,F21,D21))) -> 1 | M21: =IF(D21="","",IF(D21<F21,D21,IF(F21<D21,F21,D21))) -> 1 | O21: =IF(OFICIAL!D21="","",IF(AND(K21=OFICIAL!R21,L21=OFICIAL!S21,M21=OFICIAL!T21),9,IF(AND(K21=OFICIAL!R21,L21=OFICIAL!S21,M21<>OFICIAL!T21),6,IF(AND(K21=OFICIAL!R21,OFICIAL!S21=OFICIAL!T21,M21<>OFICIAL!T21),6,IF(AND(K21=OFICIAL!R21,L21<>OFICIAL!S21,OFICIAL!T21=M21),4,IF(AND(K21=OFICIAL!R21,OFICIAL!S21<>L21,OFICIAL!T21<>M21),3,0)))))) -> 0
A22: 46190 | B22: 0.58333333 | C22: Portugal | D22: 5 | E22: x | F22: 1 | G22: RD Congo | K22: =IF(D22="","",IF(D22>F22,C22,IF(F22>D22,G22,"EMPATE"))) -> Portugal | L22: =IF(D22="","",IF(D22>F22,D22,IF(F22>D22,F22,D22))) -> 5 | M22: =IF(D22="","",IF(D22<F22,D22,IF(F22<D22,F22,D22))) -> 1 | O22: =IF(OFICIAL!D22="","",IF(AND(K22=OFICIAL!R22,L22=OFICIAL!S22,M22=OFICIAL!T22),9,IF(AND(K22=OFICIAL!R22,L22=OFICIAL!S22,M22<>OFICIAL!T22),6,IF(AND(K22=OFICIAL!R22,OFICIAL!S22=OFICIAL!T22,M22<>OFICIAL!T22),6,IF(AND(K22=OFICIAL!R22,L22<>OFICIAL!S22,OFICIAL!T22=M22),4,IF(AND(K22=OFICIAL!R22,OFICIAL!S22<>L22,OFICIAL!T22<>M22),3,0)))))) -> 0
A23: 46190 | B23: 0.70833333 | C23: Inglaterra | D23: 2 | E23: x | F23: 2 | G23: Croácia | K23: =IF(D23="","",IF(D23>F23,C23,IF(F23>D23,G23,"EMPATE"))) -> EMPATE | L23: =IF(D23="","",IF(D23>F23,D23,IF(F23>D23,F23,D23))) -> 2 | M23: =IF(D23="","",IF(D23<F23,D23,IF(F23<D23,F23,D23))) -> 2 | O23: =IF(OFICIAL!D23="","",IF(AND(K23=OFICIAL!R23,L23=OFICIAL!S23,M23=OFICIAL!T23),9,IF(AND(K23=OFICIAL!R23,L23=OFICIAL!S23,M23<>OFICIAL!T23),6,IF(AND(K23=OFICIAL!R23,OFICIAL!S23=OFICIAL!T23,M23<>OFICIAL!T23),6,IF(AND(K23=OFICIAL!R23,L23<>OFICIAL!S23,OFICIAL!T23=M23),4,IF(AND(K23=OFICIAL!R23,OFICIAL!S23<>L23,OFICIAL!T23<>M23),3,0)))))) -> 0
A24: 46190 | B24: 0.83333333 | C24: Gana | D24: 2 | E24: x | F24: 1 | G24: Panamá | K24: =IF(D24="","",IF(D24>F24,C24,IF(F24>D24,G24,"EMPATE"))) -> Gana | L24: =IF(D24="","",IF(D24>F24,D24,IF(F24>D24,F24,D24))) -> 2 | M24: =IF(D24="","",IF(D24<F24,D24,IF(F24<D24,F24,D24))) -> 1 | O24: =IF(OFICIAL!D24="","",IF(AND(K24=OFICIAL!R24,L24=OFICIAL!S24,M24=OFICIAL!T24),9,IF(AND(K24=OFICIAL!R24,L24=OFICIAL!S24,M24<>OFICIAL!T24),6,IF(AND(K24=OFICIAL!R24,OFICIAL!S24=OFICIAL!T24,M24<>OFICIAL!T24),6,IF(AND(K24=OFICIAL!R24,L24<>OFICIAL!S24,OFICIAL!T24=M24),4,IF(AND(K24=OFICIAL!R24,OFICIAL!S24<>L24,OFICIAL!T24<>M24),3,0)))))) -> 3
... A73: 46200 | B73: 0.95833333 | C73: Argélia | D73: 1 | E73: x | F73: 2 | G73: Áustria | K73: =IF(D73="","",IF(D73>F73,C73,IF(F73>D73,G73,"EMPATE"))) -> Áustria | L73: =IF(D73="","",IF(D73>F73,D73,IF(F73>D73,F73,D73))) -> 2 | M73: =IF(D73="","",IF(D73<F73,D73,IF(F73<D73,F73,D73))) -> 1 | O73: =IF(OFICIAL!D73="","",IF(AND(K73=OFICIAL!R73,L73=OFICIAL!S73,M73=OFICIAL!T73),9,IF(AND(K73=OFICIAL!R73,L73=OFICIAL!S73,M73<>OFICIAL!T73),6,IF(AND(K73=OFICIAL!R73,OFICIAL!S73=OFICIAL!T73,M73<>OFICIAL!T73),6,IF(AND(K73=OFICIAL!R73,L73<>OFICIAL!S73,OFICIAL!T73=M73),4,IF(AND(K73=OFICIAL!R73,OFICIAL!S73<>L73,OFICIAL!T73<>M73),3,0)))))) -> 0
A74: 46201 | B74: 0.66666667 | C74: África do Sul | D74: 1 | E74: x | F74: 1 | G74: Canadá | K74: =IF(D74="","",IF(D74>F74,C74,IF(F74>D74,G74,"EMPATE"))) -> EMPATE | L74: =IF(D74="","",IF(D74>F74,D74,IF(F74>D74,F74,D74))) -> 1 | M74: =IF(D74="","",IF(D74<F74,D74,IF(F74<D74,F74,D74))) -> 1 | O74: =IF(OFICIAL!D74="","",IF(AND(K74=OFICIAL!R74,L74=OFICIAL!S74,M74=OFICIAL!T74),9,IF(AND(K74=OFICIAL!R74,L74=OFICIAL!S74,M74<>OFICIAL!T74),6,IF(AND(K74=OFICIAL!R74,OFICIAL!S74=OFICIAL!T74,M74<>OFICIAL!T74),6,IF(AND(K74=OFICIAL!R74,L74<>OFICIAL!S74,OFICIAL!T74=M74),4,IF(AND(K74=OFICIAL!R74,OFICIAL!S74<>L74,OFICIAL!T74<>M74),3,0)))))) | Q74: 46201 | R74: 0.66666667 | S74: África do Sul | T74: 1 | U74: x | V74: 1 | W74: Canadá | X74: =S74=C74 -> TRUE | AB74: =W74=G74 -> TRUE
A75: 46202 | B75: 0.58333333 | C75: Brasil | D75: 3 | E75: x | F75: 1 | G75: Japão | K75: =IF(D75="","",IF(D75>F75,C75,IF(F75>D75,G75,"EMPATE"))) -> Brasil | L75: =IF(D75="","",IF(D75>F75,D75,IF(F75>D75,F75,D75))) -> 3 | M75: =IF(D75="","",IF(D75<F75,D75,IF(F75<D75,F75,D75))) -> 1 | O75: =IF(OFICIAL!D75="","",IF(AND(K75=OFICIAL!R75,L75=OFICIAL!S75,M75=OFICIAL!T75),9,IF(AND(K75=OFICIAL!R75,L75=OFICIAL!S75,M75<>OFICIAL!T75),6,IF(AND(K75=OFICIAL!R75,OFICIAL!S75=OFICIAL!T75,M75<>OFICIAL!T75),6,IF(AND(K75=OFICIAL!R75,L75<>OFICIAL!S75,OFICIAL!T75=M75),4,IF(AND(K75=OFICIAL!R75,OFICIAL!S75<>L75,OFICIAL!T75<>M75),3,0)))))) | Q75: 46202 | R75: 0.58333333 | S75: Brasil | T75: 3 | U75: x | V75: 1 | W75: Japão | X75: =S75=C75 -> TRUE | AB75: =W75=G75 -> TRUE
A76: 46202 | B76: 0.72916667 | C76: Alemanha | D76: 2 | E76: x | F76: 1 | G76: Paraguai | K76: =IF(D76="","",IF(D76>F76,C76,IF(F76>D76,G76,"EMPATE"))) -> Alemanha | L76: =IF(D76="","",IF(D76>F76,D76,IF(F76>D76,F76,D76))) -> 2 | M76: =IF(D76="","",IF(D76<F76,D76,IF(F76<D76,F76,D76))) -> 1 | O76: =IF(OFICIAL!D76="","",IF(AND(K76=OFICIAL!R76,L76=OFICIAL!S76,M76=OFICIAL!T76),9,IF(AND(K76=OFICIAL!R76,L76=OFICIAL!S76,M76<>OFICIAL!T76),6,IF(AND(K76=OFICIAL!R76,OFICIAL!S76=OFICIAL!T76,M76<>OFICIAL!T76),6,IF(AND(K76=OFICIAL!R76,L76<>OFICIAL!S76,OFICIAL!T76=M76),4,IF(AND(K76=OFICIAL!R76,OFICIAL!S76<>L76,OFICIAL!T76<>M76),3,0)))))) | Q76: 46202 | R76: 0.72916667 | S76: Alemanha | T76: 2 | U76: x | V76: 1 | W76: Paraguai | X76: =S76=C76 -> TRUE | AB76: =W76=G76 -> TRUE
A77: 46202 | B77: 0.91666667 | C77: Holanda | D77: 2 | E77: x | F77: 1 | G77: Marrocos | K77: =IF(D77="","",IF(D77>F77,C77,IF(F77>D77,G77,"EMPATE"))) -> Holanda | L77: =IF(D77="","",IF(D77>F77,D77,IF(F77>D77,F77,D77))) -> 2 | M77: =IF(D77="","",IF(D77<F77,D77,IF(F77<D77,F77,D77))) -> 1 | O77: =IF(OFICIAL!D77="","",IF(AND(K77=OFICIAL!R77,L77=OFICIAL!S77,M77=OFICIAL!T77),9,IF(AND(K77=OFICIAL!R77,L77=OFICIAL!S77,M77<>OFICIAL!T77),6,IF(AND(K77=OFICIAL!R77,OFICIAL!S77=OFICIAL!T77,M77<>OFICIAL!T77),6,IF(AND(K77=OFICIAL!R77,L77<>OFICIAL!S77,OFICIAL!T77=M77),4,IF(AND(K77=OFICIAL!R77,OFICIAL!S77<>L77,OFICIAL!T77<>M77),3,0)))))) | Q77: 46202 | R77: 0.91666667 | S77: Holanda | T77: 2 | U77: x | V77: 1 | W77: Marrocos | X77: =S77=C77 -> TRUE | AB77: =W77=G77 -> TRUE
A78: 46203 | B78: 0.58333333 | C78: Costa do Marfim | D78: 1 | E78: x | F78: 2 | G78: Noruega | K78: =IF(D78="","",IF(D78>F78,C78,IF(F78>D78,G78,"EMPATE"))) -> Noruega | L78: =IF(D78="","",IF(D78>F78,D78,IF(F78>D78,F78,D78))) -> 2 | M78: =IF(D78="","",IF(D78<F78,D78,IF(F78<D78,F78,D78))) -> 1 | O78: =IF(OFICIAL!D78="","",IF(AND(K78=OFICIAL!R78,L78=OFICIAL!S78,M78=OFICIAL!T78),9,IF(AND(K78=OFICIAL!R78,L78=OFICIAL!S78,M78<>OFICIAL!T78),6,IF(AND(K78=OFICIAL!R78,OFICIAL!S78=OFICIAL!T78,M78<>OFICIAL!T78),6,IF(AND(K78=OFICIAL!R78,L78<>OFICIAL!S78,OFICIAL!T78=M78),4,IF(AND(K78=OFICIAL!R78,OFICIAL!S78<>L78,OFICIAL!T78<>M78),3,0)))))) | Q78: 46203 | R78: 0.58333333 | S78: Costa do Marfim | T78: 1 | U78: x | V78: 2 | W78: Noruega | X78: =S78=C78 -> TRUE | AB78: =W78=G78 -> TRUE
A79: 46203 | B79: 0.75 | C79: França | D79: 3 | E79: x | F79: 1 | G79: Suécia | K79: =IF(D79="","",IF(D79>F79,C79,IF(F79>D79,G79,"EMPATE"))) -> França | L79: =IF(D79="","",IF(D79>F79,D79,IF(F79>D79,F79,D79))) -> 3 | M79: =IF(D79="","",IF(D79<F79,D79,IF(F79<D79,F79,D79))) -> 1 | O79: =IF(OFICIAL!D79="","",IF(AND(K79=OFICIAL!R79,L79=OFICIAL!S79,M79=OFICIAL!T79),9,IF(AND(K79=OFICIAL!R79,L79=OFICIAL!S79,M79<>OFICIAL!T79),6,IF(AND(K79=OFICIAL!R79,OFICIAL!S79=OFICIAL!T79,M79<>OFICIAL!T79),6,IF(AND(K79=OFICIAL!R79,L79<>OFICIAL!S79,OFICIAL!T79=M79),4,IF(AND(K79=OFICIAL!R79,OFICIAL!S79<>L79,OFICIAL!T79<>M79),3,0)))))) | Q79: 46203 | R79: 0.75 | S79: França | T79: 3 | U79: x | V79: 1 | W79: Suécia | X79: =S79=C79 -> TRUE | AB79: =W79=G79 -> TRUE
A80: 46203 | B80: 0.91666667 | C80: México | D80: 1 | E80: x | F80: 0 | G80: Equador | K80: =IF(D80="","",IF(D80>F80,C80,IF(F80>D80,G80,"EMPATE"))) -> México | L80: =IF(D80="","",IF(D80>F80,D80,IF(F80>D80,F80,D80))) -> 1 | M80: =IF(D80="","",IF(D80<F80,D80,IF(F80<D80,F80,D80))) -> 0 | O80: =IF(OFICIAL!D80="","",IF(AND(K80=OFICIAL!R80,L80=OFICIAL!S80,M80=OFICIAL!T80),9,IF(AND(K80=OFICIAL!R80,L80=OFICIAL!S80,M80<>OFICIAL!T80),6,IF(AND(K80=OFICIAL!R80,OFICIAL!S80=OFICIAL!T80,M80<>OFICIAL!T80),6,IF(AND(K80=OFICIAL!R80,L80<>OFICIAL!S80,OFICIAL!T80=M80),4,IF(AND(K80=OFICIAL!R80,OFICIAL!S80<>L80,OFICIAL!T80<>M80),3,0)))))) | Q80: 46203 | R80: 0.91666667 | S80: México | T80: 1 | U80: x | V80: 0 | W80: Equador | X80: =S80=C80 -> TRUE | AB80: =W80=G80 -> TRUE
A81: 46204 | B81: 0.54166667 | C81: Inglaterra | D81: 2 | E81: x | F81: 0 | G81: RD Congo | K81: =IF(D81="","",IF(D81>F81,C81,IF(F81>D81,G81,"EMPATE"))) -> Inglaterra | L81: =IF(D81="","",IF(D81>F81,D81,IF(F81>D81,F81,D81))) -> 2 | M81: =IF(D81="","",IF(D81<F81,D81,IF(F81<D81,F81,D81))) -> 0 | O81: =IF(OFICIAL!D81="","",IF(AND(K81=OFICIAL!R81,L81=OFICIAL!S81,M81=OFICIAL!T81),9,IF(AND(K81=OFICIAL!R81,L81=OFICIAL!S81,M81<>OFICIAL!T81),6,IF(AND(K81=OFICIAL!R81,OFICIAL!S81=OFICIAL!T81,M81<>OFICIAL!T81),6,IF(AND(K81=OFICIAL!R81,L81<>OFICIAL!S81,OFICIAL!T81=M81),4,IF(AND(K81=OFICIAL!R81,OFICIAL!S81<>L81,OFICIAL!T81<>M81),3,0)))))) | Q81: 46204 | R81: 0.54166667 | S81: Inglaterra | T81: 2 | U81: x | V81: 0 | W81: RD Congo | X81: =S81=C81 -> TRUE | AB81: =W81=G81 -> TRUE
A82: 46204 | B82: 0.70833333 | C82: Bélgica | D82: 1 | E82: x | F82: 1 | G82: Senegal | K82: =IF(D82="","",IF(D82>F82,C82,IF(F82>D82,G82,"EMPATE"))) -> EMPATE | L82: =IF(D82="","",IF(D82>F82,D82,IF(F82>D82,F82,D82))) -> 1 | M82: =IF(D82="","",IF(D82<F82,D82,IF(F82<D82,F82,D82))) -> 1 | O82: =IF(OFICIAL!D82="","",IF(AND(K82=OFICIAL!R82,L82=OFICIAL!S82,M82=OFICIAL!T82),9,IF(AND(K82=OFICIAL!R82,L82=OFICIAL!S82,M82<>OFICIAL!T82),6,IF(AND(K82=OFICIAL!R82,OFICIAL!S82=OFICIAL!T82,M82<>OFICIAL!T82),6,IF(AND(K82=OFICIAL!R82,L82<>OFICIAL!S82,OFICIAL!T82=M82),4,IF(AND(K82=OFICIAL!R82,OFICIAL!S82<>L82,OFICIAL!T82<>M82),3,0)))))) | Q82: 46204 | R82: 0.70833333 | S82: Bélgica | T82: 1 | U82: x | V82: 1 | W82: Senegal | X82: =S82=C82 -> TRUE | AB82: =W82=G82 -> TRUE
A83: 46204 | B83: 0.875 | C83: Estados Unidos | D83: 1 | E83: x | F83: 0 | G83: Bósnia | K83: =IF(D83="","",IF(D83>F83,C83,IF(F83>D83,G83,"EMPATE"))) -> Estados Unidos | L83: =IF(D83="","",IF(D83>F83,D83,IF(F83>D83,F83,D83))) -> 1 | M83: =IF(D83="","",IF(D83<F83,D83,IF(F83<D83,F83,D83))) -> 0 | O83: =IF(OFICIAL!D83="","",IF(AND(K83=OFICIAL!R83,L83=OFICIAL!S83,M83=OFICIAL!T83),9,IF(AND(K83=OFICIAL!R83,L83=OFICIAL!S83,M83<>OFICIAL!T83),6,IF(AND(K83=OFICIAL!R83,OFICIAL!S83=OFICIAL!T83,M83<>OFICIAL!T83),6,IF(AND(K83=OFICIAL!R83,L83<>OFICIAL!S83,OFICIAL!T83=M83),4,IF(AND(K83=OFICIAL!R83,OFICIAL!S83<>L83,OFICIAL!T83<>M83),3,0)))))) | Q83: 46204 | R83: 0.875 | S83: Estados Unidos | T83: 1 | U83: x | V83: 0 | W83: Bósnia | X83: =S83=C83 -> TRUE | AB83: =W83=G83 -> TRUE
A84: 46205 | B84: 0.66666667 | C84: Espanha | D84: 2 | E84: x | F84: 0 | G84: Áustria | K84: =IF(D84="","",IF(D84>F84,C84,IF(F84>D84,G84,"EMPATE"))) -> Espanha | L84: =IF(D84="","",IF(D84>F84,D84,IF(F84>D84,F84,D84))) -> 2 | M84: =IF(D84="","",IF(D84<F84,D84,IF(F84<D84,F84,D84))) -> 0 | O84: =IF(OFICIAL!D84="","",IF(AND(K84=OFICIAL!R84,L84=OFICIAL!S84,M84=OFICIAL!T84),9,IF(AND(K84=OFICIAL!R84,L84=OFICIAL!S84,M84<>OFICIAL!T84),6,IF(AND(K84=OFICIAL!R84,OFICIAL!S84=OFICIAL!T84,M84<>OFICIAL!T84),6,IF(AND(K84=OFICIAL!R84,L84<>OFICIAL!S84,OFICIAL!T84=M84),4,IF(AND(K84=OFICIAL!R84,OFICIAL!S84<>L84,OFICIAL!T84<>M84),3,0)))))) | Q84: 46205 | R84: 0.66666667 | S84: Espanha | T84: 2 | U84: x | V84: 0 | W84: Áustria | X84: =S84=C84 -> TRUE | AB84: =W84=G84 -> TRUE
A85: 46205 | B85: 0.83333333 | C85: Portugal | D85: 1 | E85: x | F85: 1 | G85: Croácia | K85: =IF(D85="","",IF(D85>F85,C85,IF(F85>D85,G85,"EMPATE"))) -> EMPATE | L85: =IF(D85="","",IF(D85>F85,D85,IF(F85>D85,F85,D85))) -> 1 | M85: =IF(D85="","",IF(D85<F85,D85,IF(F85<D85,F85,D85))) -> 1 | O85: =IF(OFICIAL!D85="","",IF(AND(K85=OFICIAL!R85,L85=OFICIAL!S85,M85=OFICIAL!T85),9,IF(AND(K85=OFICIAL!R85,L85=OFICIAL!S85,M85<>OFICIAL!T85),6,IF(AND(K85=OFICIAL!R85,OFICIAL!S85=OFICIAL!T85,M85<>OFICIAL!T85),6,IF(AND(K85=OFICIAL!R85,L85<>OFICIAL!S85,OFICIAL!T85=M85),4,IF(AND(K85=OFICIAL!R85,OFICIAL!S85<>L85,OFICIAL!T85<>M85),3,0)))))) | Q85: 46205 | R85: 0.83333333 | S85: Portugal | T85: 1 | U85: x | V85: 1 | W85: Croácia | X85: =S85=C85 -> TRUE | AB85: =W85=G85 -> TRUE
... A89: 46206 | B89: 0.9375 | C89: Colômbia | D89: 1 | E89: x | F89: 1 | G89: Gana | K89: =IF(D89="","",IF(D89>F89,C89,IF(F89>D89,G89,"EMPATE"))) -> EMPATE | L89: =IF(D89="","",IF(D89>F89,D89,IF(F89>D89,F89,D89))) -> 1 | M89: =IF(D89="","",IF(D89<F89,D89,IF(F89<D89,F89,D89))) -> 1 | O89: =IF(OFICIAL!D89="","",IF(AND(K89=OFICIAL!R89,L89=OFICIAL!S89,M89=OFICIAL!T89),9,IF(AND(K89=OFICIAL!R89,L89=OFICIAL!S89,M89<>OFICIAL!T89),6,IF(AND(K89=OFICIAL!R89,OFICIAL!S89=OFICIAL!T89,M89<>OFICIAL!T89),6,IF(AND(K89=OFICIAL!R89,L89<>OFICIAL!S89,OFICIAL!T89=M89),4,IF(AND(K89=OFICIAL!R89,OFICIAL!S89<>L89,OFICIAL!T89<>M89),3,0)))))) | Q89: 46206 | R89: 0.9375 | S89: Colômbia | T89: 1 | U89: x | V89: 1 | W89: Gana | X89: =S89=C89 -> TRUE | AB89: =W89=G89 -> TRUE
A90: 46207 | B90: 0.58333333 | C90: Venc. Segunda Fase 3 | E90: x | G90: Venc. Segunda Fase 4 | K90: =IF(D90="","",IF(D90>F90,C90,IF(F90>D90,G90,"EMPATE"))) | L90: =IF(D90="","",IF(D90>F90,D90,IF(F90>D90,F90,D90))) | M90: =IF(D90="","",IF(D90<F90,D90,IF(F90<D90,F90,D90))) | O90: =IF(OFICIAL!D90="","",IF(AND(K90=OFICIAL!R90,L90=OFICIAL!S90,M90=OFICIAL!T90),9,IF(AND(K90=OFICIAL!R90,L90=OFICIAL!S90,M90<>OFICIAL!T90),6,IF(AND(K90=OFICIAL!R90,OFICIAL!S90=OFICIAL!T90,M90<>OFICIAL!T90),6,IF(AND(K90=OFICIAL!R90,L90<>OFICIAL!S90,OFICIAL!T90=M90),4,IF(AND(K90=OFICIAL!R90,OFICIAL!S90<>L90,OFICIAL!T90<>M90),3,0))))))
A91: 46207 | B91: 0.75 | C91: Venc. Segunda Fase 1 | E91: x | G91: Venc. Segunda Fase 2 | K91: =IF(D91="","",IF(D91>F91,C91,IF(F91>D91,G91,"EMPATE"))) | L91: =IF(D91="","",IF(D91>F91,D91,IF(F91>D91,F91,D91))) | M91: =IF(D91="","",IF(D91<F91,D91,IF(F91<D91,F91,D91))) | O91: =IF(OFICIAL!D91="","",IF(AND(K91=OFICIAL!R91,L91=OFICIAL!S91,M91=OFICIAL!T91),9,IF(AND(K91=OFICIAL!R91,L91=OFICIAL!S91,M91<>OFICIAL!T91),6,IF(AND(K91=OFICIAL!R91,OFICIAL!S91=OFICIAL!T91,M91<>OFICIAL!T91),6,IF(AND(K91=OFICIAL!R91,L91<>OFICIAL!S91,OFICIAL!T91=M91),4,IF(AND(K91=OFICIAL!R91,OFICIAL!S91<>L91,OFICIAL!T91<>M91),3,0))))))
...

Sheet FERNANDO
A1: PALPITES | H1: FERNANDO | K1: Palpite do Vencedor da Partida | L1: Score Vencedor | M1: Score Perdedor | O1: Pontos Ganhos
A2: 46184 | B2: 0.66666667 | C2: México | D2: 2 | E2: x | F2: 0 | G2: África do Sul | K2: =IF(D2="","",IF(D2>F2,C2,IF(F2>D2,G2,"EMPATE"))) -> México | L2: =IF(D2="","",IF(D2>F2,D2,IF(F2>D2,F2,D2))) -> 2 | M2: =IF(D2="","",IF(D2<F2,D2,IF(F2<D2,F2,D2))) -> 0 | O2: =IF(OFICIAL!D2="","",IF(AND(K2=OFICIAL!R2,L2=OFICIAL!S2,M2=OFICIAL!T2),9,IF(AND(K2=OFICIAL!R2,L2=OFICIAL!S2,M2<>OFICIAL!T2),6,IF(AND(K2=OFICIAL!R2,OFICIAL!S2=OFICIAL!T2,M2<>OFICIAL!T2),6,IF(AND(K2=OFICIAL!R2,L2<>OFICIAL!S2,OFICIAL!T2=M2),4,IF(AND(K2=OFICIAL!R2,OFICIAL!S2<>L2,OFICIAL!T2<>M2),3,0)))))) -> 9
A3: 46184 | B3: 0.95833333 | C3: Coréia do Sul | D3: 1 | E3: x | F3: 1 | G3: República Tcheca | K3: =IF(D3="","",IF(D3>F3,C3,IF(F3>D3,G3,"EMPATE"))) -> EMPATE | L3: =IF(D3="","",IF(D3>F3,D3,IF(F3>D3,F3,D3))) -> 1 | M3: =IF(D3="","",IF(D3<F3,D3,IF(F3<D3,F3,D3))) -> 1 | O3: =IF(OFICIAL!D3="","",IF(AND(K3=OFICIAL!R3,L3=OFICIAL!S3,M3=OFICIAL!T3),9,IF(AND(K3=OFICIAL!R3,L3=OFICIAL!S3,M3<>OFICIAL!T3),6,IF(AND(K3=OFICIAL!R3,OFICIAL!S3=OFICIAL!T3,M3<>OFICIAL!T3),6,IF(AND(K3=OFICIAL!R3,L3<>OFICIAL!S3,OFICIAL!T3=M3),4,IF(AND(K3=OFICIAL!R3,OFICIAL!S3<>L3,OFICIAL!T3<>M3),3,0)))))) -> 0
A4: 46185 | B4: 0.66666667 | C4: Canadá | D4: 0 | E4: x | F4: 2 | G4: Bósnia | K4: =IF(D4="","",IF(D4>F4,C4,IF(F4>D4,G4,"EMPATE"))) -> Bósnia | L4: =IF(D4="","",IF(D4>F4,D4,IF(F4>D4,F4,D4))) -> 2 | M4: =IF(D4="","",IF(D4<F4,D4,IF(F4<D4,F4,D4))) -> 0 | O4: =IF(OFICIAL!D4="","",IF(AND(K4=OFICIAL!R4,L4=OFICIAL!S4,M4=OFICIAL!T4),9,IF(AND(K4=OFICIAL!R4,L4=OFICIAL!S4,M4<>OFICIAL!T4),6,IF(AND(K4=OFICIAL!R4,OFICIAL!S4=OFICIAL!T4,M4<>OFICIAL!T4),6,IF(AND(K4=OFICIAL!R4,L4<>OFICIAL!S4,OFICIAL!T4=M4),4,IF(AND(K4=OFICIAL!R4,OFICIAL!S4<>L4,OFICIAL!T4<>M4),3,0)))))) -> 0
A5: 46185 | B5: 0.91666667 | C5: Estados Unidos | D5: 2 | E5: x | F5: 0 | G5: Paraguai | K5: =IF(D5="","",IF(D5>F5,C5,IF(F5>D5,G5,"EMPATE"))) -> Estados Unidos | L5: =IF(D5="","",IF(D5>F5,D5,IF(F5>D5,F5,D5))) -> 2 | M5: =IF(D5="","",IF(D5<F5,D5,IF(F5<D5,F5,D5))) -> 0 | O5: =IF(OFICIAL!D5="","",IF(AND(K5=OFICIAL!R5,L5=OFICIAL!S5,M5=OFICIAL!T5),9,IF(AND(K5=OFICIAL!R5,L5=OFICIAL!S5,M5<>OFICIAL!T5),6,IF(AND(K5=OFICIAL!R5,OFICIAL!S5=OFICIAL!T5,M5<>OFICIAL!T5),6,IF(AND(K5=OFICIAL!R5,L5<>OFICIAL!S5,OFICIAL!T5=M5),4,IF(AND(K5=OFICIAL!R5,OFICIAL!S5<>L5,OFICIAL!T5<>M5),3,0)))))) -> 3
A6: 46186 | B6: 0.66666667 | C6: Catar | D6: 2 | E6: x | F6: 0 | G6: Suíça | H6: PONTOS | I6: QTD | J6: TOTAL | K6: =IF(D6="","",IF(D6>F6,C6,IF(F6>D6,G6,"EMPATE"))) -> Catar | L6: =IF(D6="","",IF(D6>F6,D6,IF(F6>D6,F6,D6))) -> 2 | M6: =IF(D6="","",IF(D6<F6,D6,IF(F6<D6,F6,D6))) -> 0 | O6: =IF(OFICIAL!D6="","",IF(AND(K6=OFICIAL!R6,L6=OFICIAL!S6,M6=OFICIAL!T6),9,IF(AND(K6=OFICIAL!R6,L6=OFICIAL!S6,M6<>OFICIAL!T6),6,IF(AND(K6=OFICIAL!R6,OFICIAL!S6=OFICIAL!T6,M6<>OFICIAL!T6),6,IF(AND(K6=OFICIAL!R6,L6<>OFICIAL!S6,OFICIAL!T6=M6),4,IF(AND(K6=OFICIAL!R6,OFICIAL!S6<>L6,OFICIAL!T6<>M6),3,0)))))) -> 0
A7: 46186 | B7: 0.79166667 | C7: Brasil | D7: 2 | E7: x | F7: 0 | G7: Marrocos | H7: 9 | I7: =COUNTIF($O$2:$O$105,9) -> 5 | J7: =H7*I7 -> 45 | K7: =IF(D7="","",IF(D7>F7,C7,IF(F7>D7,G7,"EMPATE"))) -> Brasil | L7: =IF(D7="","",IF(D7>F7,D7,IF(F7>D7,F7,D7))) -> 2 | M7: =IF(D7="","",IF(D7<F7,D7,IF(F7<D7,F7,D7))) -> 0 | O7: =IF(OFICIAL!D7="","",IF(AND(K7=OFICIAL!R7,L7=OFICIAL!S7,M7=OFICIAL!T7),9,IF(AND(K7=OFICIAL!R7,L7=OFICIAL!S7,M7<>OFICIAL!T7),6,IF(AND(K7=OFICIAL!R7,OFICIAL!S7=OFICIAL!T7,M7<>OFICIAL!T7),6,IF(AND(K7=OFICIAL!R7,L7<>OFICIAL!S7,OFICIAL!T7=M7),4,IF(AND(K7=OFICIAL!R7,OFICIAL!S7<>L7,OFICIAL!T7<>M7),3,0)))))) -> 0
A8: 46186 | B8: 0.91666667 | C8: Haiti | D8: 1 | E8: x | F8: 1 | G8: Escócia | H8: 6 | I8: =COUNTIF($O$2:$O$105,6) -> 8 | J8: =H8*I8 -> 48 | K8: =IF(D8="","",IF(D8>F8,C8,IF(F8>D8,G8,"EMPATE"))) -> EMPATE | L8: =IF(D8="","",IF(D8>F8,D8,IF(F8>D8,F8,D8))) -> 1 | M8: =IF(D8="","",IF(D8<F8,D8,IF(F8<D8,F8,D8))) -> 1 | O8: =IF(OFICIAL!D8="","",IF(AND(K8=OFICIAL!R8,L8=OFICIAL!S8,M8=OFICIAL!T8),9,IF(AND(K8=OFICIAL!R8,L8=OFICIAL!S8,M8<>OFICIAL!T8),6,IF(AND(K8=OFICIAL!R8,OFICIAL!S8=OFICIAL!T8,M8<>OFICIAL!T8),6,IF(AND(K8=OFICIAL!R8,L8<>OFICIAL!S8,OFICIAL!T8=M8),4,IF(AND(K8=OFICIAL!R8,OFICIAL!S8<>L8,OFICIAL!T8<>M8),3,0)))))) -> 0
A9: 46187 | B9: 0.041666667 | C9: Austrália | D9: 2 | E9: x | F9: 1 | G9: Turquia | H9: 4 | I9: =COUNTIF($O$2:$O$105,4) -> 7 | J9: =H9*I9 -> 28 | K9: =IF(D9="","",IF(D9>F9,C9,IF(F9>D9,G9,"EMPATE"))) -> Austrália | L9: =IF(D9="","",IF(D9>F9,D9,IF(F9>D9,F9,D9))) -> 2 | M9: =IF(D9="","",IF(D9<F9,D9,IF(F9<D9,F9,D9))) -> 1 | O9: =IF(OFICIAL!D9="","",IF(AND(K9=OFICIAL!R9,L9=OFICIAL!S9,M9=OFICIAL!T9),9,IF(AND(K9=OFICIAL!R9,L9=OFICIAL!S9,M9<>OFICIAL!T9),6,IF(AND(K9=OFICIAL!R9,OFICIAL!S9=OFICIAL!T9,M9<>OFICIAL!T9),6,IF(AND(K9=OFICIAL!R9,L9<>OFICIAL!S9,OFICIAL!T9=M9),4,IF(AND(K9=OFICIAL!R9,OFICIAL!S9<>L9,OFICIAL!T9<>M9),3,0)))))) -> 6
A10: 46187 | B10: 0.58333333 | C10: Alemanha | D10: 4 | E10: x | F10: 0 | G10: Curaçao | H10: 3 | I10: =COUNTIF($O$2:$O$105,3) -> 15 | J10: =H10*I10 -> 45 | K10: =IF(D10="","",IF(D10>F10,C10,IF(F10>D10,G10,"EMPATE"))) -> Alemanha | L10: =IF(D10="","",IF(D10>F10,D10,IF(F10>D10,F10,D10))) -> 4 | M10: =IF(D10="","",IF(D10<F10,D10,IF(F10<D10,F10,D10))) -> 0 | O10: =IF(OFICIAL!D10="","",IF(AND(K10=OFICIAL!R10,L10=OFICIAL!S10,M10=OFICIAL!T10),9,IF(AND(K10=OFICIAL!R10,L10=OFICIAL!S10,M10<>OFICIAL!T10),6,IF(AND(K10=OFICIAL!R10,OFICIAL!S10=OFICIAL!T10,M10<>OFICIAL!T10),6,IF(AND(K10=OFICIAL!R10,L10<>OFICIAL!S10,OFICIAL!T10=M10),4,IF(AND(K10=OFICIAL!R10,OFICIAL!S10<>L10,OFICIAL!T10<>M10),3,0)))))) -> 3
A11: 46187 | B11: 0.70833333 | C11: Holanda | D11: 2 | E11: x | F11: 3 | G11: Japão | H11: 0 | I11: =COUNTIF($O$2:$O$105,0) -> 37 | J11: =H11*I11 -> 0 | K11: =IF(D11="","",IF(D11>F11,C11,IF(F11>D11,G11,"EMPATE"))) -> Japão | L11: =IF(D11="","",IF(D11>F11,D11,IF(F11>D11,F11,D11))) -> 3 | M11: =IF(D11="","",IF(D11<F11,D11,IF(F11<D11,F11,D11))) -> 2 | O11: =IF(OFICIAL!D11="","",IF(AND(K11=OFICIAL!R11,L11=OFICIAL!S11,M11=OFICIAL!T11),9,IF(AND(K11=OFICIAL!R11,L11=OFICIAL!S11,M11<>OFICIAL!T11),6,IF(AND(K11=OFICIAL!R11,OFICIAL!S11=OFICIAL!T11,M11<>OFICIAL!T11),6,IF(AND(K11=OFICIAL!R11,L11<>OFICIAL!S11,OFICIAL!T11=M11),4,IF(AND(K11=OFICIAL!R11,OFICIAL!S11<>L11,OFICIAL!T11<>M11),3,0)))))) -> 0
A12: 46187 | B12: 0.83333333 | C12: Costa do Marfim | D12: 2 | E12: x | F12: 2 | G12: Equador | I12: TOTAL | J12: =SUM(J7:J11) -> 166 | K12: =IF(D12="","",IF(D12>F12,C12,IF(F12>D12,G12,"EMPATE"))) -> EMPATE | L12: =IF(D12="","",IF(D12>F12,D12,IF(F12>D12,F12,D12))) -> 2 | M12: =IF(D12="","",IF(D12<F12,D12,IF(F12<D12,F12,D12))) -> 2 | O12: =IF(OFICIAL!D12="","",IF(AND(K12=OFICIAL!R12,L12=OFICIAL!S12,M12=OFICIAL!T12),9,IF(AND(K12=OFICIAL!R12,L12=OFICIAL!S12,M12<>OFICIAL!T12),6,IF(AND(K12=OFICIAL!R12,OFICIAL!S12=OFICIAL!T12,M12<>OFICIAL!T12),6,IF(AND(K12=OFICIAL!R12,L12<>OFICIAL!S12,OFICIAL!T12=M12),4,IF(AND(K12=OFICIAL!R12,OFICIAL!S12<>L12,OFICIAL!T12<>M12),3,0)))))) -> 0
A13: 46187 | B13: 0.95833333 | C13: Suécia | D13: 2 | E13: x | F13: 1 | G13: Tunísia | K13: =IF(D13="","",IF(D13>F13,C13,IF(F13>D13,G13,"EMPATE"))) -> Suécia | L13: =IF(D13="","",IF(D13>F13,D13,IF(F13>D13,F13,D13))) -> 2 | M13: =IF(D13="","",IF(D13<F13,D13,IF(F13<D13,F13,D13))) -> 1 | O13: =IF(OFICIAL!D13="","",IF(AND(K13=OFICIAL!R13,L13=OFICIAL!S13,M13=OFICIAL!T13),9,IF(AND(K13=OFICIAL!R13,L13=OFICIAL!S13,M13<>OFICIAL!T13),6,IF(AND(K13=OFICIAL!R13,OFICIAL!S13=OFICIAL!T13,M13<>OFICIAL!T13),6,IF(AND(K13=OFICIAL!R13,L13<>OFICIAL!S13,OFICIAL!T13=M13),4,IF(AND(K13=OFICIAL!R13,OFICIAL!S13<>L13,OFICIAL!T13<>M13),3,0)))))) -> 4
A14: 46188 | B14: 0.54166667 | C14: Espanha | D14: 4 | E14: x | F14: 1 | G14: Cabo Verde | K14: =IF(D14="","",IF(D14>F14,C14,IF(F14>D14,G14,"EMPATE"))) -> Espanha | L14: =IF(D14="","",IF(D14>F14,D14,IF(F14>D14,F14,D14))) -> 4 | M14: =IF(D14="","",IF(D14<F14,D14,IF(F14<D14,F14,D14))) -> 1 | O14: =IF(OFICIAL!D14="","",IF(AND(K14=OFICIAL!R14,L14=OFICIAL!S14,M14=OFICIAL!T14),9,IF(AND(K14=OFICIAL!R14,L14=OFICIAL!S14,M14<>OFICIAL!T14),6,IF(AND(K14=OFICIAL!R14,OFICIAL!S14=OFICIAL!T14,M14<>OFICIAL!T14),6,IF(AND(K14=OFICIAL!R14,L14<>OFICIAL!S14,OFICIAL!T14=M14),4,IF(AND(K14=OFICIAL!R14,OFICIAL!S14<>L14,OFICIAL!T14<>M14),3,0)))))) -> 0
A15: 46188 | B15: 0.66666667 | C15: Bélgica | D15: 3 | E15: x | F15: 1 | G15: Egito | K15: =IF(D15="","",IF(D15>F15,C15,IF(F15>D15,G15,"EMPATE"))) -> Bélgica | L15: =IF(D15="","",IF(D15>F15,D15,IF(F15>D15,F15,D15))) -> 3 | M15: =IF(D15="","",IF(D15<F15,D15,IF(F15<D15,F15,D15))) -> 1 | O15: =IF(OFICIAL!D15="","",IF(AND(K15=OFICIAL!R15,L15=OFICIAL!S15,M15=OFICIAL!T15),9,IF(AND(K15=OFICIAL!R15,L15=OFICIAL!S15,M15<>OFICIAL!T15),6,IF(AND(K15=OFICIAL!R15,OFICIAL!S15=OFICIAL!T15,M15<>OFICIAL!T15),6,IF(AND(K15=OFICIAL!R15,L15<>OFICIAL!S15,OFICIAL!T15=M15),4,IF(AND(K15=OFICIAL!R15,OFICIAL!S15<>L15,OFICIAL!T15<>M15),3,0)))))) -> 0
A16: 46188 | B16: 0.79166667 | C16: Arábia Saudita | D16: 0 | E16: x | F16: 3 | G16: Uruguai | K16: =IF(D16="","",IF(D16>F16,C16,IF(F16>D16,G16,"EMPATE"))) -> Uruguai | L16: =IF(D16="","",IF(D16>F16,D16,IF(F16>D16,F16,D16))) -> 3 | M16: =IF(D16="","",IF(D16<F16,D16,IF(F16<D16,F16,D16))) -> 0 | O16: =IF(OFICIAL!D16="","",IF(AND(K16=OFICIAL!R16,L16=OFICIAL!S16,M16=OFICIAL!T16),9,IF(AND(K16=OFICIAL!R16,L16=OFICIAL!S16,M16<>OFICIAL!T16),6,IF(AND(K16=OFICIAL!R16,OFICIAL!S16=OFICIAL!T16,M16<>OFICIAL!T16),6,IF(AND(K16=OFICIAL!R16,L16<>OFICIAL!S16,OFICIAL!T16=M16),4,IF(AND(K16=OFICIAL!R16,OFICIAL!S16<>L16,OFICIAL!T16<>M16),3,0)))))) -> 0
A17: 46188 | B17: 0.91666667 | C17: Irã | D17: 0 | E17: x | F17: 0 | G17: Nova Zelândia | K17: =IF(D17="","",IF(D17>F17,C17,IF(F17>D17,G17,"EMPATE"))) -> EMPATE | L17: =IF(D17="","",IF(D17>F17,D17,IF(F17>D17,F17,D17))) -> 0 | M17: =IF(D17="","",IF(D17<F17,D17,IF(F17<D17,F17,D17))) -> 0 | O17: =IF(OFICIAL!D17="","",IF(AND(K17=OFICIAL!R17,L17=OFICIAL!S17,M17=OFICIAL!T17),9,IF(AND(K17=OFICIAL!R17,L17=OFICIAL!S17,M17<>OFICIAL!T17),6,IF(AND(K17=OFICIAL!R17,OFICIAL!S17=OFICIAL!T17,M17<>OFICIAL!T17),6,IF(AND(K17=OFICIAL!R17,L17<>OFICIAL!S17,OFICIAL!T17=M17),4,IF(AND(K17=OFICIAL!R17,OFICIAL!S17<>L17,OFICIAL!T17<>M17),3,0)))))) -> 6
A18: 46189 | B18: 0.66666667 | C18: França | D18: 2 | E18: x | F18: 0 | G18: Senegal | K18: =IF(D18="","",IF(D18>F18,C18,IF(F18>D18,G18,"EMPATE"))) -> França | L18: =IF(D18="","",IF(D18>F18,D18,IF(F18>D18,F18,D18))) -> 2 | M18: =IF(D18="","",IF(D18<F18,D18,IF(F18<D18,F18,D18))) -> 0 | O18: =IF(OFICIAL!D18="","",IF(AND(K18=OFICIAL!R18,L18=OFICIAL!S18,M18=OFICIAL!T18),9,IF(AND(K18=OFICIAL!R18,L18=OFICIAL!S18,M18<>OFICIAL!T18),6,IF(AND(K18=OFICIAL!R18,OFICIAL!S18=OFICIAL!T18,M18<>OFICIAL!T18),6,IF(AND(K18=OFICIAL!R18,L18<>OFICIAL!S18,OFICIAL!T18=M18),4,IF(AND(K18=OFICIAL!R18,OFICIAL!S18<>L18,OFICIAL!T18<>M18),3,0)))))) -> 3
A19: 46189 | B19: 0.79166667 | C19: Iraque | D19: 1 | E19: x | F19: 1 | G19: Noruega | K19: =IF(D19="","",IF(D19>F19,C19,IF(F19>D19,G19,"EMPATE"))) -> EMPATE | L19: =IF(D19="","",IF(D19>F19,D19,IF(F19>D19,F19,D19))) -> 1 | M19: =IF(D19="","",IF(D19<F19,D19,IF(F19<D19,F19,D19))) -> 1 | O19: =IF(OFICIAL!D19="","",IF(AND(K19=OFICIAL!R19,L19=OFICIAL!S19,M19=OFICIAL!T19),9,IF(AND(K19=OFICIAL!R19,L19=OFICIAL!S19,M19<>OFICIAL!T19),6,IF(AND(K19=OFICIAL!R19,OFICIAL!S19=OFICIAL!T19,M19<>OFICIAL!T19),6,IF(AND(K19=OFICIAL!R19,L19<>OFICIAL!S19,OFICIAL!T19=M19),4,IF(AND(K19=OFICIAL!R19,OFICIAL!S19<>L19,OFICIAL!T19<>M19),3,0)))))) -> 0
A20: 46189 | B20: 0.91666667 | C20: Argentina | D20: 3 | E20: x | F20: 1 | G20: Argélia | K20: =IF(D20="","",IF(D20>F20,C20,IF(F20>D20,G20,"EMPATE"))) -> Argentina | L20: =IF(D20="","",IF(D20>F20,D20,IF(F20>D20,F20,D20))) -> 3 | M20: =IF(D20="","",IF(D20<F20,D20,IF(F20<D20,F20,D20))) -> 1 | O20: =IF(OFICIAL!D20="","",IF(AND(K20=OFICIAL!R20,L20=OFICIAL!S20,M20=OFICIAL!T20),9,IF(AND(K20=OFICIAL!R20,L20=OFICIAL!S20,M20<>OFICIAL!T20),6,IF(AND(K20=OFICIAL!R20,OFICIAL!S20=OFICIAL!T20,M20<>OFICIAL!T20),6,IF(AND(K20=OFICIAL!R20,L20<>OFICIAL!S20,OFICIAL!T20=M20),4,IF(AND(K20=OFICIAL!R20,OFICIAL!S20<>L20,OFICIAL!T20<>M20),3,0)))))) -> 6
A21: 46190 | B21: 0.041666667 | C21: Áustria | D21: 1 | E21: x | F21: 1 | G21: Jordânia | K21: =IF(D21="","",IF(D21>F21,C21,IF(F21>D21,G21,"EMPATE"))) -> EMPATE | L21: =IF(D21="","",IF(D21>F21,D21,IF(F21>D21,F21,D21))) -> 1 | M21: =IF(D21="","",IF(D21<F21,D21,IF(F21<D21,F21,D21))) -> 1 | O21: =IF(OFICIAL!D21="","",IF(AND(K21=OFICIAL!R21,L21=OFICIAL!S21,M21=OFICIAL!T21),9,IF(AND(K21=OFICIAL!R21,L21=OFICIAL!S21,M21<>OFICIAL!T21),6,IF(AND(K21=OFICIAL!R21,OFICIAL!S21=OFICIAL!T21,M21<>OFICIAL!T21),6,IF(AND(K21=OFICIAL!R21,L21<>OFICIAL!S21,OFICIAL!T21=M21),4,IF(AND(K21=OFICIAL!R21,OFICIAL!S21<>L21,OFICIAL!T21<>M21),3,0)))))) -> 0
A22: 46190 | B22: 0.58333333 | C22: Portugal | D22: 3 | E22: x | F22: 1 | G22: RD Congo | K22: =IF(D22="","",IF(D22>F22,C22,IF(F22>D22,G22,"EMPATE"))) -> Portugal | L22: =IF(D22="","",IF(D22>F22,D22,IF(F22>D22,F22,D22))) -> 3 | M22: =IF(D22="","",IF(D22<F22,D22,IF(F22<D22,F22,D22))) -> 1 | O22: =IF(OFICIAL!D22="","",IF(AND(K22=OFICIAL!R22,L22=OFICIAL!S22,M22=OFICIAL!T22),9,IF(AND(K22=OFICIAL!R22,L22=OFICIAL!S22,M22<>OFICIAL!T22),6,IF(AND(K22=OFICIAL!R22,OFICIAL!S22=OFICIAL!T22,M22<>OFICIAL!T22),6,IF(AND(K22=OFICIAL!R22,L22<>OFICIAL!S22,OFICIAL!T22=M22),4,IF(AND(K22=OFICIAL!R22,OFICIAL!S22<>L22,OFICIAL!T22<>M22),3,0)))))) -> 0
A23: 46190 | B23: 0.70833333 | C23: Inglaterra | D23: 2 | E23: x | F23: 2 | G23: Croácia | K23: =IF(D23="","",IF(D23>F23,C23,IF(F23>D23,G23,"EMPATE"))) -> EMPATE | L23: =IF(D23="","",IF(D23>F23,D23,IF(F23>D23,F23,D23))) -> 2 | M23: =IF(D23="","",IF(D23<F23,D23,IF(F23<D23,F23,D23))) -> 2 | O23: =IF(OFICIAL!D23="","",IF(AND(K23=OFICIAL!R23,L23=OFICIAL!S23,M23=OFICIAL!T23),9,IF(AND(K23=OFICIAL!R23,L23=OFICIAL!S23,M23<>OFICIAL!T23),6,IF(AND(K23=OFICIAL!R23,OFICIAL!S23=OFICIAL!T23,M23<>OFICIAL!T23),6,IF(AND(K23=OFICIAL!R23,L23<>OFICIAL!S23,OFICIAL!T23=M23),4,IF(AND(K23=OFICIAL!R23,OFICIAL!S23<>L23,OFICIAL!T23<>M23),3,0)))))) -> 0
A24: 46190 | B24: 0.83333333 | C24: Gana | D24: 2 | E24: x | F24: 1 | G24: Panamá | K24: =IF(D24="","",IF(D24>F24,C24,IF(F24>D24,G24,"EMPATE"))) -> Gana | L24: =IF(D24="","",IF(D24>F24,D24,IF(F24>D24,F24,D24))) -> 2 | M24: =IF(D24="","",IF(D24<F24,D24,IF(F24<D24,F24,D24))) -> 1 | O24: =IF(OFICIAL!D24="","",IF(AND(K24=OFICIAL!R24,L24=OFICIAL!S24,M24=OFICIAL!T24),9,IF(AND(K24=OFICIAL!R24,L24=OFICIAL!S24,M24<>OFICIAL!T24),6,IF(AND(K24=OFICIAL!R24,OFICIAL!S24=OFICIAL!T24,M24<>OFICIAL!T24),6,IF(AND(K24=OFICIAL!R24,L24<>OFICIAL!S24,OFICIAL!T24=M24),4,IF(AND(K24=OFICIAL!R24,OFICIAL!S24<>L24,OFICIAL!T24<>M24),3,0)))))) -> 3
... A73: 46200 | B73: 0.95833333 | C73: Argélia | D73: 1 | E73: x | F73: 1 | G73: Áustria | K73: =IF(D73="","",IF(D73>F73,C73,IF(F73>D73,G73,"EMPATE"))) -> EMPATE | L73: =IF(D73="","",IF(D73>F73,D73,IF(F73>D73,F73,D73))) -> 1 | M73: =IF(D73="","",IF(D73<F73,D73,IF(F73<D73,F73,D73))) -> 1 | O73: =IF(OFICIAL!D73="","",IF(AND(K73=OFICIAL!R73,L73=OFICIAL!S73,M73=OFICIAL!T73),9,IF(AND(K73=OFICIAL!R73,L73=OFICIAL!S73,M73<>OFICIAL!T73),6,IF(AND(K73=OFICIAL!R73,OFICIAL!S73=OFICIAL!T73,M73<>OFICIAL!T73),6,IF(AND(K73=OFICIAL!R73,L73<>OFICIAL!S73,OFICIAL!T73=M73),4,IF(AND(K73=OFICIAL!R73,OFICIAL!S73<>L73,OFICIAL!T73<>M73),3,0)))))) -> 6
